[2025-06-07T15:53:21.091+0000] {local_task_job_runner.py:123} INFO - ::group::Pre task execution logs
[2025-06-07T15:53:21.102+0000] {taskinstance.py:2613} INFO - Dependencies all met for dep_context=non-requeueable deps ti=<TaskInstance: stephen_curry_stats_medallion_etl.bronze_to_silver scheduled__2025-06-06T00:00:00+00:00 [queued]>
[2025-06-07T15:53:21.105+0000] {taskinstance.py:2613} INFO - Dependencies all met for dep_context=requeueable deps ti=<TaskInstance: stephen_curry_stats_medallion_etl.bronze_to_silver scheduled__2025-06-06T00:00:00+00:00 [queued]>
[2025-06-07T15:53:21.106+0000] {taskinstance.py:2866} INFO - Starting attempt 1 of 1
[2025-06-07T15:53:21.111+0000] {taskinstance.py:2889} INFO - Executing <Task(SparkSubmitOperator): bronze_to_silver> on 2025-06-06 00:00:00+00:00
[2025-06-07T15:53:21.114+0000] {standard_task_runner.py:72} INFO - Started process 475 to run task
[2025-06-07T15:53:21.116+0000] {standard_task_runner.py:104} INFO - Running: ['***', 'tasks', 'run', 'stephen_curry_stats_medallion_etl', 'bronze_to_silver', 'scheduled__2025-06-06T00:00:00+00:00', '--job-id', '5', '--raw', '--subdir', 'DAGS_FOLDER/medallion_sales_etl_dag.py', '--cfg-path', '/tmp/tmpsxlxdnw1']
[2025-06-07T15:53:21.118+0000] {standard_task_runner.py:105} INFO - Job 5: Subtask bronze_to_silver
[2025-06-07T15:53:21.149+0000] {task_command.py:467} INFO - Running <TaskInstance: stephen_curry_stats_medallion_etl.bronze_to_silver scheduled__2025-06-06T00:00:00+00:00 [running]> on host b5e5641a3f5a
[2025-06-07T15:53:21.197+0000] {taskinstance.py:3132} INFO - Exporting env vars: AIRFLOW_CTX_DAG_OWNER='***' AIRFLOW_CTX_DAG_ID='stephen_curry_stats_medallion_etl' AIRFLOW_CTX_TASK_ID='bronze_to_silver' AIRFLOW_CTX_EXECUTION_DATE='2025-06-06T00:00:00+00:00' AIRFLOW_CTX_TRY_NUMBER='1' AIRFLOW_CTX_DAG_RUN_ID='scheduled__2025-06-06T00:00:00+00:00'
[2025-06-07T15:53:21.198+0000] {taskinstance.py:731} INFO - ::endgroup::
[2025-06-07T15:53:21.218+0000] {base.py:84} INFO - Retrieving connection 'spark_default'
[2025-06-07T15:53:21.219+0000] {spark_submit.py:474} INFO - Spark-Submit cmd: spark-submit --master spark://spark-master:7077 --conf spark.executor.memory=2g --conf spark.sql.extensions=io.delta.sql.DeltaSparkSessionExtension --conf spark.sql.catalog.spark_catalog=org.apache.spark.sql.delta.catalog.DeltaCatalog --conf spark.hadoop.fs.s3a.endpoint=http://minio:9000 --conf spark.hadoop.fs.s3a.access.key=minioadmin --conf spark.hadoop.fs.s3a.secret.key=****** --conf spark.hadoop.fs.s3a.path.style.access=true --conf spark.hadoop.fs.s3a.impl=org.apache.hadoop.fs.s3a.S3AFileSystem --conf spark.hadoop.fs.s3a.aws.credentials.provider=org.apache.hadoop.fs.s3a.SimpleAWSCredentialsProvider --packages org.apache.hadoop:hadoop-aws:3.3.4,com.amazonaws:aws-java-sdk-bundle:1.12.262,io.delta:delta-spark_2.12:3.1.0 --name arrow-spark --queue root.default --deploy-mode client dags/bronze_to_silver_sc_stats_etl.py --output_path s3a://mybucket/sc_stats_db/silver/transformed_data
[2025-06-07T15:53:22.086+0000] {spark_submit.py:644} INFO - :: loading settings :: url = jar:file:/home/***/.local/lib/python3.11/site-packages/pyspark/jars/ivy-2.5.1.jar!/org/apache/ivy/core/settings/ivysettings.xml
[2025-06-07T15:53:22.123+0000] {spark_submit.py:644} INFO - Ivy Default Cache set to: /home/***/.ivy2/cache
[2025-06-07T15:53:22.123+0000] {spark_submit.py:644} INFO - The jars for the packages stored in: /home/***/.ivy2/jars
[2025-06-07T15:53:22.125+0000] {spark_submit.py:644} INFO - org.apache.hadoop#hadoop-aws added as a dependency
[2025-06-07T15:53:22.125+0000] {spark_submit.py:644} INFO - com.amazonaws#aws-java-sdk-bundle added as a dependency
[2025-06-07T15:53:22.125+0000] {spark_submit.py:644} INFO - io.delta#delta-spark_2.12 added as a dependency
[2025-06-07T15:53:22.126+0000] {spark_submit.py:644} INFO - :: resolving dependencies :: org.apache.spark#spark-submit-parent-d681d088-3fd8-43d1-b545-56b990cd98bf;1.0
[2025-06-07T15:53:22.126+0000] {spark_submit.py:644} INFO - confs: [default]
[2025-06-07T15:53:22.212+0000] {spark_submit.py:644} INFO - found org.apache.hadoop#hadoop-aws;3.3.4 in central
[2025-06-07T15:53:22.224+0000] {spark_submit.py:644} INFO - found com.amazonaws#aws-java-sdk-bundle;1.12.262 in central
[2025-06-07T15:53:22.234+0000] {spark_submit.py:644} INFO - found org.wildfly.openssl#wildfly-openssl;1.0.7.Final in central
[2025-06-07T15:53:22.243+0000] {spark_submit.py:644} INFO - found io.delta#delta-spark_2.12;3.1.0 in central
[2025-06-07T15:53:22.251+0000] {spark_submit.py:644} INFO - found io.delta#delta-storage;3.1.0 in central
[2025-06-07T15:53:22.257+0000] {spark_submit.py:644} INFO - found org.antlr#antlr4-runtime;4.9.3 in central
[2025-06-07T15:53:22.272+0000] {spark_submit.py:644} INFO - :: resolution report :: resolve 139ms :: artifacts dl 8ms
[2025-06-07T15:53:22.272+0000] {spark_submit.py:644} INFO - :: modules in use:
[2025-06-07T15:53:22.273+0000] {spark_submit.py:644} INFO - com.amazonaws#aws-java-sdk-bundle;1.12.262 from central in [default]
[2025-06-07T15:53:22.273+0000] {spark_submit.py:644} INFO - io.delta#delta-spark_2.12;3.1.0 from central in [default]
[2025-06-07T15:53:22.273+0000] {spark_submit.py:644} INFO - io.delta#delta-storage;3.1.0 from central in [default]
[2025-06-07T15:53:22.273+0000] {spark_submit.py:644} INFO - org.antlr#antlr4-runtime;4.9.3 from central in [default]
[2025-06-07T15:53:22.273+0000] {spark_submit.py:644} INFO - org.apache.hadoop#hadoop-aws;3.3.4 from central in [default]
[2025-06-07T15:53:22.274+0000] {spark_submit.py:644} INFO - org.wildfly.openssl#wildfly-openssl;1.0.7.Final from central in [default]
[2025-06-07T15:53:22.274+0000] {spark_submit.py:644} INFO - ---------------------------------------------------------------------
[2025-06-07T15:53:22.274+0000] {spark_submit.py:644} INFO - |                  |            modules            ||   artifacts   |
[2025-06-07T15:53:22.274+0000] {spark_submit.py:644} INFO - |       conf       | number| search|dwnlded|evicted|| number|dwnlded|
[2025-06-07T15:53:22.274+0000] {spark_submit.py:644} INFO - ---------------------------------------------------------------------
[2025-06-07T15:53:22.274+0000] {spark_submit.py:644} INFO - |      default     |   6   |   0   |   0   |   0   ||   6   |   0   |
[2025-06-07T15:53:22.274+0000] {spark_submit.py:644} INFO - ---------------------------------------------------------------------
[2025-06-07T15:53:22.275+0000] {spark_submit.py:644} INFO - :: retrieving :: org.apache.spark#spark-submit-parent-d681d088-3fd8-43d1-b545-56b990cd98bf
[2025-06-07T15:53:22.276+0000] {spark_submit.py:644} INFO - confs: [default]
[2025-06-07T15:53:22.279+0000] {spark_submit.py:644} INFO - 0 artifacts copied, 6 already retrieved (0kB/4ms)
[2025-06-07T15:53:22.379+0000] {spark_submit.py:644} INFO - 25/06/07 15:53:22 WARN NativeCodeLoader: Unable to load native-hadoop library for your platform... using builtin-java classes where applicable
[2025-06-07T15:53:23.189+0000] {spark_submit.py:644} INFO - 25/06/07 15:53:23 INFO SparkContext: Running Spark version 3.5.2
[2025-06-07T15:53:23.189+0000] {spark_submit.py:644} INFO - 25/06/07 15:53:23 INFO SparkContext: OS info Linux, 6.10.14-linuxkit, aarch64
[2025-06-07T15:53:23.190+0000] {spark_submit.py:644} INFO - 25/06/07 15:53:23 INFO SparkContext: Java version 17.0.15
[2025-06-07T15:53:23.200+0000] {spark_submit.py:644} INFO - 25/06/07 15:53:23 INFO ResourceUtils: ==============================================================
[2025-06-07T15:53:23.201+0000] {spark_submit.py:644} INFO - 25/06/07 15:53:23 INFO ResourceUtils: No custom resources configured for spark.driver.
[2025-06-07T15:53:23.201+0000] {spark_submit.py:644} INFO - 25/06/07 15:53:23 INFO ResourceUtils: ==============================================================
[2025-06-07T15:53:23.201+0000] {spark_submit.py:644} INFO - 25/06/07 15:53:23 INFO SparkContext: Submitted application: BronzeToSilverStephenCurryStats
[2025-06-07T15:53:23.213+0000] {spark_submit.py:644} INFO - 25/06/07 15:53:23 INFO ResourceProfile: Default ResourceProfile created, executor resources: Map(memory -> name: memory, amount: 2048, script: , vendor: , offHeap -> name: offHeap, amount: 0, script: , vendor: ), task resources: Map(cpus -> name: cpus, amount: 1.0)
[2025-06-07T15:53:23.217+0000] {spark_submit.py:644} INFO - 25/06/07 15:53:23 INFO ResourceProfile: Limiting resource is cpu
[2025-06-07T15:53:23.217+0000] {spark_submit.py:644} INFO - 25/06/07 15:53:23 INFO ResourceProfileManager: Added ResourceProfile id: 0
[2025-06-07T15:53:23.252+0000] {spark_submit.py:644} INFO - 25/06/07 15:53:23 INFO SecurityManager: Changing view acls to: ***
[2025-06-07T15:53:23.252+0000] {spark_submit.py:644} INFO - 25/06/07 15:53:23 INFO SecurityManager: Changing modify acls to: ***
[2025-06-07T15:53:23.252+0000] {spark_submit.py:644} INFO - 25/06/07 15:53:23 INFO SecurityManager: Changing view acls groups to:
[2025-06-07T15:53:23.252+0000] {spark_submit.py:644} INFO - 25/06/07 15:53:23 INFO SecurityManager: Changing modify acls groups to:
[2025-06-07T15:53:23.253+0000] {spark_submit.py:644} INFO - 25/06/07 15:53:23 INFO SecurityManager: SecurityManager: authentication disabled; ui acls disabled; users with view permissions: ***; groups with view permissions: EMPTY; users with modify permissions: ***; groups with modify permissions: EMPTY
[2025-06-07T15:53:23.372+0000] {spark_submit.py:644} INFO - 25/06/07 15:53:23 INFO Utils: Successfully started service 'sparkDriver' on port 45543.
[2025-06-07T15:53:23.391+0000] {spark_submit.py:644} INFO - 25/06/07 15:53:23 INFO SparkEnv: Registering MapOutputTracker
[2025-06-07T15:53:23.416+0000] {spark_submit.py:644} INFO - 25/06/07 15:53:23 INFO SparkEnv: Registering BlockManagerMaster
[2025-06-07T15:53:23.425+0000] {spark_submit.py:644} INFO - 25/06/07 15:53:23 INFO BlockManagerMasterEndpoint: Using org.apache.spark.storage.DefaultTopologyMapper for getting topology information
[2025-06-07T15:53:23.426+0000] {spark_submit.py:644} INFO - 25/06/07 15:53:23 INFO BlockManagerMasterEndpoint: BlockManagerMasterEndpoint up
[2025-06-07T15:53:23.429+0000] {spark_submit.py:644} INFO - 25/06/07 15:53:23 INFO SparkEnv: Registering BlockManagerMasterHeartbeat
[2025-06-07T15:53:23.441+0000] {spark_submit.py:644} INFO - 25/06/07 15:53:23 INFO DiskBlockManager: Created local directory at /tmp/blockmgr-2fffa9c9-5f11-4821-9fb6-5621beb7ea5e
[2025-06-07T15:53:23.447+0000] {spark_submit.py:644} INFO - 25/06/07 15:53:23 INFO MemoryStore: MemoryStore started with capacity 434.4 MiB
[2025-06-07T15:53:23.455+0000] {spark_submit.py:644} INFO - 25/06/07 15:53:23 INFO SparkEnv: Registering OutputCommitCoordinator
[2025-06-07T15:53:23.515+0000] {spark_submit.py:644} INFO - 25/06/07 15:53:23 INFO JettyUtils: Start Jetty 0.0.0.0:4040 for SparkUI
[2025-06-07T15:53:23.543+0000] {spark_submit.py:644} INFO - 25/06/07 15:53:23 INFO Utils: Successfully started service 'SparkUI' on port 4040.
[2025-06-07T15:53:23.561+0000] {spark_submit.py:644} INFO - 25/06/07 15:53:23 INFO SparkContext: Added JAR file:///home/***/.ivy2/jars/org.apache.hadoop_hadoop-aws-3.3.4.jar at spark://b5e5641a3f5a:45543/jars/org.apache.hadoop_hadoop-aws-3.3.4.jar with timestamp 1749311603180
[2025-06-07T15:53:23.561+0000] {spark_submit.py:644} INFO - 25/06/07 15:53:23 INFO SparkContext: Added JAR file:///home/***/.ivy2/jars/com.amazonaws_aws-java-sdk-bundle-1.12.262.jar at spark://b5e5641a3f5a:45543/jars/com.amazonaws_aws-java-sdk-bundle-1.12.262.jar with timestamp 1749311603180
[2025-06-07T15:53:23.562+0000] {spark_submit.py:644} INFO - 25/06/07 15:53:23 INFO SparkContext: Added JAR file:///home/***/.ivy2/jars/io.delta_delta-spark_2.12-3.1.0.jar at spark://b5e5641a3f5a:45543/jars/io.delta_delta-spark_2.12-3.1.0.jar with timestamp 1749311603180
[2025-06-07T15:53:23.562+0000] {spark_submit.py:644} INFO - 25/06/07 15:53:23 INFO SparkContext: Added JAR file:///home/***/.ivy2/jars/org.wildfly.openssl_wildfly-openssl-1.0.7.Final.jar at spark://b5e5641a3f5a:45543/jars/org.wildfly.openssl_wildfly-openssl-1.0.7.Final.jar with timestamp 1749311603180
[2025-06-07T15:53:23.562+0000] {spark_submit.py:644} INFO - 25/06/07 15:53:23 INFO SparkContext: Added JAR file:///home/***/.ivy2/jars/io.delta_delta-storage-3.1.0.jar at spark://b5e5641a3f5a:45543/jars/io.delta_delta-storage-3.1.0.jar with timestamp 1749311603180
[2025-06-07T15:53:23.562+0000] {spark_submit.py:644} INFO - 25/06/07 15:53:23 INFO SparkContext: Added JAR file:///home/***/.ivy2/jars/org.antlr_antlr4-runtime-4.9.3.jar at spark://b5e5641a3f5a:45543/jars/org.antlr_antlr4-runtime-4.9.3.jar with timestamp 1749311603180
[2025-06-07T15:53:23.563+0000] {spark_submit.py:644} INFO - 25/06/07 15:53:23 INFO SparkContext: Added file file:///home/***/.ivy2/jars/org.apache.hadoop_hadoop-aws-3.3.4.jar at spark://b5e5641a3f5a:45543/files/org.apache.hadoop_hadoop-aws-3.3.4.jar with timestamp 1749311603180
[2025-06-07T15:53:23.564+0000] {spark_submit.py:644} INFO - 25/06/07 15:53:23 INFO Utils: Copying /home/***/.ivy2/jars/org.apache.hadoop_hadoop-aws-3.3.4.jar to /tmp/spark-dca8dcb4-dd02-443c-b8c0-69612a8e39c3/userFiles-67c7577f-9a7a-4d14-856c-9806f80d4b15/org.apache.hadoop_hadoop-aws-3.3.4.jar
[2025-06-07T15:53:23.570+0000] {spark_submit.py:644} INFO - 25/06/07 15:53:23 INFO SparkContext: Added file file:///home/***/.ivy2/jars/com.amazonaws_aws-java-sdk-bundle-1.12.262.jar at spark://b5e5641a3f5a:45543/files/com.amazonaws_aws-java-sdk-bundle-1.12.262.jar with timestamp 1749311603180
[2025-06-07T15:53:23.571+0000] {spark_submit.py:644} INFO - 25/06/07 15:53:23 INFO Utils: Copying /home/***/.ivy2/jars/com.amazonaws_aws-java-sdk-bundle-1.12.262.jar to /tmp/spark-dca8dcb4-dd02-443c-b8c0-69612a8e39c3/userFiles-67c7577f-9a7a-4d14-856c-9806f80d4b15/com.amazonaws_aws-java-sdk-bundle-1.12.262.jar
[2025-06-07T15:53:23.651+0000] {spark_submit.py:644} INFO - 25/06/07 15:53:23 INFO SparkContext: Added file file:///home/***/.ivy2/jars/io.delta_delta-spark_2.12-3.1.0.jar at spark://b5e5641a3f5a:45543/files/io.delta_delta-spark_2.12-3.1.0.jar with timestamp 1749311603180
[2025-06-07T15:53:23.652+0000] {spark_submit.py:644} INFO - 25/06/07 15:53:23 INFO Utils: Copying /home/***/.ivy2/jars/io.delta_delta-spark_2.12-3.1.0.jar to /tmp/spark-dca8dcb4-dd02-443c-b8c0-69612a8e39c3/userFiles-67c7577f-9a7a-4d14-856c-9806f80d4b15/io.delta_delta-spark_2.12-3.1.0.jar
[2025-06-07T15:53:23.655+0000] {spark_submit.py:644} INFO - 25/06/07 15:53:23 INFO SparkContext: Added file file:///home/***/.ivy2/jars/org.wildfly.openssl_wildfly-openssl-1.0.7.Final.jar at spark://b5e5641a3f5a:45543/files/org.wildfly.openssl_wildfly-openssl-1.0.7.Final.jar with timestamp 1749311603180
[2025-06-07T15:53:23.656+0000] {spark_submit.py:644} INFO - 25/06/07 15:53:23 INFO Utils: Copying /home/***/.ivy2/jars/org.wildfly.openssl_wildfly-openssl-1.0.7.Final.jar to /tmp/spark-dca8dcb4-dd02-443c-b8c0-69612a8e39c3/userFiles-67c7577f-9a7a-4d14-856c-9806f80d4b15/org.wildfly.openssl_wildfly-openssl-1.0.7.Final.jar
[2025-06-07T15:53:23.657+0000] {spark_submit.py:644} INFO - 25/06/07 15:53:23 INFO SparkContext: Added file file:///home/***/.ivy2/jars/io.delta_delta-storage-3.1.0.jar at spark://b5e5641a3f5a:45543/files/io.delta_delta-storage-3.1.0.jar with timestamp 1749311603180
[2025-06-07T15:53:23.658+0000] {spark_submit.py:644} INFO - 25/06/07 15:53:23 INFO Utils: Copying /home/***/.ivy2/jars/io.delta_delta-storage-3.1.0.jar to /tmp/spark-dca8dcb4-dd02-443c-b8c0-69612a8e39c3/userFiles-67c7577f-9a7a-4d14-856c-9806f80d4b15/io.delta_delta-storage-3.1.0.jar
[2025-06-07T15:53:23.659+0000] {spark_submit.py:644} INFO - 25/06/07 15:53:23 INFO SparkContext: Added file file:///home/***/.ivy2/jars/org.antlr_antlr4-runtime-4.9.3.jar at spark://b5e5641a3f5a:45543/files/org.antlr_antlr4-runtime-4.9.3.jar with timestamp 1749311603180
[2025-06-07T15:53:23.660+0000] {spark_submit.py:644} INFO - 25/06/07 15:53:23 INFO Utils: Copying /home/***/.ivy2/jars/org.antlr_antlr4-runtime-4.9.3.jar to /tmp/spark-dca8dcb4-dd02-443c-b8c0-69612a8e39c3/userFiles-67c7577f-9a7a-4d14-856c-9806f80d4b15/org.antlr_antlr4-runtime-4.9.3.jar
[2025-06-07T15:53:23.701+0000] {spark_submit.py:644} INFO - 25/06/07 15:53:23 INFO StandaloneAppClient$ClientEndpoint: Connecting to master spark://spark-master:7077...
[2025-06-07T15:53:23.723+0000] {spark_submit.py:644} INFO - 25/06/07 15:53:23 INFO TransportClientFactory: Successfully created connection to spark-master/172.19.0.6:7077 after 11 ms (0 ms spent in bootstraps)
[2025-06-07T15:53:23.766+0000] {spark_submit.py:644} INFO - 25/06/07 15:53:23 INFO StandaloneSchedulerBackend: Connected to Spark cluster with app ID app-20250607155323-0001
[2025-06-07T15:53:23.766+0000] {spark_submit.py:644} INFO - 25/06/07 15:53:23 INFO StandaloneAppClient$ClientEndpoint: Executor added: app-20250607155323-0001/0 on worker-20250607155059-172.19.0.7-41643 (172.19.0.7:41643) with 4 core(s)
[2025-06-07T15:53:23.768+0000] {spark_submit.py:644} INFO - 25/06/07 15:53:23 INFO StandaloneSchedulerBackend: Granted executor ID app-20250607155323-0001/0 on hostPort 172.19.0.7:41643 with 4 core(s), 2.0 GiB RAM
[2025-06-07T15:53:23.771+0000] {spark_submit.py:644} INFO - 25/06/07 15:53:23 INFO Utils: Successfully started service 'org.apache.spark.network.netty.NettyBlockTransferService' on port 32903.
[2025-06-07T15:53:23.771+0000] {spark_submit.py:644} INFO - 25/06/07 15:53:23 INFO NettyBlockTransferService: Server created on b5e5641a3f5a:32903
[2025-06-07T15:53:23.772+0000] {spark_submit.py:644} INFO - 25/06/07 15:53:23 INFO BlockManager: Using org.apache.spark.storage.RandomBlockReplicationPolicy for block replication policy
[2025-06-07T15:53:23.775+0000] {spark_submit.py:644} INFO - 25/06/07 15:53:23 INFO BlockManagerMaster: Registering BlockManager BlockManagerId(driver, b5e5641a3f5a, 32903, None)
[2025-06-07T15:53:23.777+0000] {spark_submit.py:644} INFO - 25/06/07 15:53:23 INFO BlockManagerMasterEndpoint: Registering block manager b5e5641a3f5a:32903 with 434.4 MiB RAM, BlockManagerId(driver, b5e5641a3f5a, 32903, None)
[2025-06-07T15:53:23.778+0000] {spark_submit.py:644} INFO - 25/06/07 15:53:23 INFO BlockManagerMaster: Registered BlockManager BlockManagerId(driver, b5e5641a3f5a, 32903, None)
[2025-06-07T15:53:23.779+0000] {spark_submit.py:644} INFO - 25/06/07 15:53:23 INFO BlockManager: Initialized BlockManager: BlockManagerId(driver, b5e5641a3f5a, 32903, None)
[2025-06-07T15:53:23.788+0000] {spark_submit.py:644} INFO - 25/06/07 15:53:23 INFO StandaloneAppClient$ClientEndpoint: Executor updated: app-20250607155323-0001/0 is now RUNNING
[2025-06-07T15:53:23.906+0000] {spark_submit.py:644} INFO - 25/06/07 15:53:23 INFO StandaloneSchedulerBackend: SchedulerBackend is ready for scheduling beginning after reached minRegisteredResourcesRatio: 0.0
[2025-06-07T15:53:24.069+0000] {spark_submit.py:644} INFO - Bronze to Silver: Spark session created.
[2025-06-07T15:53:24.073+0000] {spark_submit.py:644} INFO - 25/06/07 15:53:24 INFO SharedState: Setting hive.metastore.warehouse.dir ('null') to the value of spark.sql.warehouse.dir.
[2025-06-07T15:53:24.075+0000] {spark_submit.py:644} INFO - 25/06/07 15:53:24 INFO SharedState: Warehouse path is 'file:/tmp/spark-warehouse'.
[2025-06-07T15:53:24.768+0000] {spark_submit.py:644} INFO - 25/06/07 15:53:24 INFO HiveConf: Found configuration file null
[2025-06-07T15:53:24.773+0000] {spark_submit.py:644} INFO - 25/06/07 15:53:24 INFO HiveUtils: Initializing HiveMetastoreConnection version 2.3.9 using Spark classes.
[2025-06-07T15:53:24.916+0000] {spark_submit.py:644} INFO - 25/06/07 15:53:24 INFO HiveClientImpl: Warehouse location for Hive client (version 2.3.9) is file:/tmp/spark-warehouse
[2025-06-07T15:53:24.933+0000] {spark_submit.py:644} INFO - 25/06/07 15:53:24 INFO metastore: Trying to connect to metastore with URI thrift://hive-metastore:9083
[2025-06-07T15:53:24.949+0000] {spark_submit.py:644} INFO - 25/06/07 15:53:24 INFO metastore: Opened a connection to metastore, current connections: 1
[2025-06-07T15:53:24.968+0000] {spark_submit.py:644} INFO - 25/06/07 15:53:24 INFO metastore: Connected to metastore.
[2025-06-07T15:53:25.519+0000] {spark_submit.py:644} INFO - 25/06/07 15:53:25 INFO StandaloneSchedulerBackend$StandaloneDriverEndpoint: Registered executor NettyRpcEndpointRef(spark-client://Executor) (172.19.0.7:49852) with ID 0,  ResourceProfileId 0
[2025-06-07T15:53:25.523+0000] {spark_submit.py:644} INFO - 25/06/07 15:53:25 WARN MetricsConfig: Cannot locate configuration: tried hadoop-metrics2-s3a-file-system.properties,hadoop-metrics2.properties
[2025-06-07T15:53:25.530+0000] {spark_submit.py:644} INFO - 25/06/07 15:53:25 INFO MetricsSystemImpl: Scheduled Metric snapshot period at 10 second(s).
[2025-06-07T15:53:25.531+0000] {spark_submit.py:644} INFO - 25/06/07 15:53:25 INFO MetricsSystemImpl: s3a-file-system metrics system started
[2025-06-07T15:53:25.558+0000] {spark_submit.py:644} INFO - 25/06/07 15:53:25 INFO BlockManagerMasterEndpoint: Registering block manager 172.19.0.7:39917 with 1048.8 MiB RAM, BlockManagerId(0, 172.19.0.7, 39917, None)
[2025-06-07T15:53:26.156+0000] {spark_submit.py:644} INFO - 25/06/07 15:53:26 INFO DelegatingLogStore: LogStore `LogStoreAdapter(io.delta.storage.S3SingleDriverLogStore)` is used for scheme `s3a`
[2025-06-07T15:53:26.302+0000] {spark_submit.py:644} INFO - 25/06/07 15:53:26 INFO DeltaLog: Loading version 0.
[2025-06-07T15:53:27.255+0000] {spark_submit.py:644} INFO - 25/06/07 15:53:27 INFO DeltaLogFileIndex: Created DeltaLogFileIndex(JSON, numFilesInSegment: 1, totalFileSize: 3839)
[2025-06-07T15:53:27.687+0000] {spark_submit.py:644} INFO - 25/06/07 15:53:27 INFO DataSourceStrategy: Pruning directories with:
[2025-06-07T15:53:27.700+0000] {spark_submit.py:644} INFO - 25/06/07 15:53:27 INFO FileSourceStrategy: Pushed Filters:
[2025-06-07T15:53:27.701+0000] {spark_submit.py:644} INFO - 25/06/07 15:53:27 INFO FileSourceStrategy: Post-Scan Filters: (isnotnull(protocol#11.minReaderVersion) OR isnotnull(metaData#10.id))
[2025-06-07T15:53:27.953+0000] {spark_submit.py:644} INFO - 25/06/07 15:53:27 INFO CodeGenerator: Code generated in 148.572001 ms
[2025-06-07T15:53:27.989+0000] {spark_submit.py:644} INFO - 25/06/07 15:53:27 INFO MemoryStore: Block broadcast_0 stored as values in memory (estimated size 205.3 KiB, free 434.2 MiB)
[2025-06-07T15:53:28.018+0000] {spark_submit.py:644} INFO - 25/06/07 15:53:28 INFO MemoryStore: Block broadcast_0_piece0 stored as bytes in memory (estimated size 36.2 KiB, free 434.2 MiB)
[2025-06-07T15:53:28.020+0000] {spark_submit.py:644} INFO - 25/06/07 15:53:28 INFO BlockManagerInfo: Added broadcast_0_piece0 in memory on b5e5641a3f5a:32903 (size: 36.2 KiB, free: 434.4 MiB)
[2025-06-07T15:53:28.023+0000] {spark_submit.py:644} INFO - 25/06/07 15:53:28 INFO SparkContext: Created broadcast 0 from toString at String.java:4220
[2025-06-07T15:53:28.041+0000] {spark_submit.py:644} INFO - 25/06/07 15:53:28 INFO FileSourceScanExec: Planning scan with bin packing, max size: 4194304 bytes, open cost is considered as scanning 4194304 bytes.
[2025-06-07T15:53:28.134+0000] {spark_submit.py:644} INFO - 25/06/07 15:53:28 INFO SparkContext: Starting job: toString at String.java:4220
[2025-06-07T15:53:28.142+0000] {spark_submit.py:644} INFO - 25/06/07 15:53:28 INFO DAGScheduler: Got job 0 (toString at String.java:4220) with 1 output partitions
[2025-06-07T15:53:28.144+0000] {spark_submit.py:644} INFO - 25/06/07 15:53:28 INFO DAGScheduler: Final stage: ResultStage 0 (toString at String.java:4220)
[2025-06-07T15:53:28.144+0000] {spark_submit.py:644} INFO - 25/06/07 15:53:28 INFO DAGScheduler: Parents of final stage: List()
[2025-06-07T15:53:28.144+0000] {spark_submit.py:644} INFO - 25/06/07 15:53:28 INFO DAGScheduler: Missing parents: List()
[2025-06-07T15:53:28.145+0000] {spark_submit.py:644} INFO - 25/06/07 15:53:28 INFO DAGScheduler: Submitting ResultStage 0 (MapPartitionsRDD[3] at toString at String.java:4220), which has no missing parents
[2025-06-07T15:53:28.153+0000] {spark_submit.py:644} INFO - 25/06/07 15:53:28 INFO MemoryStore: Block broadcast_1 stored as values in memory (estimated size 40.0 KiB, free 434.1 MiB)
[2025-06-07T15:53:28.154+0000] {spark_submit.py:644} INFO - 25/06/07 15:53:28 INFO MemoryStore: Block broadcast_1_piece0 stored as bytes in memory (estimated size 13.7 KiB, free 434.1 MiB)
[2025-06-07T15:53:28.155+0000] {spark_submit.py:644} INFO - 25/06/07 15:53:28 INFO BlockManagerInfo: Added broadcast_1_piece0 in memory on b5e5641a3f5a:32903 (size: 13.7 KiB, free: 434.4 MiB)
[2025-06-07T15:53:28.155+0000] {spark_submit.py:644} INFO - 25/06/07 15:53:28 INFO SparkContext: Created broadcast 1 from broadcast at DAGScheduler.scala:1585
[2025-06-07T15:53:28.166+0000] {spark_submit.py:644} INFO - 25/06/07 15:53:28 INFO DAGScheduler: Submitting 1 missing tasks from ResultStage 0 (MapPartitionsRDD[3] at toString at String.java:4220) (first 15 tasks are for partitions Vector(0))
[2025-06-07T15:53:28.167+0000] {spark_submit.py:644} INFO - 25/06/07 15:53:28 INFO TaskSchedulerImpl: Adding task set 0.0 with 1 tasks resource profile 0
[2025-06-07T15:53:28.183+0000] {spark_submit.py:644} INFO - 25/06/07 15:53:28 INFO TaskSetManager: Starting task 0.0 in stage 0.0 (TID 0) (172.19.0.7, executor 0, partition 0, PROCESS_LOCAL, 10842 bytes)
[2025-06-07T15:53:28.319+0000] {spark_submit.py:644} INFO - 25/06/07 15:53:28 INFO BlockManagerInfo: Added broadcast_1_piece0 in memory on 172.19.0.7:39917 (size: 13.7 KiB, free: 1048.8 MiB)
[2025-06-07T15:53:28.866+0000] {spark_submit.py:644} INFO - 25/06/07 15:53:28 INFO BlockManagerInfo: Added broadcast_0_piece0 in memory on 172.19.0.7:39917 (size: 36.2 KiB, free: 1048.8 MiB)
[2025-06-07T15:53:29.481+0000] {spark_submit.py:644} INFO - 25/06/07 15:53:29 INFO TaskSetManager: Finished task 0.0 in stage 0.0 (TID 0) in 1304 ms on 172.19.0.7 (executor 0) (1/1)
[2025-06-07T15:53:29.482+0000] {spark_submit.py:644} INFO - 25/06/07 15:53:29 INFO TaskSchedulerImpl: Removed TaskSet 0.0, whose tasks have all completed, from pool
[2025-06-07T15:53:29.486+0000] {spark_submit.py:644} INFO - 25/06/07 15:53:29 INFO DAGScheduler: ResultStage 0 (toString at String.java:4220) finished in 1.334 s
[2025-06-07T15:53:29.487+0000] {spark_submit.py:644} INFO - 25/06/07 15:53:29 INFO DAGScheduler: Job 0 is finished. Cancelling potential speculative or zombie tasks for this job
[2025-06-07T15:53:29.487+0000] {spark_submit.py:644} INFO - 25/06/07 15:53:29 INFO TaskSchedulerImpl: Killing all running tasks in stage 0: Stage finished
[2025-06-07T15:53:29.489+0000] {spark_submit.py:644} INFO - 25/06/07 15:53:29 INFO DAGScheduler: Job 0 finished: toString at String.java:4220, took 1.353587 s
[2025-06-07T15:53:29.524+0000] {spark_submit.py:644} INFO - 25/06/07 15:53:29 INFO BlockManagerInfo: Removed broadcast_1_piece0 on 172.19.0.7:39917 in memory (size: 13.7 KiB, free: 1048.8 MiB)
[2025-06-07T15:53:29.525+0000] {spark_submit.py:644} INFO - 25/06/07 15:53:29 INFO BlockManagerInfo: Removed broadcast_1_piece0 on b5e5641a3f5a:32903 in memory (size: 13.7 KiB, free: 434.4 MiB)
[2025-06-07T15:53:29.544+0000] {spark_submit.py:644} INFO - 25/06/07 15:53:29 INFO CodeGenerator: Code generated in 37.834583 ms
[2025-06-07T15:53:29.547+0000] {spark_submit.py:644} INFO - 25/06/07 15:53:29 INFO Snapshot: [tableId=488fdb3c-94d3-41fc-866a-cb27844fa401] Created snapshot Snapshot(path=s3a://mybucket/sc_stats_db/bronze/raw_data/_delta_log, version=0, metadata=Metadata(9e663b76-69fe-4dd4-b26d-29bc9e7c617a,null,null,Format(parquet,Map()),{"type":"struct","fields":[{"name":"Season_year","type":"string","nullable":true,"metadata":{}},{"name":"Season_div","type":"string","nullable":true,"metadata":{}},{"name":"Date","type":"string","nullable":true,"metadata":{}},{"name":"OPP","type":"string","nullable":true,"metadata":{}},{"name":"Result","type":"string","nullable":true,"metadata":{}},{"name":"T_Score","type":"long","nullable":true,"metadata":{}},{"name":"O_Score","type":"long","nullable":true,"metadata":{}},{"name":"MIN","type":"double","nullable":true,"metadata":{}},{"name":"FG","type":"string","nullable":true,"metadata":{}},{"name":"FGM","type":"long","nullable":true,"metadata":{}},{"name":"FGA","type":"long","nullable":true,"metadata":{}},{"name":"FG_Percentage","type":"double","nullable":true,"metadata":{}},{"name":"3PT","type":"string","nullable":true,"metadata":{}},{"name":"3PTM","type":"long","nullable":true,"metadata":{}},{"name":"3PTA","type":"long","nullable":true,"metadata":{}},{"name":"3P_Percentage","type":"double","nullable":true,"metadata":{}},{"name":"FT","type":"string","nullable":true,"metadata":{}},{"name":"FTM","type":"long","nullable":true,"metadata":{}},{"name":"FTA","type":"long","nullable":true,"metadata":{}},{"name":"FT_Percentage","type":"double","nullable":true,"metadata":{}},{"name":"REB","type":"long","nullable":true,"metadata":{}},{"name":"AST","type":"long","nullable":true,"metadata":{}},{"name":"BLK","type":"long","nullable":true,"metadata":{}},{"name":"STL","type":"long","nullable":true,"metadata":{}},{"name":"PF","type":"long","nullable":true,"metadata":{}},{"name":"TO","type":"long","nullable":true,"metadata":{}},{"name":"PTS","type":"long","nullable":true,"metadata":{}}]},List(),Map(),Some(1749311590895)), logSegment=LogSegment(s3a://mybucket/sc_stats_db/bronze/raw_data/_delta_log,0,WrappedArray(S3AFileStatus{path=s3a://mybucket/sc_stats_db/bronze/raw_data/_delta_log/00000000000000000000.json; isDirectory=false; length=3839; replication=1; blocksize=33554432; modification_time=1749311595537; access_time=0; owner=***; group=***; permission=rw-rw-rw-; isSymlink=false; hasAcl=false; isEncrypted=true; isErasureCoded=false} isEmptyDirectory=FALSE eTag=b4b547c69ede3516fbb7bb8167cbc9d3 versionId=null),org.apache.spark.sql.delta.EmptyCheckpointProvider$@3200bfd8,1749311595537), checksumOpt=None)
[2025-06-07T15:53:29.626+0000] {spark_submit.py:644} INFO - Successfully read bronze table
[2025-06-07T15:53:29.720+0000] {spark_submit.py:644} INFO - Writing data to Silver layer
[2025-06-07T15:53:29.793+0000] {spark_submit.py:644} INFO - 25/06/07 15:53:29 WARN SparkStringUtils: Truncated the string representation of a plan since it was too large. This behavior can be adjusted by setting 'spark.sql.debug.maxToStringFields'.
[2025-06-07T15:53:29.846+0000] {spark_submit.py:644} INFO - 25/06/07 15:53:29 INFO DelegatingLogStore: LogStore `LogStoreAdapter(io.delta.storage.S3SingleDriverLogStore)` is used for scheme `s3a`
[2025-06-07T15:53:29.853+0000] {spark_submit.py:644} INFO - 25/06/07 15:53:29 INFO DeltaLog: Creating initial snapshot without metadata, because the directory is empty
[2025-06-07T15:53:29.855+0000] {spark_submit.py:644} INFO - 25/06/07 15:53:29 INFO InitialSnapshot: [tableId=572a5ade-e616-41d2-bf27-e0de216be5a3] Created snapshot InitialSnapshot(path=s3a://mybucket/sc_stats_db/silver/transformed_data/_delta_log, version=-1, metadata=Metadata(9f5339a7-12dc-486a-aa30-ea291b4d6d74,null,null,Format(parquet,Map()),null,List(),Map(),Some(1749311609855)), logSegment=LogSegment(s3a://mybucket/sc_stats_db/silver/transformed_data/_delta_log,-1,List(),org.apache.spark.sql.delta.EmptyCheckpointProvider$@3200bfd8,-1), checksumOpt=None)
[2025-06-07T15:53:29.896+0000] {spark_submit.py:644} INFO - 25/06/07 15:53:29 INFO BlockManagerInfo: Removed broadcast_0_piece0 on b5e5641a3f5a:32903 in memory (size: 36.2 KiB, free: 434.4 MiB)
[2025-06-07T15:53:29.899+0000] {spark_submit.py:644} INFO - 25/06/07 15:53:29 INFO BlockManagerInfo: Removed broadcast_0_piece0 on 172.19.0.7:39917 in memory (size: 36.2 KiB, free: 1048.8 MiB)
[2025-06-07T15:53:29.902+0000] {spark_submit.py:644} INFO - 25/06/07 15:53:29 INFO DeltaLog: No delta log found for the Delta table at s3a://mybucket/sc_stats_db/silver/transformed_data/_delta_log
[2025-06-07T15:53:29.902+0000] {spark_submit.py:644} INFO - 25/06/07 15:53:29 INFO InitialSnapshot: [tableId=9f5339a7-12dc-486a-aa30-ea291b4d6d74] Created snapshot InitialSnapshot(path=s3a://mybucket/sc_stats_db/silver/transformed_data/_delta_log, version=-1, metadata=Metadata(38848d9d-43b1-406a-ad33-9520a1f8ea1e,null,null,Format(parquet,Map()),null,List(),Map(),Some(1749311609902)), logSegment=LogSegment(s3a://mybucket/sc_stats_db/silver/transformed_data/_delta_log,-1,List(),org.apache.spark.sql.delta.EmptyCheckpointProvider$@3200bfd8,-1), checksumOpt=None)
[2025-06-07T15:53:29.934+0000] {spark_submit.py:644} INFO - 25/06/07 15:53:29 INFO OptimisticTransaction: [tableId=38848d9d,txnId=6d0d6b70] Updated metadata from - to Metadata(f55065e3-5b96-4330-a530-1eddc6979537,null,null,Format(parquet,Map()),{"type":"struct","fields":[{"name":"Season_year","type":"string","nullable":true,"metadata":{}},{"name":"Season_div","type":"string","nullable":true,"metadata":{}},{"name":"Date","type":"date","nullable":true,"metadata":{}},{"name":"OPP","type":"string","nullable":true,"metadata":{}},{"name":"Result","type":"string","nullable":true,"metadata":{}},{"name":"T_Score","type":"long","nullable":true,"metadata":{}},{"name":"O_Score","type":"long","nullable":true,"metadata":{}},{"name":"MIN","type":"double","nullable":true,"metadata":{}},{"name":"FG","type":"string","nullable":true,"metadata":{}},{"name":"FGM","type":"long","nullable":true,"metadata":{}},{"name":"FGA","type":"long","nullable":true,"metadata":{}},{"name":"FG_Percentage","type":"double","nullable":true,"metadata":{}},{"name":"3PT","type":"string","nullable":true,"metadata":{}},{"name":"3PTM","type":"long","nullable":true,"metadata":{}},{"name":"3PTA","type":"long","nullable":true,"metadata":{}},{"name":"3P_Percentage","type":"double","nullable":true,"metadata":{}},{"name":"FT","type":"string","nullable":true,"metadata":{}},{"name":"FTM","type":"long","nullable":true,"metadata":{}},{"name":"FTA","type":"long","nullable":true,"metadata":{}},{"name":"FT_Percentage","type":"double","nullable":true,"metadata":{}},{"name":"REB","type":"long","nullable":true,"metadata":{}},{"name":"AST","type":"long","nullable":true,"metadata":{}},{"name":"BLK","type":"long","nullable":true,"metadata":{}},{"name":"STL","type":"long","nullable":true,"metadata":{}},{"name":"PF","type":"long","nullable":true,"metadata":{}},{"name":"TO","type":"long","nullable":true,"metadata":{}},{"name":"PTS","type":"long","nullable":true,"metadata":{}},{"name":"Point_Difference","type":"long","nullable":true,"metadata":{}}]},ArrayBuffer(),Map(),Some(1749311609921))
[2025-06-07T15:53:30.157+0000] {spark_submit.py:644} INFO - 25/06/07 15:53:30 INFO PrepareDeltaScan: DELTA: Filtering files for query
[2025-06-07T15:53:30.159+0000] {spark_submit.py:644} INFO - 25/06/07 15:53:30 INFO Snapshot: [tableId=9e663b76-69fe-4dd4-b26d-29bc9e7c617a] DELTA: Compute snapshot for version: 0
[2025-06-07T15:53:30.166+0000] {spark_submit.py:644} INFO - 25/06/07 15:53:30 INFO MemoryStore: Block broadcast_2 stored as values in memory (estimated size 205.0 KiB, free 434.2 MiB)
[2025-06-07T15:53:30.171+0000] {spark_submit.py:644} INFO - 25/06/07 15:53:30 INFO MemoryStore: Block broadcast_2_piece0 stored as bytes in memory (estimated size 36.0 KiB, free 434.2 MiB)
[2025-06-07T15:53:30.171+0000] {spark_submit.py:644} INFO - 25/06/07 15:53:30 INFO BlockManagerInfo: Added broadcast_2_piece0 in memory on b5e5641a3f5a:32903 (size: 36.0 KiB, free: 434.4 MiB)
[2025-06-07T15:53:30.172+0000] {spark_submit.py:644} INFO - 25/06/07 15:53:30 INFO SparkContext: Created broadcast 2 from $anonfun$recordDeltaOperationInternal$1 at DatabricksLogging.scala:128
[2025-06-07T15:53:30.409+0000] {spark_submit.py:644} INFO - 25/06/07 15:53:30 INFO DataSourceStrategy: Pruning directories with:
[2025-06-07T15:53:30.410+0000] {spark_submit.py:644} INFO - 25/06/07 15:53:30 INFO FileSourceStrategy: Pushed Filters:
[2025-06-07T15:53:30.410+0000] {spark_submit.py:644} INFO - 25/06/07 15:53:30 INFO FileSourceStrategy: Post-Scan Filters:
[2025-06-07T15:53:30.544+0000] {spark_submit.py:644} INFO - 25/06/07 15:53:30 INFO CodeGenerator: Code generated in 58.920375 ms
[2025-06-07T15:53:30.549+0000] {spark_submit.py:644} INFO - 25/06/07 15:53:30 INFO MemoryStore: Block broadcast_3 stored as values in memory (estimated size 205.3 KiB, free 434.0 MiB)
[2025-06-07T15:53:30.550+0000] {spark_submit.py:644} INFO - 25/06/07 15:53:30 INFO MemoryStore: Block broadcast_3_piece0 stored as bytes in memory (estimated size 36.2 KiB, free 433.9 MiB)
[2025-06-07T15:53:30.550+0000] {spark_submit.py:644} INFO - 25/06/07 15:53:30 INFO BlockManagerInfo: Added broadcast_3_piece0 in memory on b5e5641a3f5a:32903 (size: 36.2 KiB, free: 434.3 MiB)
[2025-06-07T15:53:30.550+0000] {spark_submit.py:644} INFO - 25/06/07 15:53:30 INFO SparkContext: Created broadcast 3 from $anonfun$recordDeltaOperationInternal$1 at DatabricksLogging.scala:128
[2025-06-07T15:53:30.551+0000] {spark_submit.py:644} INFO - 25/06/07 15:53:30 INFO FileSourceScanExec: Planning scan with bin packing, max size: 4194304 bytes, open cost is considered as scanning 4194304 bytes.
[2025-06-07T15:53:30.591+0000] {spark_submit.py:644} INFO - 25/06/07 15:53:30 INFO DAGScheduler: Registering RDD 7 ($anonfun$recordDeltaOperationInternal$1 at DatabricksLogging.scala:128) as input to shuffle 0
[2025-06-07T15:53:30.591+0000] {spark_submit.py:644} INFO - 25/06/07 15:53:30 INFO DAGScheduler: Got map stage job 1 ($anonfun$recordDeltaOperationInternal$1 at DatabricksLogging.scala:128) with 1 output partitions
[2025-06-07T15:53:30.592+0000] {spark_submit.py:644} INFO - 25/06/07 15:53:30 INFO DAGScheduler: Final stage: ShuffleMapStage 1 ($anonfun$recordDeltaOperationInternal$1 at DatabricksLogging.scala:128)
[2025-06-07T15:53:30.592+0000] {spark_submit.py:644} INFO - 25/06/07 15:53:30 INFO DAGScheduler: Parents of final stage: List()
[2025-06-07T15:53:30.592+0000] {spark_submit.py:644} INFO - 25/06/07 15:53:30 INFO DAGScheduler: Missing parents: List()
[2025-06-07T15:53:30.593+0000] {spark_submit.py:644} INFO - 25/06/07 15:53:30 INFO DAGScheduler: Submitting ShuffleMapStage 1 (MapPartitionsRDD[7] at $anonfun$recordDeltaOperationInternal$1 at DatabricksLogging.scala:128), which has no missing parents
[2025-06-07T15:53:30.600+0000] {spark_submit.py:644} INFO - 25/06/07 15:53:30 INFO MemoryStore: Block broadcast_4 stored as values in memory (estimated size 105.6 KiB, free 433.8 MiB)
[2025-06-07T15:53:30.601+0000] {spark_submit.py:644} INFO - 25/06/07 15:53:30 INFO MemoryStore: Block broadcast_4_piece0 stored as bytes in memory (estimated size 32.6 KiB, free 433.8 MiB)
[2025-06-07T15:53:30.602+0000] {spark_submit.py:644} INFO - 25/06/07 15:53:30 INFO BlockManagerInfo: Added broadcast_4_piece0 in memory on b5e5641a3f5a:32903 (size: 32.6 KiB, free: 434.3 MiB)
[2025-06-07T15:53:30.602+0000] {spark_submit.py:644} INFO - 25/06/07 15:53:30 INFO SparkContext: Created broadcast 4 from broadcast at DAGScheduler.scala:1585
[2025-06-07T15:53:30.603+0000] {spark_submit.py:644} INFO - 25/06/07 15:53:30 INFO DAGScheduler: Submitting 1 missing tasks from ShuffleMapStage 1 (MapPartitionsRDD[7] at $anonfun$recordDeltaOperationInternal$1 at DatabricksLogging.scala:128) (first 15 tasks are for partitions Vector(0))
[2025-06-07T15:53:30.603+0000] {spark_submit.py:644} INFO - 25/06/07 15:53:30 INFO TaskSchedulerImpl: Adding task set 1.0 with 1 tasks resource profile 0
[2025-06-07T15:53:30.605+0000] {spark_submit.py:644} INFO - 25/06/07 15:53:30 INFO TaskSetManager: Starting task 0.0 in stage 1.0 (TID 1) (172.19.0.7, executor 0, partition 0, PROCESS_LOCAL, 10831 bytes)
[2025-06-07T15:53:30.622+0000] {spark_submit.py:644} INFO - 25/06/07 15:53:30 INFO BlockManagerInfo: Added broadcast_4_piece0 in memory on 172.19.0.7:39917 (size: 32.6 KiB, free: 1048.8 MiB)
[2025-06-07T15:53:30.887+0000] {spark_submit.py:644} INFO - 25/06/07 15:53:30 INFO BlockManagerInfo: Added broadcast_3_piece0 in memory on 172.19.0.7:39917 (size: 36.2 KiB, free: 1048.7 MiB)
[2025-06-07T15:53:31.387+0000] {spark_submit.py:644} INFO - 25/06/07 15:53:31 INFO TaskSetManager: Finished task 0.0 in stage 1.0 (TID 1) in 783 ms on 172.19.0.7 (executor 0) (1/1)
[2025-06-07T15:53:31.388+0000] {spark_submit.py:644} INFO - 25/06/07 15:53:31 INFO TaskSchedulerImpl: Removed TaskSet 1.0, whose tasks have all completed, from pool
[2025-06-07T15:53:31.389+0000] {spark_submit.py:644} INFO - 25/06/07 15:53:31 INFO DAGScheduler: ShuffleMapStage 1 ($anonfun$recordDeltaOperationInternal$1 at DatabricksLogging.scala:128) finished in 0.795 s
[2025-06-07T15:53:31.389+0000] {spark_submit.py:644} INFO - 25/06/07 15:53:31 INFO DAGScheduler: looking for newly runnable stages
[2025-06-07T15:53:31.389+0000] {spark_submit.py:644} INFO - 25/06/07 15:53:31 INFO DAGScheduler: running: Set()
[2025-06-07T15:53:31.389+0000] {spark_submit.py:644} INFO - 25/06/07 15:53:31 INFO DAGScheduler: waiting: Set()
[2025-06-07T15:53:31.390+0000] {spark_submit.py:644} INFO - 25/06/07 15:53:31 INFO DAGScheduler: failed: Set()
[2025-06-07T15:53:31.410+0000] {spark_submit.py:644} INFO - 25/06/07 15:53:31 INFO BlockManagerInfo: Removed broadcast_4_piece0 on b5e5641a3f5a:32903 in memory (size: 32.6 KiB, free: 434.3 MiB)
[2025-06-07T15:53:31.412+0000] {spark_submit.py:644} INFO - 25/06/07 15:53:31 INFO BlockManagerInfo: Removed broadcast_4_piece0 on 172.19.0.7:39917 in memory (size: 32.6 KiB, free: 1048.8 MiB)
[2025-06-07T15:53:31.616+0000] {spark_submit.py:644} INFO - 25/06/07 15:53:31 INFO CodeGenerator: Generated method too long to be JIT compiled: org.apache.spark.sql.catalyst.expressions.GeneratedClass$GeneratedIteratorForCodegenStage3.serializefromobject_doConsume_0$ is 24899 bytes
[2025-06-07T15:53:31.616+0000] {spark_submit.py:644} INFO - 25/06/07 15:53:31 INFO CodeGenerator: Code generated in 133.367916 ms
[2025-06-07T15:53:31.669+0000] {spark_submit.py:644} INFO - 25/06/07 15:53:31 INFO CodeGenerator: Code generated in 37.784833 ms
[2025-06-07T15:53:31.839+0000] {spark_submit.py:644} INFO - 25/06/07 15:53:31 INFO CodeGenerator: Code generated in 36.851375 ms
[2025-06-07T15:53:31.845+0000] {spark_submit.py:644} INFO - 25/06/07 15:53:31 INFO DAGScheduler: Registering RDD 17 ($anonfun$recordDeltaOperationInternal$1 at DatabricksLogging.scala:128) as input to shuffle 1
[2025-06-07T15:53:31.845+0000] {spark_submit.py:644} INFO - 25/06/07 15:53:31 INFO DAGScheduler: Got map stage job 2 ($anonfun$recordDeltaOperationInternal$1 at DatabricksLogging.scala:128) with 50 output partitions
[2025-06-07T15:53:31.845+0000] {spark_submit.py:644} INFO - 25/06/07 15:53:31 INFO DAGScheduler: Final stage: ShuffleMapStage 3 ($anonfun$recordDeltaOperationInternal$1 at DatabricksLogging.scala:128)
[2025-06-07T15:53:31.846+0000] {spark_submit.py:644} INFO - 25/06/07 15:53:31 INFO DAGScheduler: Parents of final stage: List(ShuffleMapStage 2)
[2025-06-07T15:53:31.848+0000] {spark_submit.py:644} INFO - 25/06/07 15:53:31 INFO DAGScheduler: Missing parents: List()
[2025-06-07T15:53:31.848+0000] {spark_submit.py:644} INFO - 25/06/07 15:53:31 INFO DAGScheduler: Submitting ShuffleMapStage 3 (MapPartitionsRDD[17] at $anonfun$recordDeltaOperationInternal$1 at DatabricksLogging.scala:128), which has no missing parents
[2025-06-07T15:53:31.871+0000] {spark_submit.py:644} INFO - 25/06/07 15:53:31 INFO MemoryStore: Block broadcast_5 stored as values in memory (estimated size 602.6 KiB, free 433.3 MiB)
[2025-06-07T15:53:31.872+0000] {spark_submit.py:644} INFO - 25/06/07 15:53:31 INFO MemoryStore: Block broadcast_5_piece0 stored as bytes in memory (estimated size 138.1 KiB, free 433.2 MiB)
[2025-06-07T15:53:31.873+0000] {spark_submit.py:644} INFO - 25/06/07 15:53:31 INFO BlockManagerInfo: Added broadcast_5_piece0 in memory on b5e5641a3f5a:32903 (size: 138.1 KiB, free: 434.2 MiB)
[2025-06-07T15:53:31.873+0000] {spark_submit.py:644} INFO - 25/06/07 15:53:31 INFO SparkContext: Created broadcast 5 from broadcast at DAGScheduler.scala:1585
[2025-06-07T15:53:31.873+0000] {spark_submit.py:644} INFO - 25/06/07 15:53:31 INFO DAGScheduler: Submitting 50 missing tasks from ShuffleMapStage 3 (MapPartitionsRDD[17] at $anonfun$recordDeltaOperationInternal$1 at DatabricksLogging.scala:128) (first 15 tasks are for partitions Vector(0, 1, 2, 3, 4, 5, 6, 7, 8, 9, 10, 11, 12, 13, 14))
[2025-06-07T15:53:31.874+0000] {spark_submit.py:644} INFO - 25/06/07 15:53:31 INFO TaskSchedulerImpl: Adding task set 3.0 with 50 tasks resource profile 0
[2025-06-07T15:53:31.877+0000] {spark_submit.py:644} INFO - 25/06/07 15:53:31 INFO TaskSetManager: Starting task 11.0 in stage 3.0 (TID 2) (172.19.0.7, executor 0, partition 11, NODE_LOCAL, 10175 bytes)
[2025-06-07T15:53:31.877+0000] {spark_submit.py:644} INFO - 25/06/07 15:53:31 INFO TaskSetManager: Starting task 42.0 in stage 3.0 (TID 3) (172.19.0.7, executor 0, partition 42, NODE_LOCAL, 10175 bytes)
[2025-06-07T15:53:31.877+0000] {spark_submit.py:644} INFO - 25/06/07 15:53:31 INFO TaskSetManager: Starting task 0.0 in stage 3.0 (TID 4) (172.19.0.7, executor 0, partition 0, PROCESS_LOCAL, 10175 bytes)
[2025-06-07T15:53:31.878+0000] {spark_submit.py:644} INFO - 25/06/07 15:53:31 INFO TaskSetManager: Starting task 1.0 in stage 3.0 (TID 5) (172.19.0.7, executor 0, partition 1, PROCESS_LOCAL, 10175 bytes)
[2025-06-07T15:53:31.891+0000] {spark_submit.py:644} INFO - 25/06/07 15:53:31 INFO BlockManagerInfo: Added broadcast_5_piece0 in memory on 172.19.0.7:39917 (size: 138.1 KiB, free: 1048.6 MiB)
[2025-06-07T15:53:32.068+0000] {spark_submit.py:644} INFO - 25/06/07 15:53:32 INFO MapOutputTrackerMasterEndpoint: Asked to send map output locations for shuffle 0 to 172.19.0.7:49852
[2025-06-07T15:53:32.434+0000] {spark_submit.py:644} INFO - 25/06/07 15:53:32 INFO BlockManagerInfo: Added rdd_14_0 in memory on 172.19.0.7:39917 (size: 46.0 B, free: 1048.6 MiB)
[2025-06-07T15:53:32.435+0000] {spark_submit.py:644} INFO - 25/06/07 15:53:32 INFO BlockManagerInfo: Added rdd_14_1 in memory on 172.19.0.7:39917 (size: 46.0 B, free: 1048.6 MiB)
[2025-06-07T15:53:32.436+0000] {spark_submit.py:644} INFO - 25/06/07 15:53:32 INFO BlockManagerInfo: Added rdd_14_11 in memory on 172.19.0.7:39917 (size: 798.0 B, free: 1048.6 MiB)
[2025-06-07T15:53:32.456+0000] {spark_submit.py:644} INFO - 25/06/07 15:53:32 INFO BlockManagerInfo: Added rdd_14_42 in memory on 172.19.0.7:39917 (size: 688.0 B, free: 1048.6 MiB)
[2025-06-07T15:53:32.798+0000] {spark_submit.py:644} INFO - 25/06/07 15:53:32 INFO TaskSetManager: Starting task 2.0 in stage 3.0 (TID 6) (172.19.0.7, executor 0, partition 2, PROCESS_LOCAL, 10175 bytes)
[2025-06-07T15:53:32.800+0000] {spark_submit.py:644} INFO - 25/06/07 15:53:32 INFO TaskSetManager: Starting task 3.0 in stage 3.0 (TID 7) (172.19.0.7, executor 0, partition 3, PROCESS_LOCAL, 10175 bytes)
[2025-06-07T15:53:32.801+0000] {spark_submit.py:644} INFO - 25/06/07 15:53:32 INFO TaskSetManager: Finished task 11.0 in stage 3.0 (TID 2) in 924 ms on 172.19.0.7 (executor 0) (1/50)
[2025-06-07T15:53:32.803+0000] {spark_submit.py:644} INFO - 25/06/07 15:53:32 INFO TaskSetManager: Finished task 1.0 in stage 3.0 (TID 5) in 924 ms on 172.19.0.7 (executor 0) (2/50)
[2025-06-07T15:53:32.804+0000] {spark_submit.py:644} INFO - 25/06/07 15:53:32 INFO TaskSetManager: Starting task 4.0 in stage 3.0 (TID 8) (172.19.0.7, executor 0, partition 4, PROCESS_LOCAL, 10175 bytes)
[2025-06-07T15:53:32.806+0000] {spark_submit.py:644} INFO - 25/06/07 15:53:32 INFO TaskSetManager: Finished task 42.0 in stage 3.0 (TID 3) in 925 ms on 172.19.0.7 (executor 0) (3/50)
[2025-06-07T15:53:32.808+0000] {spark_submit.py:644} INFO - 25/06/07 15:53:32 INFO TaskSetManager: Starting task 5.0 in stage 3.0 (TID 9) (172.19.0.7, executor 0, partition 5, PROCESS_LOCAL, 10175 bytes)
[2025-06-07T15:53:32.808+0000] {spark_submit.py:644} INFO - 25/06/07 15:53:32 INFO TaskSetManager: Finished task 0.0 in stage 3.0 (TID 4) in 927 ms on 172.19.0.7 (executor 0) (4/50)
[2025-06-07T15:53:32.936+0000] {spark_submit.py:644} INFO - 25/06/07 15:53:32 INFO BlockManagerInfo: Added rdd_14_4 in memory on 172.19.0.7:39917 (size: 46.0 B, free: 1048.6 MiB)
[2025-06-07T15:53:32.944+0000] {spark_submit.py:644} INFO - 25/06/07 15:53:32 INFO BlockManagerInfo: Added rdd_14_2 in memory on 172.19.0.7:39917 (size: 46.0 B, free: 1048.6 MiB)
[2025-06-07T15:53:32.973+0000] {spark_submit.py:644} INFO - 25/06/07 15:53:32 INFO BlockManagerInfo: Added rdd_14_3 in memory on 172.19.0.7:39917 (size: 46.0 B, free: 1048.6 MiB)
[2025-06-07T15:53:32.973+0000] {spark_submit.py:644} INFO - 25/06/07 15:53:32 INFO BlockManagerInfo: Added rdd_14_5 in memory on 172.19.0.7:39917 (size: 46.0 B, free: 1048.6 MiB)
[2025-06-07T15:53:32.978+0000] {spark_submit.py:644} INFO - 25/06/07 15:53:32 INFO TaskSetManager: Starting task 6.0 in stage 3.0 (TID 10) (172.19.0.7, executor 0, partition 6, PROCESS_LOCAL, 10175 bytes)
[2025-06-07T15:53:32.986+0000] {spark_submit.py:644} INFO - 25/06/07 15:53:32 INFO TaskSetManager: Finished task 4.0 in stage 3.0 (TID 8) in 184 ms on 172.19.0.7 (executor 0) (5/50)
[2025-06-07T15:53:32.994+0000] {spark_submit.py:644} INFO - 25/06/07 15:53:32 INFO TaskSetManager: Starting task 7.0 in stage 3.0 (TID 11) (172.19.0.7, executor 0, partition 7, PROCESS_LOCAL, 10175 bytes)
[2025-06-07T15:53:32.995+0000] {spark_submit.py:644} INFO - 25/06/07 15:53:32 INFO TaskSetManager: Finished task 2.0 in stage 3.0 (TID 6) in 196 ms on 172.19.0.7 (executor 0) (6/50)
[2025-06-07T15:53:33.017+0000] {spark_submit.py:644} INFO - 25/06/07 15:53:33 INFO TaskSetManager: Starting task 8.0 in stage 3.0 (TID 12) (172.19.0.7, executor 0, partition 8, PROCESS_LOCAL, 10175 bytes)
[2025-06-07T15:53:33.019+0000] {spark_submit.py:644} INFO - 25/06/07 15:53:33 INFO TaskSetManager: Finished task 5.0 in stage 3.0 (TID 9) in 214 ms on 172.19.0.7 (executor 0) (7/50)
[2025-06-07T15:53:33.020+0000] {spark_submit.py:644} INFO - 25/06/07 15:53:33 INFO TaskSetManager: Starting task 9.0 in stage 3.0 (TID 13) (172.19.0.7, executor 0, partition 9, PROCESS_LOCAL, 10175 bytes)
[2025-06-07T15:53:33.022+0000] {spark_submit.py:644} INFO - 25/06/07 15:53:33 INFO TaskSetManager: Finished task 3.0 in stage 3.0 (TID 7) in 221 ms on 172.19.0.7 (executor 0) (8/50)
[2025-06-07T15:53:33.088+0000] {spark_submit.py:644} INFO - 25/06/07 15:53:33 INFO BlockManagerInfo: Added rdd_14_6 in memory on 172.19.0.7:39917 (size: 46.0 B, free: 1048.6 MiB)
[2025-06-07T15:53:33.091+0000] {spark_submit.py:644} INFO - 25/06/07 15:53:33 INFO BlockManagerInfo: Added rdd_14_7 in memory on 172.19.0.7:39917 (size: 46.0 B, free: 1048.6 MiB)
[2025-06-07T15:53:33.125+0000] {spark_submit.py:644} INFO - 25/06/07 15:53:33 INFO BlockManagerInfo: Added rdd_14_8 in memory on 172.19.0.7:39917 (size: 46.0 B, free: 1048.6 MiB)
[2025-06-07T15:53:33.126+0000] {spark_submit.py:644} INFO - 25/06/07 15:53:33 INFO BlockManagerInfo: Added rdd_14_9 in memory on 172.19.0.7:39917 (size: 46.0 B, free: 1048.6 MiB)
[2025-06-07T15:53:33.130+0000] {spark_submit.py:644} INFO - 25/06/07 15:53:33 INFO TaskSetManager: Starting task 10.0 in stage 3.0 (TID 14) (172.19.0.7, executor 0, partition 10, PROCESS_LOCAL, 10175 bytes)
[2025-06-07T15:53:33.131+0000] {spark_submit.py:644} INFO - 25/06/07 15:53:33 INFO TaskSetManager: Starting task 12.0 in stage 3.0 (TID 15) (172.19.0.7, executor 0, partition 12, PROCESS_LOCAL, 10175 bytes)
[2025-06-07T15:53:33.132+0000] {spark_submit.py:644} INFO - 25/06/07 15:53:33 INFO TaskSetManager: Finished task 7.0 in stage 3.0 (TID 11) in 137 ms on 172.19.0.7 (executor 0) (9/50)
[2025-06-07T15:53:33.133+0000] {spark_submit.py:644} INFO - 25/06/07 15:53:33 INFO TaskSetManager: Finished task 6.0 in stage 3.0 (TID 10) in 154 ms on 172.19.0.7 (executor 0) (10/50)
[2025-06-07T15:53:33.164+0000] {spark_submit.py:644} INFO - 25/06/07 15:53:33 INFO TaskSetManager: Starting task 13.0 in stage 3.0 (TID 16) (172.19.0.7, executor 0, partition 13, PROCESS_LOCAL, 10175 bytes)
[2025-06-07T15:53:33.165+0000] {spark_submit.py:644} INFO - 25/06/07 15:53:33 INFO TaskSetManager: Finished task 8.0 in stage 3.0 (TID 12) in 150 ms on 172.19.0.7 (executor 0) (11/50)
[2025-06-07T15:53:33.169+0000] {spark_submit.py:644} INFO - 25/06/07 15:53:33 INFO TaskSetManager: Starting task 14.0 in stage 3.0 (TID 17) (172.19.0.7, executor 0, partition 14, PROCESS_LOCAL, 10175 bytes)
[2025-06-07T15:53:33.172+0000] {spark_submit.py:644} INFO - 25/06/07 15:53:33 INFO TaskSetManager: Finished task 9.0 in stage 3.0 (TID 13) in 151 ms on 172.19.0.7 (executor 0) (12/50)
[2025-06-07T15:53:33.216+0000] {spark_submit.py:644} INFO - 25/06/07 15:53:33 INFO BlockManagerInfo: Added rdd_14_10 in memory on 172.19.0.7:39917 (size: 46.0 B, free: 1048.6 MiB)
[2025-06-07T15:53:33.226+0000] {spark_submit.py:644} INFO - 25/06/07 15:53:33 INFO BlockManagerInfo: Added rdd_14_12 in memory on 172.19.0.7:39917 (size: 46.0 B, free: 1048.6 MiB)
[2025-06-07T15:53:33.253+0000] {spark_submit.py:644} INFO - 25/06/07 15:53:33 INFO TaskSetManager: Starting task 15.0 in stage 3.0 (TID 18) (172.19.0.7, executor 0, partition 15, PROCESS_LOCAL, 10175 bytes)
[2025-06-07T15:53:33.254+0000] {spark_submit.py:644} INFO - 25/06/07 15:53:33 INFO TaskSetManager: Finished task 10.0 in stage 3.0 (TID 14) in 124 ms on 172.19.0.7 (executor 0) (13/50)
[2025-06-07T15:53:33.256+0000] {spark_submit.py:644} INFO - 25/06/07 15:53:33 INFO BlockManagerInfo: Added rdd_14_13 in memory on 172.19.0.7:39917 (size: 46.0 B, free: 1048.6 MiB)
[2025-06-07T15:53:33.264+0000] {spark_submit.py:644} INFO - 25/06/07 15:53:33 INFO BlockManagerInfo: Added rdd_14_14 in memory on 172.19.0.7:39917 (size: 46.0 B, free: 1048.6 MiB)
[2025-06-07T15:53:33.266+0000] {spark_submit.py:644} INFO - 25/06/07 15:53:33 INFO TaskSetManager: Starting task 16.0 in stage 3.0 (TID 19) (172.19.0.7, executor 0, partition 16, PROCESS_LOCAL, 10175 bytes)
[2025-06-07T15:53:33.267+0000] {spark_submit.py:644} INFO - 25/06/07 15:53:33 INFO TaskSetManager: Finished task 12.0 in stage 3.0 (TID 15) in 136 ms on 172.19.0.7 (executor 0) (14/50)
[2025-06-07T15:53:33.330+0000] {spark_submit.py:644} INFO - 25/06/07 15:53:33 INFO TaskSetManager: Starting task 17.0 in stage 3.0 (TID 20) (172.19.0.7, executor 0, partition 17, PROCESS_LOCAL, 10175 bytes)
[2025-06-07T15:53:33.342+0000] {spark_submit.py:644} INFO - 25/06/07 15:53:33 INFO TaskSetManager: Finished task 13.0 in stage 3.0 (TID 16) in 168 ms on 172.19.0.7 (executor 0) (15/50)
[2025-06-07T15:53:33.343+0000] {spark_submit.py:644} INFO - 25/06/07 15:53:33 INFO TaskSetManager: Starting task 18.0 in stage 3.0 (TID 21) (172.19.0.7, executor 0, partition 18, PROCESS_LOCAL, 10175 bytes)
[2025-06-07T15:53:33.343+0000] {spark_submit.py:644} INFO - 25/06/07 15:53:33 INFO TaskSetManager: Finished task 14.0 in stage 3.0 (TID 17) in 175 ms on 172.19.0.7 (executor 0) (16/50)
[2025-06-07T15:53:33.373+0000] {spark_submit.py:644} INFO - 25/06/07 15:53:33 INFO BlockManagerInfo: Added rdd_14_15 in memory on 172.19.0.7:39917 (size: 46.0 B, free: 1048.6 MiB)
[2025-06-07T15:53:33.378+0000] {spark_submit.py:644} INFO - 25/06/07 15:53:33 INFO BlockManagerInfo: Added rdd_14_16 in memory on 172.19.0.7:39917 (size: 46.0 B, free: 1048.6 MiB)
[2025-06-07T15:53:33.403+0000] {spark_submit.py:644} INFO - 25/06/07 15:53:33 INFO TaskSetManager: Starting task 19.0 in stage 3.0 (TID 22) (172.19.0.7, executor 0, partition 19, PROCESS_LOCAL, 10175 bytes)
[2025-06-07T15:53:33.405+0000] {spark_submit.py:644} INFO - 25/06/07 15:53:33 INFO TaskSetManager: Finished task 16.0 in stage 3.0 (TID 19) in 137 ms on 172.19.0.7 (executor 0) (17/50)
[2025-06-07T15:53:33.406+0000] {spark_submit.py:644} INFO - 25/06/07 15:53:33 INFO BlockManagerInfo: Added rdd_14_18 in memory on 172.19.0.7:39917 (size: 46.0 B, free: 1048.6 MiB)
[2025-06-07T15:53:33.407+0000] {spark_submit.py:644} INFO - 25/06/07 15:53:33 INFO TaskSetManager: Starting task 20.0 in stage 3.0 (TID 23) (172.19.0.7, executor 0, partition 20, PROCESS_LOCAL, 10175 bytes)
[2025-06-07T15:53:33.407+0000] {spark_submit.py:644} INFO - 25/06/07 15:53:33 INFO TaskSetManager: Finished task 15.0 in stage 3.0 (TID 18) in 154 ms on 172.19.0.7 (executor 0) (18/50)
[2025-06-07T15:53:33.409+0000] {spark_submit.py:644} INFO - 25/06/07 15:53:33 INFO BlockManagerInfo: Added rdd_14_17 in memory on 172.19.0.7:39917 (size: 46.0 B, free: 1048.6 MiB)
[2025-06-07T15:53:33.425+0000] {spark_submit.py:644} INFO - 25/06/07 15:53:33 INFO TaskSetManager: Starting task 21.0 in stage 3.0 (TID 24) (172.19.0.7, executor 0, partition 21, PROCESS_LOCAL, 10175 bytes)
[2025-06-07T15:53:33.429+0000] {spark_submit.py:644} INFO - 25/06/07 15:53:33 INFO TaskSetManager: Finished task 18.0 in stage 3.0 (TID 21) in 83 ms on 172.19.0.7 (executor 0) (19/50)
[2025-06-07T15:53:33.429+0000] {spark_submit.py:644} INFO - 25/06/07 15:53:33 INFO TaskSetManager: Starting task 22.0 in stage 3.0 (TID 25) (172.19.0.7, executor 0, partition 22, PROCESS_LOCAL, 10175 bytes)
[2025-06-07T15:53:33.430+0000] {spark_submit.py:644} INFO - 25/06/07 15:53:33 INFO TaskSetManager: Finished task 17.0 in stage 3.0 (TID 20) in 100 ms on 172.19.0.7 (executor 0) (20/50)
[2025-06-07T15:53:33.453+0000] {spark_submit.py:644} INFO - 25/06/07 15:53:33 INFO BlockManagerInfo: Added rdd_14_19 in memory on 172.19.0.7:39917 (size: 46.0 B, free: 1048.6 MiB)
[2025-06-07T15:53:33.463+0000] {spark_submit.py:644} INFO - 25/06/07 15:53:33 INFO BlockManagerInfo: Added rdd_14_20 in memory on 172.19.0.7:39917 (size: 46.0 B, free: 1048.6 MiB)
[2025-06-07T15:53:33.478+0000] {spark_submit.py:644} INFO - 25/06/07 15:53:33 INFO TaskSetManager: Starting task 23.0 in stage 3.0 (TID 26) (172.19.0.7, executor 0, partition 23, PROCESS_LOCAL, 10175 bytes)
[2025-06-07T15:53:33.479+0000] {spark_submit.py:644} INFO - 25/06/07 15:53:33 INFO TaskSetManager: Finished task 19.0 in stage 3.0 (TID 22) in 78 ms on 172.19.0.7 (executor 0) (21/50)
[2025-06-07T15:53:33.485+0000] {spark_submit.py:644} INFO - 25/06/07 15:53:33 INFO BlockManagerInfo: Added rdd_14_21 in memory on 172.19.0.7:39917 (size: 46.0 B, free: 1048.6 MiB)
[2025-06-07T15:53:33.487+0000] {spark_submit.py:644} INFO - 25/06/07 15:53:33 INFO BlockManagerInfo: Added rdd_14_22 in memory on 172.19.0.7:39917 (size: 46.0 B, free: 1048.6 MiB)
[2025-06-07T15:53:33.489+0000] {spark_submit.py:644} INFO - 25/06/07 15:53:33 INFO TaskSetManager: Starting task 24.0 in stage 3.0 (TID 27) (172.19.0.7, executor 0, partition 24, PROCESS_LOCAL, 10175 bytes)
[2025-06-07T15:53:33.492+0000] {spark_submit.py:644} INFO - 25/06/07 15:53:33 INFO TaskSetManager: Finished task 20.0 in stage 3.0 (TID 23) in 87 ms on 172.19.0.7 (executor 0) (22/50)
[2025-06-07T15:53:33.510+0000] {spark_submit.py:644} INFO - 25/06/07 15:53:33 INFO TaskSetManager: Starting task 25.0 in stage 3.0 (TID 28) (172.19.0.7, executor 0, partition 25, PROCESS_LOCAL, 10175 bytes)
[2025-06-07T15:53:33.511+0000] {spark_submit.py:644} INFO - 25/06/07 15:53:33 INFO TaskSetManager: Finished task 21.0 in stage 3.0 (TID 24) in 86 ms on 172.19.0.7 (executor 0) (23/50)
[2025-06-07T15:53:33.512+0000] {spark_submit.py:644} INFO - 25/06/07 15:53:33 INFO TaskSetManager: Starting task 26.0 in stage 3.0 (TID 29) (172.19.0.7, executor 0, partition 26, PROCESS_LOCAL, 10175 bytes)
[2025-06-07T15:53:33.514+0000] {spark_submit.py:644} INFO - 25/06/07 15:53:33 INFO TaskSetManager: Finished task 22.0 in stage 3.0 (TID 25) in 84 ms on 172.19.0.7 (executor 0) (24/50)
[2025-06-07T15:53:33.525+0000] {spark_submit.py:644} INFO - 25/06/07 15:53:33 INFO BlockManagerInfo: Added rdd_14_23 in memory on 172.19.0.7:39917 (size: 46.0 B, free: 1048.6 MiB)
[2025-06-07T15:53:33.534+0000] {spark_submit.py:644} INFO - 25/06/07 15:53:33 INFO BlockManagerInfo: Added rdd_14_24 in memory on 172.19.0.7:39917 (size: 46.0 B, free: 1048.6 MiB)
[2025-06-07T15:53:33.551+0000] {spark_submit.py:644} INFO - 25/06/07 15:53:33 INFO TaskSetManager: Starting task 27.0 in stage 3.0 (TID 30) (172.19.0.7, executor 0, partition 27, PROCESS_LOCAL, 10175 bytes)
[2025-06-07T15:53:33.552+0000] {spark_submit.py:644} INFO - 25/06/07 15:53:33 INFO TaskSetManager: Finished task 23.0 in stage 3.0 (TID 26) in 73 ms on 172.19.0.7 (executor 0) (25/50)
[2025-06-07T15:53:33.565+0000] {spark_submit.py:644} INFO - 25/06/07 15:53:33 INFO BlockManagerInfo: Added rdd_14_25 in memory on 172.19.0.7:39917 (size: 46.0 B, free: 1048.6 MiB)
[2025-06-07T15:53:33.566+0000] {spark_submit.py:644} INFO - 25/06/07 15:53:33 INFO TaskSetManager: Starting task 28.0 in stage 3.0 (TID 31) (172.19.0.7, executor 0, partition 28, PROCESS_LOCAL, 10175 bytes)
[2025-06-07T15:53:33.566+0000] {spark_submit.py:644} INFO - 25/06/07 15:53:33 INFO TaskSetManager: Finished task 24.0 in stage 3.0 (TID 27) in 77 ms on 172.19.0.7 (executor 0) (26/50)
[2025-06-07T15:53:33.567+0000] {spark_submit.py:644} INFO - 25/06/07 15:53:33 INFO BlockManagerInfo: Added rdd_14_26 in memory on 172.19.0.7:39917 (size: 46.0 B, free: 1048.6 MiB)
[2025-06-07T15:53:33.586+0000] {spark_submit.py:644} INFO - 25/06/07 15:53:33 INFO TaskSetManager: Starting task 29.0 in stage 3.0 (TID 32) (172.19.0.7, executor 0, partition 29, PROCESS_LOCAL, 10175 bytes)
[2025-06-07T15:53:33.587+0000] {spark_submit.py:644} INFO - 25/06/07 15:53:33 INFO TaskSetManager: Finished task 26.0 in stage 3.0 (TID 29) in 75 ms on 172.19.0.7 (executor 0) (27/50)
[2025-06-07T15:53:33.587+0000] {spark_submit.py:644} INFO - 25/06/07 15:53:33 INFO TaskSetManager: Starting task 30.0 in stage 3.0 (TID 33) (172.19.0.7, executor 0, partition 30, PROCESS_LOCAL, 10175 bytes)
[2025-06-07T15:53:33.588+0000] {spark_submit.py:644} INFO - 25/06/07 15:53:33 INFO TaskSetManager: Finished task 25.0 in stage 3.0 (TID 28) in 77 ms on 172.19.0.7 (executor 0) (28/50)
[2025-06-07T15:53:33.599+0000] {spark_submit.py:644} INFO - 25/06/07 15:53:33 INFO BlockManagerInfo: Added rdd_14_27 in memory on 172.19.0.7:39917 (size: 46.0 B, free: 1048.6 MiB)
[2025-06-07T15:53:33.605+0000] {spark_submit.py:644} INFO - 25/06/07 15:53:33 INFO BlockManagerInfo: Added rdd_14_28 in memory on 172.19.0.7:39917 (size: 46.0 B, free: 1048.6 MiB)
[2025-06-07T15:53:33.618+0000] {spark_submit.py:644} INFO - 25/06/07 15:53:33 INFO TaskSetManager: Starting task 31.0 in stage 3.0 (TID 34) (172.19.0.7, executor 0, partition 31, PROCESS_LOCAL, 10175 bytes)
[2025-06-07T15:53:33.618+0000] {spark_submit.py:644} INFO - 25/06/07 15:53:33 INFO TaskSetManager: Finished task 27.0 in stage 3.0 (TID 30) in 67 ms on 172.19.0.7 (executor 0) (29/50)
[2025-06-07T15:53:33.622+0000] {spark_submit.py:644} INFO - 25/06/07 15:53:33 INFO TaskSetManager: Starting task 32.0 in stage 3.0 (TID 35) (172.19.0.7, executor 0, partition 32, PROCESS_LOCAL, 10175 bytes)
[2025-06-07T15:53:33.623+0000] {spark_submit.py:644} INFO - 25/06/07 15:53:33 INFO TaskSetManager: Finished task 28.0 in stage 3.0 (TID 31) in 58 ms on 172.19.0.7 (executor 0) (30/50)
[2025-06-07T15:53:33.636+0000] {spark_submit.py:644} INFO - 25/06/07 15:53:33 INFO BlockManagerInfo: Added rdd_14_30 in memory on 172.19.0.7:39917 (size: 46.0 B, free: 1048.6 MiB)
[2025-06-07T15:53:33.639+0000] {spark_submit.py:644} INFO - 25/06/07 15:53:33 INFO BlockManagerInfo: Added rdd_14_29 in memory on 172.19.0.7:39917 (size: 46.0 B, free: 1048.6 MiB)
[2025-06-07T15:53:33.658+0000] {spark_submit.py:644} INFO - 25/06/07 15:53:33 INFO TaskSetManager: Starting task 33.0 in stage 3.0 (TID 36) (172.19.0.7, executor 0, partition 33, PROCESS_LOCAL, 10175 bytes)
[2025-06-07T15:53:33.659+0000] {spark_submit.py:644} INFO - 25/06/07 15:53:33 INFO TaskSetManager: Finished task 30.0 in stage 3.0 (TID 33) in 72 ms on 172.19.0.7 (executor 0) (31/50)
[2025-06-07T15:53:33.662+0000] {spark_submit.py:644} INFO - 25/06/07 15:53:33 INFO BlockManagerInfo: Added rdd_14_31 in memory on 172.19.0.7:39917 (size: 46.0 B, free: 1048.6 MiB)
[2025-06-07T15:53:33.667+0000] {spark_submit.py:644} INFO - 25/06/07 15:53:33 INFO BlockManagerInfo: Added rdd_14_32 in memory on 172.19.0.7:39917 (size: 46.0 B, free: 1048.6 MiB)
[2025-06-07T15:53:33.671+0000] {spark_submit.py:644} INFO - 25/06/07 15:53:33 INFO TaskSetManager: Starting task 34.0 in stage 3.0 (TID 37) (172.19.0.7, executor 0, partition 34, PROCESS_LOCAL, 10175 bytes)
[2025-06-07T15:53:33.671+0000] {spark_submit.py:644} INFO - 25/06/07 15:53:33 INFO TaskSetManager: Finished task 29.0 in stage 3.0 (TID 32) in 83 ms on 172.19.0.7 (executor 0) (32/50)
[2025-06-07T15:53:33.685+0000] {spark_submit.py:644} INFO - 25/06/07 15:53:33 INFO TaskSetManager: Starting task 35.0 in stage 3.0 (TID 38) (172.19.0.7, executor 0, partition 35, PROCESS_LOCAL, 10175 bytes)
[2025-06-07T15:53:33.687+0000] {spark_submit.py:644} INFO - 25/06/07 15:53:33 INFO TaskSetManager: Finished task 32.0 in stage 3.0 (TID 35) in 64 ms on 172.19.0.7 (executor 0) (33/50)
[2025-06-07T15:53:33.689+0000] {spark_submit.py:644} INFO - 25/06/07 15:53:33 INFO TaskSetManager: Starting task 36.0 in stage 3.0 (TID 39) (172.19.0.7, executor 0, partition 36, PROCESS_LOCAL, 10175 bytes)
[2025-06-07T15:53:33.689+0000] {spark_submit.py:644} INFO - 25/06/07 15:53:33 INFO TaskSetManager: Finished task 31.0 in stage 3.0 (TID 34) in 71 ms on 172.19.0.7 (executor 0) (34/50)
[2025-06-07T15:53:33.697+0000] {spark_submit.py:644} INFO - 25/06/07 15:53:33 INFO BlockManagerInfo: Added rdd_14_33 in memory on 172.19.0.7:39917 (size: 46.0 B, free: 1048.6 MiB)
[2025-06-07T15:53:33.707+0000] {spark_submit.py:644} INFO - 25/06/07 15:53:33 INFO BlockManagerInfo: Added rdd_14_34 in memory on 172.19.0.7:39917 (size: 46.0 B, free: 1048.6 MiB)
[2025-06-07T15:53:33.713+0000] {spark_submit.py:644} INFO - 25/06/07 15:53:33 INFO TaskSetManager: Starting task 37.0 in stage 3.0 (TID 40) (172.19.0.7, executor 0, partition 37, PROCESS_LOCAL, 10175 bytes)
[2025-06-07T15:53:33.719+0000] {spark_submit.py:644} INFO - 25/06/07 15:53:33 INFO TaskSetManager: Finished task 33.0 in stage 3.0 (TID 36) in 56 ms on 172.19.0.7 (executor 0) (35/50)
[2025-06-07T15:53:33.719+0000] {spark_submit.py:644} INFO - 25/06/07 15:53:33 INFO BlockManagerInfo: Added rdd_14_36 in memory on 172.19.0.7:39917 (size: 46.0 B, free: 1048.6 MiB)
[2025-06-07T15:53:33.720+0000] {spark_submit.py:644} INFO - 25/06/07 15:53:33 INFO BlockManagerInfo: Added rdd_14_35 in memory on 172.19.0.7:39917 (size: 46.0 B, free: 1048.6 MiB)
[2025-06-07T15:53:33.726+0000] {spark_submit.py:644} INFO - 25/06/07 15:53:33 INFO TaskSetManager: Starting task 38.0 in stage 3.0 (TID 41) (172.19.0.7, executor 0, partition 38, PROCESS_LOCAL, 10175 bytes)
[2025-06-07T15:53:33.726+0000] {spark_submit.py:644} INFO - 25/06/07 15:53:33 INFO TaskSetManager: Finished task 34.0 in stage 3.0 (TID 37) in 59 ms on 172.19.0.7 (executor 0) (36/50)
[2025-06-07T15:53:33.738+0000] {spark_submit.py:644} INFO - 25/06/07 15:53:33 INFO TaskSetManager: Starting task 39.0 in stage 3.0 (TID 42) (172.19.0.7, executor 0, partition 39, PROCESS_LOCAL, 10175 bytes)
[2025-06-07T15:53:33.738+0000] {spark_submit.py:644} INFO - 25/06/07 15:53:33 INFO TaskSetManager: Starting task 40.0 in stage 3.0 (TID 43) (172.19.0.7, executor 0, partition 40, PROCESS_LOCAL, 10175 bytes)
[2025-06-07T15:53:33.739+0000] {spark_submit.py:644} INFO - 25/06/07 15:53:33 INFO TaskSetManager: Finished task 35.0 in stage 3.0 (TID 38) in 53 ms on 172.19.0.7 (executor 0) (37/50)
[2025-06-07T15:53:33.741+0000] {spark_submit.py:644} INFO - 25/06/07 15:53:33 INFO TaskSetManager: Finished task 36.0 in stage 3.0 (TID 39) in 51 ms on 172.19.0.7 (executor 0) (38/50)
[2025-06-07T15:53:33.746+0000] {spark_submit.py:644} INFO - 25/06/07 15:53:33 INFO BlockManagerInfo: Added rdd_14_37 in memory on 172.19.0.7:39917 (size: 46.0 B, free: 1048.6 MiB)
[2025-06-07T15:53:33.754+0000] {spark_submit.py:644} INFO - 25/06/07 15:53:33 INFO BlockManagerInfo: Added rdd_14_38 in memory on 172.19.0.7:39917 (size: 46.0 B, free: 1048.6 MiB)
[2025-06-07T15:53:33.763+0000] {spark_submit.py:644} INFO - 25/06/07 15:53:33 INFO TaskSetManager: Starting task 41.0 in stage 3.0 (TID 44) (172.19.0.7, executor 0, partition 41, PROCESS_LOCAL, 10175 bytes)
[2025-06-07T15:53:33.764+0000] {spark_submit.py:644} INFO - 25/06/07 15:53:33 INFO TaskSetManager: Finished task 37.0 in stage 3.0 (TID 40) in 51 ms on 172.19.0.7 (executor 0) (39/50)
[2025-06-07T15:53:33.775+0000] {spark_submit.py:644} INFO - 25/06/07 15:53:33 INFO TaskSetManager: Starting task 43.0 in stage 3.0 (TID 45) (172.19.0.7, executor 0, partition 43, PROCESS_LOCAL, 10175 bytes)
[2025-06-07T15:53:33.776+0000] {spark_submit.py:644} INFO - 25/06/07 15:53:33 INFO TaskSetManager: Finished task 38.0 in stage 3.0 (TID 41) in 51 ms on 172.19.0.7 (executor 0) (40/50)
[2025-06-07T15:53:33.777+0000] {spark_submit.py:644} INFO - 25/06/07 15:53:33 INFO BlockManagerInfo: Added rdd_14_40 in memory on 172.19.0.7:39917 (size: 46.0 B, free: 1048.6 MiB)
[2025-06-07T15:53:33.780+0000] {spark_submit.py:644} INFO - 25/06/07 15:53:33 INFO BlockManagerInfo: Added rdd_14_39 in memory on 172.19.0.7:39917 (size: 46.0 B, free: 1048.6 MiB)
[2025-06-07T15:53:33.795+0000] {spark_submit.py:644} INFO - 25/06/07 15:53:33 INFO BlockManagerInfo: Added rdd_14_41 in memory on 172.19.0.7:39917 (size: 46.0 B, free: 1048.6 MiB)
[2025-06-07T15:53:33.796+0000] {spark_submit.py:644} INFO - 25/06/07 15:53:33 INFO TaskSetManager: Starting task 44.0 in stage 3.0 (TID 46) (172.19.0.7, executor 0, partition 44, PROCESS_LOCAL, 10175 bytes)
[2025-06-07T15:53:33.796+0000] {spark_submit.py:644} INFO - 25/06/07 15:53:33 INFO TaskSetManager: Finished task 40.0 in stage 3.0 (TID 43) in 58 ms on 172.19.0.7 (executor 0) (41/50)
[2025-06-07T15:53:33.802+0000] {spark_submit.py:644} INFO - 25/06/07 15:53:33 INFO TaskSetManager: Starting task 45.0 in stage 3.0 (TID 47) (172.19.0.7, executor 0, partition 45, PROCESS_LOCAL, 10175 bytes)
[2025-06-07T15:53:33.803+0000] {spark_submit.py:644} INFO - 25/06/07 15:53:33 INFO TaskSetManager: Finished task 39.0 in stage 3.0 (TID 42) in 65 ms on 172.19.0.7 (executor 0) (42/50)
[2025-06-07T15:53:33.807+0000] {spark_submit.py:644} INFO - 25/06/07 15:53:33 INFO BlockManagerInfo: Added rdd_14_43 in memory on 172.19.0.7:39917 (size: 46.0 B, free: 1048.6 MiB)
[2025-06-07T15:53:33.814+0000] {spark_submit.py:644} INFO - 25/06/07 15:53:33 INFO TaskSetManager: Starting task 46.0 in stage 3.0 (TID 48) (172.19.0.7, executor 0, partition 46, PROCESS_LOCAL, 10175 bytes)
[2025-06-07T15:53:33.815+0000] {spark_submit.py:644} INFO - 25/06/07 15:53:33 INFO TaskSetManager: Finished task 41.0 in stage 3.0 (TID 44) in 51 ms on 172.19.0.7 (executor 0) (43/50)
[2025-06-07T15:53:33.821+0000] {spark_submit.py:644} INFO - 25/06/07 15:53:33 INFO TaskSetManager: Starting task 47.0 in stage 3.0 (TID 49) (172.19.0.7, executor 0, partition 47, PROCESS_LOCAL, 10175 bytes)
[2025-06-07T15:53:33.821+0000] {spark_submit.py:644} INFO - 25/06/07 15:53:33 INFO TaskSetManager: Finished task 43.0 in stage 3.0 (TID 45) in 46 ms on 172.19.0.7 (executor 0) (44/50)
[2025-06-07T15:53:33.822+0000] {spark_submit.py:644} INFO - 25/06/07 15:53:33 INFO BlockManagerInfo: Added rdd_14_44 in memory on 172.19.0.7:39917 (size: 46.0 B, free: 1048.6 MiB)
[2025-06-07T15:53:33.826+0000] {spark_submit.py:644} INFO - 25/06/07 15:53:33 INFO BlockManagerInfo: Added rdd_14_45 in memory on 172.19.0.7:39917 (size: 46.0 B, free: 1048.6 MiB)
[2025-06-07T15:53:33.838+0000] {spark_submit.py:644} INFO - 25/06/07 15:53:33 INFO TaskSetManager: Starting task 48.0 in stage 3.0 (TID 50) (172.19.0.7, executor 0, partition 48, PROCESS_LOCAL, 10175 bytes)
[2025-06-07T15:53:33.839+0000] {spark_submit.py:644} INFO - 25/06/07 15:53:33 INFO TaskSetManager: Finished task 44.0 in stage 3.0 (TID 46) in 44 ms on 172.19.0.7 (executor 0) (45/50)
[2025-06-07T15:53:33.842+0000] {spark_submit.py:644} INFO - 25/06/07 15:53:33 INFO TaskSetManager: Starting task 49.0 in stage 3.0 (TID 51) (172.19.0.7, executor 0, partition 49, PROCESS_LOCAL, 10175 bytes)
[2025-06-07T15:53:33.842+0000] {spark_submit.py:644} INFO - 25/06/07 15:53:33 INFO TaskSetManager: Finished task 45.0 in stage 3.0 (TID 47) in 40 ms on 172.19.0.7 (executor 0) (46/50)
[2025-06-07T15:53:33.849+0000] {spark_submit.py:644} INFO - 25/06/07 15:53:33 INFO BlockManagerInfo: Added rdd_14_46 in memory on 172.19.0.7:39917 (size: 46.0 B, free: 1048.6 MiB)
[2025-06-07T15:53:33.852+0000] {spark_submit.py:644} INFO - 25/06/07 15:53:33 INFO BlockManagerInfo: Added rdd_14_47 in memory on 172.19.0.7:39917 (size: 46.0 B, free: 1048.6 MiB)
[2025-06-07T15:53:33.864+0000] {spark_submit.py:644} INFO - 25/06/07 15:53:33 INFO TaskSetManager: Finished task 46.0 in stage 3.0 (TID 48) in 51 ms on 172.19.0.7 (executor 0) (47/50)
[2025-06-07T15:53:33.865+0000] {spark_submit.py:644} INFO - 25/06/07 15:53:33 INFO TaskSetManager: Finished task 47.0 in stage 3.0 (TID 49) in 45 ms on 172.19.0.7 (executor 0) (48/50)
[2025-06-07T15:53:33.874+0000] {spark_submit.py:644} INFO - 25/06/07 15:53:33 INFO BlockManagerInfo: Added rdd_14_48 in memory on 172.19.0.7:39917 (size: 46.0 B, free: 1048.6 MiB)
[2025-06-07T15:53:33.874+0000] {spark_submit.py:644} INFO - 25/06/07 15:53:33 INFO BlockManagerInfo: Added rdd_14_49 in memory on 172.19.0.7:39917 (size: 46.0 B, free: 1048.6 MiB)
[2025-06-07T15:53:33.890+0000] {spark_submit.py:644} INFO - 25/06/07 15:53:33 INFO TaskSetManager: Finished task 49.0 in stage 3.0 (TID 51) in 49 ms on 172.19.0.7 (executor 0) (49/50)
[2025-06-07T15:53:33.891+0000] {spark_submit.py:644} INFO - 25/06/07 15:53:33 INFO TaskSetManager: Finished task 48.0 in stage 3.0 (TID 50) in 52 ms on 172.19.0.7 (executor 0) (50/50)
[2025-06-07T15:53:33.891+0000] {spark_submit.py:644} INFO - 25/06/07 15:53:33 INFO TaskSchedulerImpl: Removed TaskSet 3.0, whose tasks have all completed, from pool
[2025-06-07T15:53:33.891+0000] {spark_submit.py:644} INFO - 25/06/07 15:53:33 INFO DAGScheduler: ShuffleMapStage 3 ($anonfun$recordDeltaOperationInternal$1 at DatabricksLogging.scala:128) finished in 2.037 s
[2025-06-07T15:53:33.891+0000] {spark_submit.py:644} INFO - 25/06/07 15:53:33 INFO DAGScheduler: looking for newly runnable stages
[2025-06-07T15:53:33.892+0000] {spark_submit.py:644} INFO - 25/06/07 15:53:33 INFO DAGScheduler: running: Set()
[2025-06-07T15:53:33.892+0000] {spark_submit.py:644} INFO - 25/06/07 15:53:33 INFO DAGScheduler: waiting: Set()
[2025-06-07T15:53:33.892+0000] {spark_submit.py:644} INFO - 25/06/07 15:53:33 INFO DAGScheduler: failed: Set()
[2025-06-07T15:53:33.908+0000] {spark_submit.py:644} INFO - 25/06/07 15:53:33 INFO SparkContext: Starting job: $anonfun$recordDeltaOperationInternal$1 at DatabricksLogging.scala:128
[2025-06-07T15:53:33.909+0000] {spark_submit.py:644} INFO - 25/06/07 15:53:33 INFO DAGScheduler: Got job 3 ($anonfun$recordDeltaOperationInternal$1 at DatabricksLogging.scala:128) with 1 output partitions
[2025-06-07T15:53:33.909+0000] {spark_submit.py:644} INFO - 25/06/07 15:53:33 INFO DAGScheduler: Final stage: ResultStage 6 ($anonfun$recordDeltaOperationInternal$1 at DatabricksLogging.scala:128)
[2025-06-07T15:53:33.909+0000] {spark_submit.py:644} INFO - 25/06/07 15:53:33 INFO DAGScheduler: Parents of final stage: List(ShuffleMapStage 5)
[2025-06-07T15:53:33.909+0000] {spark_submit.py:644} INFO - 25/06/07 15:53:33 INFO DAGScheduler: Missing parents: List()
[2025-06-07T15:53:33.909+0000] {spark_submit.py:644} INFO - 25/06/07 15:53:33 INFO DAGScheduler: Submitting ResultStage 6 (MapPartitionsRDD[20] at $anonfun$recordDeltaOperationInternal$1 at DatabricksLogging.scala:128), which has no missing parents
[2025-06-07T15:53:33.912+0000] {spark_submit.py:644} INFO - 25/06/07 15:53:33 INFO MemoryStore: Block broadcast_6 stored as values in memory (estimated size 533.9 KiB, free 432.7 MiB)
[2025-06-07T15:53:33.914+0000] {spark_submit.py:644} INFO - 25/06/07 15:53:33 INFO MemoryStore: Block broadcast_6_piece0 stored as bytes in memory (estimated size 124.5 KiB, free 432.6 MiB)
[2025-06-07T15:53:33.914+0000] {spark_submit.py:644} INFO - 25/06/07 15:53:33 INFO BlockManagerInfo: Added broadcast_6_piece0 in memory on b5e5641a3f5a:32903 (size: 124.5 KiB, free: 434.1 MiB)
[2025-06-07T15:53:33.914+0000] {spark_submit.py:644} INFO - 25/06/07 15:53:33 INFO SparkContext: Created broadcast 6 from broadcast at DAGScheduler.scala:1585
[2025-06-07T15:53:33.915+0000] {spark_submit.py:644} INFO - 25/06/07 15:53:33 INFO DAGScheduler: Submitting 1 missing tasks from ResultStage 6 (MapPartitionsRDD[20] at $anonfun$recordDeltaOperationInternal$1 at DatabricksLogging.scala:128) (first 15 tasks are for partitions Vector(0))
[2025-06-07T15:53:33.915+0000] {spark_submit.py:644} INFO - 25/06/07 15:53:33 INFO TaskSchedulerImpl: Adding task set 6.0 with 1 tasks resource profile 0
[2025-06-07T15:53:33.915+0000] {spark_submit.py:644} INFO - 25/06/07 15:53:33 INFO TaskSetManager: Starting task 0.0 in stage 6.0 (TID 52) (172.19.0.7, executor 0, partition 0, NODE_LOCAL, 10186 bytes)
[2025-06-07T15:53:33.922+0000] {spark_submit.py:644} INFO - 25/06/07 15:53:33 INFO BlockManagerInfo: Added broadcast_6_piece0 in memory on 172.19.0.7:39917 (size: 124.5 KiB, free: 1048.5 MiB)
[2025-06-07T15:53:33.931+0000] {spark_submit.py:644} INFO - 25/06/07 15:53:33 INFO MapOutputTrackerMasterEndpoint: Asked to send map output locations for shuffle 1 to 172.19.0.7:49852
[2025-06-07T15:53:33.965+0000] {spark_submit.py:644} INFO - 25/06/07 15:53:33 INFO TaskSetManager: Finished task 0.0 in stage 6.0 (TID 52) in 50 ms on 172.19.0.7 (executor 0) (1/1)
[2025-06-07T15:53:33.966+0000] {spark_submit.py:644} INFO - 25/06/07 15:53:33 INFO TaskSchedulerImpl: Removed TaskSet 6.0, whose tasks have all completed, from pool
[2025-06-07T15:53:33.966+0000] {spark_submit.py:644} INFO - 25/06/07 15:53:33 INFO DAGScheduler: ResultStage 6 ($anonfun$recordDeltaOperationInternal$1 at DatabricksLogging.scala:128) finished in 0.057 s
[2025-06-07T15:53:33.966+0000] {spark_submit.py:644} INFO - 25/06/07 15:53:33 INFO DAGScheduler: Job 3 is finished. Cancelling potential speculative or zombie tasks for this job
[2025-06-07T15:53:33.967+0000] {spark_submit.py:644} INFO - 25/06/07 15:53:33 INFO TaskSchedulerImpl: Killing all running tasks in stage 6: Stage finished
[2025-06-07T15:53:33.967+0000] {spark_submit.py:644} INFO - 25/06/07 15:53:33 INFO DAGScheduler: Job 3 finished: $anonfun$recordDeltaOperationInternal$1 at DatabricksLogging.scala:128, took 0.058623 s
[2025-06-07T15:53:33.990+0000] {spark_submit.py:644} INFO - 25/06/07 15:53:33 INFO CodeGenerator: Code generated in 17.488542 ms
[2025-06-07T15:53:33.991+0000] {spark_submit.py:644} INFO - 25/06/07 15:53:33 INFO Snapshot: [tableId=9e663b76-69fe-4dd4-b26d-29bc9e7c617a] DELTA: Done
[2025-06-07T15:53:34.149+0000] {spark_submit.py:644} INFO - 25/06/07 15:53:34 INFO CodeGenerator: Code generated in 56.333459 ms
[2025-06-07T15:53:34.161+0000] {spark_submit.py:644} INFO - 25/06/07 15:53:34 INFO SparkContext: Starting job: $anonfun$recordDeltaOperationInternal$1 at DatabricksLogging.scala:128
[2025-06-07T15:53:34.162+0000] {spark_submit.py:644} INFO - 25/06/07 15:53:34 INFO DAGScheduler: Got job 4 ($anonfun$recordDeltaOperationInternal$1 at DatabricksLogging.scala:128) with 50 output partitions
[2025-06-07T15:53:34.163+0000] {spark_submit.py:644} INFO - 25/06/07 15:53:34 INFO DAGScheduler: Final stage: ResultStage 8 ($anonfun$recordDeltaOperationInternal$1 at DatabricksLogging.scala:128)
[2025-06-07T15:53:34.163+0000] {spark_submit.py:644} INFO - 25/06/07 15:53:34 INFO DAGScheduler: Parents of final stage: List(ShuffleMapStage 7)
[2025-06-07T15:53:34.163+0000] {spark_submit.py:644} INFO - 25/06/07 15:53:34 INFO DAGScheduler: Missing parents: List()
[2025-06-07T15:53:34.163+0000] {spark_submit.py:644} INFO - 25/06/07 15:53:34 INFO DAGScheduler: Submitting ResultStage 8 (MapPartitionsRDD[22] at $anonfun$recordDeltaOperationInternal$1 at DatabricksLogging.scala:128), which has no missing parents
[2025-06-07T15:53:34.167+0000] {spark_submit.py:644} INFO - 25/06/07 15:53:34 INFO MemoryStore: Block broadcast_7 stored as values in memory (estimated size 684.1 KiB, free 431.9 MiB)
[2025-06-07T15:53:34.168+0000] {spark_submit.py:644} INFO - 25/06/07 15:53:34 INFO MemoryStore: Block broadcast_7_piece0 stored as bytes in memory (estimated size 154.5 KiB, free 431.7 MiB)
[2025-06-07T15:53:34.169+0000] {spark_submit.py:644} INFO - 25/06/07 15:53:34 INFO BlockManagerInfo: Added broadcast_7_piece0 in memory on b5e5641a3f5a:32903 (size: 154.5 KiB, free: 433.9 MiB)
[2025-06-07T15:53:34.169+0000] {spark_submit.py:644} INFO - 25/06/07 15:53:34 INFO SparkContext: Created broadcast 7 from broadcast at DAGScheduler.scala:1585
[2025-06-07T15:53:34.169+0000] {spark_submit.py:644} INFO - 25/06/07 15:53:34 INFO DAGScheduler: Submitting 50 missing tasks from ResultStage 8 (MapPartitionsRDD[22] at $anonfun$recordDeltaOperationInternal$1 at DatabricksLogging.scala:128) (first 15 tasks are for partitions Vector(0, 1, 2, 3, 4, 5, 6, 7, 8, 9, 10, 11, 12, 13, 14))
[2025-06-07T15:53:34.169+0000] {spark_submit.py:644} INFO - 25/06/07 15:53:34 INFO TaskSchedulerImpl: Adding task set 8.0 with 50 tasks resource profile 0
[2025-06-07T15:53:34.170+0000] {spark_submit.py:644} INFO - 25/06/07 15:53:34 INFO TaskSetManager: Starting task 0.0 in stage 8.0 (TID 53) (172.19.0.7, executor 0, partition 0, PROCESS_LOCAL, 10186 bytes)
[2025-06-07T15:53:34.171+0000] {spark_submit.py:644} INFO - 25/06/07 15:53:34 INFO TaskSetManager: Starting task 1.0 in stage 8.0 (TID 54) (172.19.0.7, executor 0, partition 1, PROCESS_LOCAL, 10186 bytes)
[2025-06-07T15:53:34.171+0000] {spark_submit.py:644} INFO - 25/06/07 15:53:34 INFO TaskSetManager: Starting task 2.0 in stage 8.0 (TID 55) (172.19.0.7, executor 0, partition 2, PROCESS_LOCAL, 10186 bytes)
[2025-06-07T15:53:34.171+0000] {spark_submit.py:644} INFO - 25/06/07 15:53:34 INFO TaskSetManager: Starting task 3.0 in stage 8.0 (TID 56) (172.19.0.7, executor 0, partition 3, PROCESS_LOCAL, 10186 bytes)
[2025-06-07T15:53:34.178+0000] {spark_submit.py:644} INFO - 25/06/07 15:53:34 INFO BlockManagerInfo: Added broadcast_7_piece0 in memory on 172.19.0.7:39917 (size: 154.5 KiB, free: 1048.4 MiB)
[2025-06-07T15:53:34.295+0000] {spark_submit.py:644} INFO - 25/06/07 15:53:34 INFO TaskSetManager: Starting task 4.0 in stage 8.0 (TID 57) (172.19.0.7, executor 0, partition 4, PROCESS_LOCAL, 10186 bytes)
[2025-06-07T15:53:34.296+0000] {spark_submit.py:644} INFO - 25/06/07 15:53:34 INFO TaskSetManager: Starting task 5.0 in stage 8.0 (TID 58) (172.19.0.7, executor 0, partition 5, PROCESS_LOCAL, 10186 bytes)
[2025-06-07T15:53:34.297+0000] {spark_submit.py:644} INFO - 25/06/07 15:53:34 INFO TaskSetManager: Finished task 2.0 in stage 8.0 (TID 55) in 125 ms on 172.19.0.7 (executor 0) (1/50)
[2025-06-07T15:53:34.298+0000] {spark_submit.py:644} INFO - 25/06/07 15:53:34 INFO TaskSetManager: Starting task 6.0 in stage 8.0 (TID 59) (172.19.0.7, executor 0, partition 6, PROCESS_LOCAL, 10186 bytes)
[2025-06-07T15:53:34.301+0000] {spark_submit.py:644} INFO - 25/06/07 15:53:34 INFO TaskSetManager: Starting task 7.0 in stage 8.0 (TID 60) (172.19.0.7, executor 0, partition 7, PROCESS_LOCAL, 10186 bytes)
[2025-06-07T15:53:34.301+0000] {spark_submit.py:644} INFO - 25/06/07 15:53:34 INFO TaskSetManager: Finished task 0.0 in stage 8.0 (TID 53) in 127 ms on 172.19.0.7 (executor 0) (2/50)
[2025-06-07T15:53:34.301+0000] {spark_submit.py:644} INFO - 25/06/07 15:53:34 INFO TaskSetManager: Finished task 1.0 in stage 8.0 (TID 54) in 127 ms on 172.19.0.7 (executor 0) (3/50)
[2025-06-07T15:53:34.302+0000] {spark_submit.py:644} INFO - 25/06/07 15:53:34 INFO TaskSetManager: Finished task 3.0 in stage 8.0 (TID 56) in 127 ms on 172.19.0.7 (executor 0) (4/50)
[2025-06-07T15:53:34.311+0000] {spark_submit.py:644} INFO - 25/06/07 15:53:34 INFO TaskSetManager: Starting task 8.0 in stage 8.0 (TID 61) (172.19.0.7, executor 0, partition 8, PROCESS_LOCAL, 10186 bytes)
[2025-06-07T15:53:34.312+0000] {spark_submit.py:644} INFO - 25/06/07 15:53:34 INFO TaskSetManager: Starting task 9.0 in stage 8.0 (TID 62) (172.19.0.7, executor 0, partition 9, PROCESS_LOCAL, 10186 bytes)
[2025-06-07T15:53:34.312+0000] {spark_submit.py:644} INFO - 25/06/07 15:53:34 INFO TaskSetManager: Finished task 5.0 in stage 8.0 (TID 58) in 15 ms on 172.19.0.7 (executor 0) (5/50)
[2025-06-07T15:53:34.313+0000] {spark_submit.py:644} INFO - 25/06/07 15:53:34 INFO TaskSetManager: Finished task 4.0 in stage 8.0 (TID 57) in 18 ms on 172.19.0.7 (executor 0) (6/50)
[2025-06-07T15:53:34.314+0000] {spark_submit.py:644} INFO - 25/06/07 15:53:34 INFO TaskSetManager: Starting task 10.0 in stage 8.0 (TID 63) (172.19.0.7, executor 0, partition 10, PROCESS_LOCAL, 10186 bytes)
[2025-06-07T15:53:34.315+0000] {spark_submit.py:644} INFO - 25/06/07 15:53:34 INFO TaskSetManager: Finished task 7.0 in stage 8.0 (TID 60) in 18 ms on 172.19.0.7 (executor 0) (7/50)
[2025-06-07T15:53:34.316+0000] {spark_submit.py:644} INFO - 25/06/07 15:53:34 INFO TaskSetManager: Starting task 11.0 in stage 8.0 (TID 64) (172.19.0.7, executor 0, partition 11, PROCESS_LOCAL, 10186 bytes)
[2025-06-07T15:53:34.317+0000] {spark_submit.py:644} INFO - 25/06/07 15:53:34 INFO TaskSetManager: Finished task 6.0 in stage 8.0 (TID 59) in 20 ms on 172.19.0.7 (executor 0) (8/50)
[2025-06-07T15:53:34.322+0000] {spark_submit.py:644} INFO - 25/06/07 15:53:34 INFO TaskSetManager: Starting task 12.0 in stage 8.0 (TID 65) (172.19.0.7, executor 0, partition 12, PROCESS_LOCAL, 10186 bytes)
[2025-06-07T15:53:34.323+0000] {spark_submit.py:644} INFO - 25/06/07 15:53:34 INFO TaskSetManager: Finished task 8.0 in stage 8.0 (TID 61) in 12 ms on 172.19.0.7 (executor 0) (9/50)
[2025-06-07T15:53:34.324+0000] {spark_submit.py:644} INFO - 25/06/07 15:53:34 INFO TaskSetManager: Starting task 13.0 in stage 8.0 (TID 66) (172.19.0.7, executor 0, partition 13, PROCESS_LOCAL, 10186 bytes)
[2025-06-07T15:53:34.324+0000] {spark_submit.py:644} INFO - 25/06/07 15:53:34 INFO TaskSetManager: Finished task 9.0 in stage 8.0 (TID 62) in 12 ms on 172.19.0.7 (executor 0) (10/50)
[2025-06-07T15:53:34.326+0000] {spark_submit.py:644} INFO - 25/06/07 15:53:34 INFO TaskSetManager: Starting task 14.0 in stage 8.0 (TID 67) (172.19.0.7, executor 0, partition 14, PROCESS_LOCAL, 10186 bytes)
[2025-06-07T15:53:34.330+0000] {spark_submit.py:644} INFO - 25/06/07 15:53:34 INFO TaskSetManager: Starting task 15.0 in stage 8.0 (TID 68) (172.19.0.7, executor 0, partition 15, PROCESS_LOCAL, 10186 bytes)
[2025-06-07T15:53:34.331+0000] {spark_submit.py:644} INFO - 25/06/07 15:53:34 INFO TaskSetManager: Finished task 10.0 in stage 8.0 (TID 63) in 13 ms on 172.19.0.7 (executor 0) (11/50)
[2025-06-07T15:53:34.331+0000] {spark_submit.py:644} INFO - 25/06/07 15:53:34 INFO TaskSetManager: Finished task 11.0 in stage 8.0 (TID 64) in 12 ms on 172.19.0.7 (executor 0) (12/50)
[2025-06-07T15:53:34.333+0000] {spark_submit.py:644} INFO - 25/06/07 15:53:34 INFO TaskSetManager: Starting task 16.0 in stage 8.0 (TID 69) (172.19.0.7, executor 0, partition 16, PROCESS_LOCAL, 10186 bytes)
[2025-06-07T15:53:34.333+0000] {spark_submit.py:644} INFO - 25/06/07 15:53:34 INFO TaskSetManager: Finished task 12.0 in stage 8.0 (TID 65) in 12 ms on 172.19.0.7 (executor 0) (13/50)
[2025-06-07T15:53:34.334+0000] {spark_submit.py:644} INFO - 25/06/07 15:53:34 INFO TaskSetManager: Starting task 17.0 in stage 8.0 (TID 70) (172.19.0.7, executor 0, partition 17, PROCESS_LOCAL, 10186 bytes)
[2025-06-07T15:53:34.335+0000] {spark_submit.py:644} INFO - 25/06/07 15:53:34 INFO TaskSetManager: Finished task 13.0 in stage 8.0 (TID 66) in 12 ms on 172.19.0.7 (executor 0) (14/50)
[2025-06-07T15:53:34.341+0000] {spark_submit.py:644} INFO - 25/06/07 15:53:34 INFO TaskSetManager: Starting task 18.0 in stage 8.0 (TID 71) (172.19.0.7, executor 0, partition 18, PROCESS_LOCAL, 10186 bytes)
[2025-06-07T15:53:34.342+0000] {spark_submit.py:644} INFO - 25/06/07 15:53:34 INFO TaskSetManager: Starting task 19.0 in stage 8.0 (TID 72) (172.19.0.7, executor 0, partition 19, PROCESS_LOCAL, 10186 bytes)
[2025-06-07T15:53:34.342+0000] {spark_submit.py:644} INFO - 25/06/07 15:53:34 INFO TaskSetManager: Finished task 14.0 in stage 8.0 (TID 67) in 15 ms on 172.19.0.7 (executor 0) (15/50)
[2025-06-07T15:53:34.342+0000] {spark_submit.py:644} INFO - 25/06/07 15:53:34 INFO TaskSetManager: Finished task 15.0 in stage 8.0 (TID 68) in 15 ms on 172.19.0.7 (executor 0) (16/50)
[2025-06-07T15:53:34.345+0000] {spark_submit.py:644} INFO - 25/06/07 15:53:34 INFO TaskSetManager: Starting task 20.0 in stage 8.0 (TID 73) (172.19.0.7, executor 0, partition 20, PROCESS_LOCAL, 10186 bytes)
[2025-06-07T15:53:34.345+0000] {spark_submit.py:644} INFO - 25/06/07 15:53:34 INFO TaskSetManager: Finished task 16.0 in stage 8.0 (TID 69) in 13 ms on 172.19.0.7 (executor 0) (17/50)
[2025-06-07T15:53:34.345+0000] {spark_submit.py:644} INFO - 25/06/07 15:53:34 INFO TaskSetManager: Starting task 21.0 in stage 8.0 (TID 74) (172.19.0.7, executor 0, partition 21, PROCESS_LOCAL, 10186 bytes)
[2025-06-07T15:53:34.346+0000] {spark_submit.py:644} INFO - 25/06/07 15:53:34 INFO TaskSetManager: Finished task 17.0 in stage 8.0 (TID 70) in 13 ms on 172.19.0.7 (executor 0) (18/50)
[2025-06-07T15:53:34.352+0000] {spark_submit.py:644} INFO - 25/06/07 15:53:34 INFO TaskSetManager: Starting task 22.0 in stage 8.0 (TID 75) (172.19.0.7, executor 0, partition 22, PROCESS_LOCAL, 10186 bytes)
[2025-06-07T15:53:34.353+0000] {spark_submit.py:644} INFO - 25/06/07 15:53:34 INFO TaskSetManager: Finished task 19.0 in stage 8.0 (TID 72) in 12 ms on 172.19.0.7 (executor 0) (19/50)
[2025-06-07T15:53:34.354+0000] {spark_submit.py:644} INFO - 25/06/07 15:53:34 INFO TaskSetManager: Starting task 23.0 in stage 8.0 (TID 76) (172.19.0.7, executor 0, partition 23, PROCESS_LOCAL, 10186 bytes)
[2025-06-07T15:53:34.354+0000] {spark_submit.py:644} INFO - 25/06/07 15:53:34 INFO TaskSetManager: Finished task 18.0 in stage 8.0 (TID 71) in 13 ms on 172.19.0.7 (executor 0) (20/50)
[2025-06-07T15:53:34.355+0000] {spark_submit.py:644} INFO - 25/06/07 15:53:34 INFO TaskSetManager: Starting task 24.0 in stage 8.0 (TID 77) (172.19.0.7, executor 0, partition 24, PROCESS_LOCAL, 10186 bytes)
[2025-06-07T15:53:34.356+0000] {spark_submit.py:644} INFO - 25/06/07 15:53:34 INFO TaskSetManager: Finished task 20.0 in stage 8.0 (TID 73) in 12 ms on 172.19.0.7 (executor 0) (21/50)
[2025-06-07T15:53:34.356+0000] {spark_submit.py:644} INFO - 25/06/07 15:53:34 INFO TaskSetManager: Starting task 25.0 in stage 8.0 (TID 78) (172.19.0.7, executor 0, partition 25, PROCESS_LOCAL, 10186 bytes)
[2025-06-07T15:53:34.357+0000] {spark_submit.py:644} INFO - 25/06/07 15:53:34 INFO TaskSetManager: Finished task 21.0 in stage 8.0 (TID 74) in 12 ms on 172.19.0.7 (executor 0) (22/50)
[2025-06-07T15:53:34.366+0000] {spark_submit.py:644} INFO - 25/06/07 15:53:34 INFO TaskSetManager: Starting task 26.0 in stage 8.0 (TID 79) (172.19.0.7, executor 0, partition 26, PROCESS_LOCAL, 10186 bytes)
[2025-06-07T15:53:34.367+0000] {spark_submit.py:644} INFO - 25/06/07 15:53:34 INFO TaskSetManager: Finished task 22.0 in stage 8.0 (TID 75) in 15 ms on 172.19.0.7 (executor 0) (23/50)
[2025-06-07T15:53:34.369+0000] {spark_submit.py:644} INFO - 25/06/07 15:53:34 INFO TaskSetManager: Starting task 27.0 in stage 8.0 (TID 80) (172.19.0.7, executor 0, partition 27, PROCESS_LOCAL, 10186 bytes)
[2025-06-07T15:53:34.370+0000] {spark_submit.py:644} INFO - 25/06/07 15:53:34 INFO TaskSetManager: Starting task 28.0 in stage 8.0 (TID 81) (172.19.0.7, executor 0, partition 28, PROCESS_LOCAL, 10186 bytes)
[2025-06-07T15:53:34.370+0000] {spark_submit.py:644} INFO - 25/06/07 15:53:34 INFO TaskSetManager: Finished task 24.0 in stage 8.0 (TID 77) in 13 ms on 172.19.0.7 (executor 0) (24/50)
[2025-06-07T15:53:34.371+0000] {spark_submit.py:644} INFO - 25/06/07 15:53:34 INFO TaskSetManager: Finished task 23.0 in stage 8.0 (TID 76) in 15 ms on 172.19.0.7 (executor 0) (25/50)
[2025-06-07T15:53:34.371+0000] {spark_submit.py:644} INFO - 25/06/07 15:53:34 INFO TaskSetManager: Starting task 29.0 in stage 8.0 (TID 82) (172.19.0.7, executor 0, partition 29, PROCESS_LOCAL, 10186 bytes)
[2025-06-07T15:53:34.371+0000] {spark_submit.py:644} INFO - 25/06/07 15:53:34 INFO TaskSetManager: Finished task 25.0 in stage 8.0 (TID 78) in 14 ms on 172.19.0.7 (executor 0) (26/50)
[2025-06-07T15:53:34.375+0000] {spark_submit.py:644} INFO - 25/06/07 15:53:34 INFO TaskSetManager: Starting task 30.0 in stage 8.0 (TID 83) (172.19.0.7, executor 0, partition 30, PROCESS_LOCAL, 10186 bytes)
[2025-06-07T15:53:34.376+0000] {spark_submit.py:644} INFO - 25/06/07 15:53:34 INFO TaskSetManager: Finished task 26.0 in stage 8.0 (TID 79) in 9 ms on 172.19.0.7 (executor 0) (27/50)
[2025-06-07T15:53:34.379+0000] {spark_submit.py:644} INFO - 25/06/07 15:53:34 INFO TaskSetManager: Starting task 31.0 in stage 8.0 (TID 84) (172.19.0.7, executor 0, partition 31, PROCESS_LOCAL, 10186 bytes)
[2025-06-07T15:53:34.380+0000] {spark_submit.py:644} INFO - 25/06/07 15:53:34 INFO TaskSetManager: Starting task 32.0 in stage 8.0 (TID 85) (172.19.0.7, executor 0, partition 32, PROCESS_LOCAL, 10186 bytes)
[2025-06-07T15:53:34.380+0000] {spark_submit.py:644} INFO - 25/06/07 15:53:34 INFO TaskSetManager: Finished task 27.0 in stage 8.0 (TID 80) in 12 ms on 172.19.0.7 (executor 0) (28/50)
[2025-06-07T15:53:34.381+0000] {spark_submit.py:644} INFO - 25/06/07 15:53:34 INFO TaskSetManager: Starting task 33.0 in stage 8.0 (TID 86) (172.19.0.7, executor 0, partition 33, PROCESS_LOCAL, 10186 bytes)
[2025-06-07T15:53:34.381+0000] {spark_submit.py:644} INFO - 25/06/07 15:53:34 INFO TaskSetManager: Finished task 28.0 in stage 8.0 (TID 81) in 13 ms on 172.19.0.7 (executor 0) (29/50)
[2025-06-07T15:53:34.381+0000] {spark_submit.py:644} INFO - 25/06/07 15:53:34 INFO TaskSetManager: Finished task 29.0 in stage 8.0 (TID 82) in 11 ms on 172.19.0.7 (executor 0) (30/50)
[2025-06-07T15:53:34.384+0000] {spark_submit.py:644} INFO - 25/06/07 15:53:34 INFO TaskSetManager: Starting task 34.0 in stage 8.0 (TID 87) (172.19.0.7, executor 0, partition 34, PROCESS_LOCAL, 10186 bytes)
[2025-06-07T15:53:34.385+0000] {spark_submit.py:644} INFO - 25/06/07 15:53:34 INFO TaskSetManager: Finished task 30.0 in stage 8.0 (TID 83) in 10 ms on 172.19.0.7 (executor 0) (31/50)
[2025-06-07T15:53:34.392+0000] {spark_submit.py:644} INFO - 25/06/07 15:53:34 INFO TaskSetManager: Starting task 35.0 in stage 8.0 (TID 88) (172.19.0.7, executor 0, partition 35, PROCESS_LOCAL, 10186 bytes)
[2025-06-07T15:53:34.393+0000] {spark_submit.py:644} INFO - 25/06/07 15:53:34 INFO TaskSetManager: Starting task 36.0 in stage 8.0 (TID 89) (172.19.0.7, executor 0, partition 36, PROCESS_LOCAL, 10186 bytes)
[2025-06-07T15:53:34.393+0000] {spark_submit.py:644} INFO - 25/06/07 15:53:34 INFO TaskSetManager: Starting task 37.0 in stage 8.0 (TID 90) (172.19.0.7, executor 0, partition 37, PROCESS_LOCAL, 10186 bytes)
[2025-06-07T15:53:34.394+0000] {spark_submit.py:644} INFO - 25/06/07 15:53:34 INFO TaskSetManager: Finished task 33.0 in stage 8.0 (TID 86) in 12 ms on 172.19.0.7 (executor 0) (32/50)
[2025-06-07T15:53:34.395+0000] {spark_submit.py:644} INFO - 25/06/07 15:53:34 INFO TaskSetManager: Finished task 31.0 in stage 8.0 (TID 84) in 15 ms on 172.19.0.7 (executor 0) (33/50)
[2025-06-07T15:53:34.395+0000] {spark_submit.py:644} INFO - 25/06/07 15:53:34 INFO TaskSetManager: Finished task 32.0 in stage 8.0 (TID 85) in 14 ms on 172.19.0.7 (executor 0) (34/50)
[2025-06-07T15:53:34.395+0000] {spark_submit.py:644} INFO - 25/06/07 15:53:34 INFO TaskSetManager: Starting task 38.0 in stage 8.0 (TID 91) (172.19.0.7, executor 0, partition 38, PROCESS_LOCAL, 10186 bytes)
[2025-06-07T15:53:34.395+0000] {spark_submit.py:644} INFO - 25/06/07 15:53:34 INFO TaskSetManager: Finished task 34.0 in stage 8.0 (TID 87) in 10 ms on 172.19.0.7 (executor 0) (35/50)
[2025-06-07T15:53:34.408+0000] {spark_submit.py:644} INFO - 25/06/07 15:53:34 INFO TaskSetManager: Starting task 39.0 in stage 8.0 (TID 92) (172.19.0.7, executor 0, partition 39, PROCESS_LOCAL, 10186 bytes)
[2025-06-07T15:53:34.409+0000] {spark_submit.py:644} INFO - 25/06/07 15:53:34 INFO TaskSetManager: Starting task 40.0 in stage 8.0 (TID 93) (172.19.0.7, executor 0, partition 40, PROCESS_LOCAL, 10186 bytes)
[2025-06-07T15:53:34.410+0000] {spark_submit.py:644} INFO - 25/06/07 15:53:34 INFO TaskSetManager: Finished task 35.0 in stage 8.0 (TID 88) in 17 ms on 172.19.0.7 (executor 0) (36/50)
[2025-06-07T15:53:34.412+0000] {spark_submit.py:644} INFO - 25/06/07 15:53:34 INFO TaskSetManager: Starting task 41.0 in stage 8.0 (TID 94) (172.19.0.7, executor 0, partition 41, PROCESS_LOCAL, 10186 bytes)
[2025-06-07T15:53:34.412+0000] {spark_submit.py:644} INFO - 25/06/07 15:53:34 INFO TaskSetManager: Starting task 42.0 in stage 8.0 (TID 95) (172.19.0.7, executor 0, partition 42, PROCESS_LOCAL, 10186 bytes)
[2025-06-07T15:53:34.412+0000] {spark_submit.py:644} INFO - 25/06/07 15:53:34 INFO TaskSetManager: Finished task 36.0 in stage 8.0 (TID 89) in 19 ms on 172.19.0.7 (executor 0) (37/50)
[2025-06-07T15:53:34.412+0000] {spark_submit.py:644} INFO - 25/06/07 15:53:34 INFO TaskSetManager: Finished task 37.0 in stage 8.0 (TID 90) in 18 ms on 172.19.0.7 (executor 0) (38/50)
[2025-06-07T15:53:34.412+0000] {spark_submit.py:644} INFO - 25/06/07 15:53:34 INFO TaskSetManager: Finished task 38.0 in stage 8.0 (TID 91) in 16 ms on 172.19.0.7 (executor 0) (39/50)
[2025-06-07T15:53:34.420+0000] {spark_submit.py:644} INFO - 25/06/07 15:53:34 INFO TaskSetManager: Starting task 43.0 in stage 8.0 (TID 96) (172.19.0.7, executor 0, partition 43, PROCESS_LOCAL, 10186 bytes)
[2025-06-07T15:53:34.420+0000] {spark_submit.py:644} INFO - 25/06/07 15:53:34 INFO TaskSetManager: Starting task 44.0 in stage 8.0 (TID 97) (172.19.0.7, executor 0, partition 44, PROCESS_LOCAL, 10186 bytes)
[2025-06-07T15:53:34.421+0000] {spark_submit.py:644} INFO - 25/06/07 15:53:34 INFO TaskSetManager: Finished task 39.0 in stage 8.0 (TID 92) in 13 ms on 172.19.0.7 (executor 0) (40/50)
[2025-06-07T15:53:34.421+0000] {spark_submit.py:644} INFO - 25/06/07 15:53:34 INFO TaskSetManager: Starting task 45.0 in stage 8.0 (TID 98) (172.19.0.7, executor 0, partition 45, PROCESS_LOCAL, 10186 bytes)
[2025-06-07T15:53:34.421+0000] {spark_submit.py:644} INFO - 25/06/07 15:53:34 INFO TaskSetManager: Finished task 40.0 in stage 8.0 (TID 93) in 13 ms on 172.19.0.7 (executor 0) (41/50)
[2025-06-07T15:53:34.422+0000] {spark_submit.py:644} INFO - 25/06/07 15:53:34 INFO TaskSetManager: Starting task 46.0 in stage 8.0 (TID 99) (172.19.0.7, executor 0, partition 46, PROCESS_LOCAL, 10186 bytes)
[2025-06-07T15:53:34.423+0000] {spark_submit.py:644} INFO - 25/06/07 15:53:34 INFO TaskSetManager: Finished task 41.0 in stage 8.0 (TID 94) in 13 ms on 172.19.0.7 (executor 0) (42/50)
[2025-06-07T15:53:34.423+0000] {spark_submit.py:644} INFO - 25/06/07 15:53:34 INFO TaskSetManager: Finished task 42.0 in stage 8.0 (TID 95) in 13 ms on 172.19.0.7 (executor 0) (43/50)
[2025-06-07T15:53:34.431+0000] {spark_submit.py:644} INFO - 25/06/07 15:53:34 INFO TaskSetManager: Starting task 47.0 in stage 8.0 (TID 100) (172.19.0.7, executor 0, partition 47, PROCESS_LOCAL, 10186 bytes)
[2025-06-07T15:53:34.432+0000] {spark_submit.py:644} INFO - 25/06/07 15:53:34 INFO TaskSetManager: Finished task 43.0 in stage 8.0 (TID 96) in 12 ms on 172.19.0.7 (executor 0) (44/50)
[2025-06-07T15:53:34.434+0000] {spark_submit.py:644} INFO - 25/06/07 15:53:34 INFO TaskSetManager: Starting task 48.0 in stage 8.0 (TID 101) (172.19.0.7, executor 0, partition 48, PROCESS_LOCAL, 10186 bytes)
[2025-06-07T15:53:34.435+0000] {spark_submit.py:644} INFO - 25/06/07 15:53:34 INFO TaskSetManager: Finished task 46.0 in stage 8.0 (TID 99) in 13 ms on 172.19.0.7 (executor 0) (45/50)
[2025-06-07T15:53:34.435+0000] {spark_submit.py:644} INFO - 25/06/07 15:53:34 INFO TaskSetManager: Starting task 49.0 in stage 8.0 (TID 102) (172.19.0.7, executor 0, partition 49, PROCESS_LOCAL, 10186 bytes)
[2025-06-07T15:53:34.435+0000] {spark_submit.py:644} INFO - 25/06/07 15:53:34 INFO TaskSetManager: Finished task 44.0 in stage 8.0 (TID 97) in 15 ms on 172.19.0.7 (executor 0) (46/50)
[2025-06-07T15:53:34.436+0000] {spark_submit.py:644} INFO - 25/06/07 15:53:34 INFO TaskSetManager: Finished task 45.0 in stage 8.0 (TID 98) in 14 ms on 172.19.0.7 (executor 0) (47/50)
[2025-06-07T15:53:34.439+0000] {spark_submit.py:644} INFO - 25/06/07 15:53:34 INFO TaskSetManager: Finished task 47.0 in stage 8.0 (TID 100) in 9 ms on 172.19.0.7 (executor 0) (48/50)
