[2025-06-07T15:53:38.205+0000] {local_task_job_runner.py:123} INFO - ::group::Pre task execution logs
[2025-06-07T15:53:38.214+0000] {taskinstance.py:2613} INFO - Dependencies all met for dep_context=non-requeueable deps ti=<TaskInstance: stephen_curry_stats_medallion_etl.silver_to_gold scheduled__2025-06-06T00:00:00+00:00 [queued]>
[2025-06-07T15:53:38.218+0000] {taskinstance.py:2613} INFO - Dependencies all met for dep_context=requeueable deps ti=<TaskInstance: stephen_curry_stats_medallion_etl.silver_to_gold scheduled__2025-06-06T00:00:00+00:00 [queued]>
[2025-06-07T15:53:38.218+0000] {taskinstance.py:2866} INFO - Starting attempt 1 of 1
[2025-06-07T15:53:38.223+0000] {taskinstance.py:2889} INFO - Executing <Task(SparkSubmitOperator): silver_to_gold> on 2025-06-06 00:00:00+00:00
[2025-06-07T15:53:38.225+0000] {standard_task_runner.py:72} INFO - Started process 760 to run task
[2025-06-07T15:53:38.228+0000] {standard_task_runner.py:104} INFO - Running: ['***', 'tasks', 'run', 'stephen_curry_stats_medallion_etl', 'silver_to_gold', 'scheduled__2025-06-06T00:00:00+00:00', '--job-id', '6', '--raw', '--subdir', 'DAGS_FOLDER/medallion_sales_etl_dag.py', '--cfg-path', '/tmp/tmpgcu07hx6']
[2025-06-07T15:53:38.229+0000] {standard_task_runner.py:105} INFO - Job 6: Subtask silver_to_gold
[2025-06-07T15:53:38.257+0000] {task_command.py:467} INFO - Running <TaskInstance: stephen_curry_stats_medallion_etl.silver_to_gold scheduled__2025-06-06T00:00:00+00:00 [running]> on host b5e5641a3f5a
[2025-06-07T15:53:38.302+0000] {taskinstance.py:3132} INFO - Exporting env vars: AIRFLOW_CTX_DAG_OWNER='***' AIRFLOW_CTX_DAG_ID='stephen_curry_stats_medallion_etl' AIRFLOW_CTX_TASK_ID='silver_to_gold' AIRFLOW_CTX_EXECUTION_DATE='2025-06-06T00:00:00+00:00' AIRFLOW_CTX_TRY_NUMBER='1' AIRFLOW_CTX_DAG_RUN_ID='scheduled__2025-06-06T00:00:00+00:00'
[2025-06-07T15:53:38.302+0000] {taskinstance.py:731} INFO - ::endgroup::
[2025-06-07T15:53:38.317+0000] {base.py:84} INFO - Retrieving connection 'spark_default'
[2025-06-07T15:53:38.319+0000] {spark_submit.py:474} INFO - Spark-Submit cmd: spark-submit --master spark://spark-master:7077 --conf spark.executor.memory=2g --conf spark.sql.extensions=io.delta.sql.DeltaSparkSessionExtension --conf spark.sql.catalog.spark_catalog=org.apache.spark.sql.delta.catalog.DeltaCatalog --conf spark.hadoop.fs.s3a.endpoint=http://minio:9000 --conf spark.hadoop.fs.s3a.access.key=minioadmin --conf spark.hadoop.fs.s3a.secret.key=****** --conf spark.hadoop.fs.s3a.path.style.access=true --conf spark.hadoop.fs.s3a.impl=org.apache.hadoop.fs.s3a.S3AFileSystem --conf spark.hadoop.fs.s3a.aws.credentials.provider=org.apache.hadoop.fs.s3a.SimpleAWSCredentialsProvider --packages org.apache.hadoop:hadoop-aws:3.3.4,com.amazonaws:aws-java-sdk-bundle:1.12.262,io.delta:delta-spark_2.12:3.1.0 --name arrow-spark --queue root.default --deploy-mode client dags/silver_to_gold_sc_summary_etl.py --output_path s3a://mybucket/sc_stats_db/gold/summary_data
[2025-06-07T15:53:39.194+0000] {spark_submit.py:644} INFO - :: loading settings :: url = jar:file:/home/***/.local/lib/python3.11/site-packages/pyspark/jars/ivy-2.5.1.jar!/org/apache/ivy/core/settings/ivysettings.xml
[2025-06-07T15:53:39.245+0000] {spark_submit.py:644} INFO - Ivy Default Cache set to: /home/***/.ivy2/cache
[2025-06-07T15:53:39.245+0000] {spark_submit.py:644} INFO - The jars for the packages stored in: /home/***/.ivy2/jars
[2025-06-07T15:53:39.247+0000] {spark_submit.py:644} INFO - org.apache.hadoop#hadoop-aws added as a dependency
[2025-06-07T15:53:39.248+0000] {spark_submit.py:644} INFO - com.amazonaws#aws-java-sdk-bundle added as a dependency
[2025-06-07T15:53:39.248+0000] {spark_submit.py:644} INFO - io.delta#delta-spark_2.12 added as a dependency
[2025-06-07T15:53:39.248+0000] {spark_submit.py:644} INFO - :: resolving dependencies :: org.apache.spark#spark-submit-parent-b555b526-a45a-42e5-ad70-3df74fd1605d;1.0
[2025-06-07T15:53:39.248+0000] {spark_submit.py:644} INFO - confs: [default]
[2025-06-07T15:53:39.333+0000] {spark_submit.py:644} INFO - found org.apache.hadoop#hadoop-aws;3.3.4 in central
[2025-06-07T15:53:39.346+0000] {spark_submit.py:644} INFO - found com.amazonaws#aws-java-sdk-bundle;1.12.262 in central
[2025-06-07T15:53:39.358+0000] {spark_submit.py:644} INFO - found org.wildfly.openssl#wildfly-openssl;1.0.7.Final in central
[2025-06-07T15:53:39.367+0000] {spark_submit.py:644} INFO - found io.delta#delta-spark_2.12;3.1.0 in central
[2025-06-07T15:53:39.377+0000] {spark_submit.py:644} INFO - found io.delta#delta-storage;3.1.0 in central
[2025-06-07T15:53:39.384+0000] {spark_submit.py:644} INFO - found org.antlr#antlr4-runtime;4.9.3 in central
[2025-06-07T15:53:39.399+0000] {spark_submit.py:644} INFO - :: resolution report :: resolve 145ms :: artifacts dl 6ms
[2025-06-07T15:53:39.400+0000] {spark_submit.py:644} INFO - :: modules in use:
[2025-06-07T15:53:39.400+0000] {spark_submit.py:644} INFO - com.amazonaws#aws-java-sdk-bundle;1.12.262 from central in [default]
[2025-06-07T15:53:39.400+0000] {spark_submit.py:644} INFO - io.delta#delta-spark_2.12;3.1.0 from central in [default]
[2025-06-07T15:53:39.401+0000] {spark_submit.py:644} INFO - io.delta#delta-storage;3.1.0 from central in [default]
[2025-06-07T15:53:39.401+0000] {spark_submit.py:644} INFO - org.antlr#antlr4-runtime;4.9.3 from central in [default]
[2025-06-07T15:53:39.401+0000] {spark_submit.py:644} INFO - org.apache.hadoop#hadoop-aws;3.3.4 from central in [default]
[2025-06-07T15:53:39.401+0000] {spark_submit.py:644} INFO - org.wildfly.openssl#wildfly-openssl;1.0.7.Final from central in [default]
[2025-06-07T15:53:39.401+0000] {spark_submit.py:644} INFO - ---------------------------------------------------------------------
[2025-06-07T15:53:39.401+0000] {spark_submit.py:644} INFO - |                  |            modules            ||   artifacts   |
[2025-06-07T15:53:39.401+0000] {spark_submit.py:644} INFO - |       conf       | number| search|dwnlded|evicted|| number|dwnlded|
[2025-06-07T15:53:39.401+0000] {spark_submit.py:644} INFO - ---------------------------------------------------------------------
[2025-06-07T15:53:39.401+0000] {spark_submit.py:644} INFO - |      default     |   6   |   0   |   0   |   0   ||   6   |   0   |
[2025-06-07T15:53:39.402+0000] {spark_submit.py:644} INFO - ---------------------------------------------------------------------
[2025-06-07T15:53:39.402+0000] {spark_submit.py:644} INFO - :: retrieving :: org.apache.spark#spark-submit-parent-b555b526-a45a-42e5-ad70-3df74fd1605d
[2025-06-07T15:53:39.402+0000] {spark_submit.py:644} INFO - confs: [default]
[2025-06-07T15:53:39.405+0000] {spark_submit.py:644} INFO - 0 artifacts copied, 6 already retrieved (0kB/3ms)
[2025-06-07T15:53:39.496+0000] {spark_submit.py:644} INFO - 25/06/07 15:53:39 WARN NativeCodeLoader: Unable to load native-hadoop library for your platform... using builtin-java classes where applicable
[2025-06-07T15:53:40.178+0000] {spark_submit.py:644} INFO - 25/06/07 15:53:40 INFO SparkContext: Running Spark version 3.5.2
[2025-06-07T15:53:40.178+0000] {spark_submit.py:644} INFO - 25/06/07 15:53:40 INFO SparkContext: OS info Linux, 6.10.14-linuxkit, aarch64
[2025-06-07T15:53:40.178+0000] {spark_submit.py:644} INFO - 25/06/07 15:53:40 INFO SparkContext: Java version 17.0.15
[2025-06-07T15:53:40.189+0000] {spark_submit.py:644} INFO - 25/06/07 15:53:40 INFO ResourceUtils: ==============================================================
[2025-06-07T15:53:40.189+0000] {spark_submit.py:644} INFO - 25/06/07 15:53:40 INFO ResourceUtils: No custom resources configured for spark.driver.
[2025-06-07T15:53:40.190+0000] {spark_submit.py:644} INFO - 25/06/07 15:53:40 INFO ResourceUtils: ==============================================================
[2025-06-07T15:53:40.190+0000] {spark_submit.py:644} INFO - 25/06/07 15:53:40 INFO SparkContext: Submitted application: SilverToGoldStephenCurryStats
[2025-06-07T15:53:40.204+0000] {spark_submit.py:644} INFO - 25/06/07 15:53:40 INFO ResourceProfile: Default ResourceProfile created, executor resources: Map(memory -> name: memory, amount: 2048, script: , vendor: , offHeap -> name: offHeap, amount: 0, script: , vendor: ), task resources: Map(cpus -> name: cpus, amount: 1.0)
[2025-06-07T15:53:40.208+0000] {spark_submit.py:644} INFO - 25/06/07 15:53:40 INFO ResourceProfile: Limiting resource is cpu
[2025-06-07T15:53:40.209+0000] {spark_submit.py:644} INFO - 25/06/07 15:53:40 INFO ResourceProfileManager: Added ResourceProfile id: 0
[2025-06-07T15:53:40.237+0000] {spark_submit.py:644} INFO - 25/06/07 15:53:40 INFO SecurityManager: Changing view acls to: ***
[2025-06-07T15:53:40.238+0000] {spark_submit.py:644} INFO - 25/06/07 15:53:40 INFO SecurityManager: Changing modify acls to: ***
[2025-06-07T15:53:40.238+0000] {spark_submit.py:644} INFO - 25/06/07 15:53:40 INFO SecurityManager: Changing view acls groups to:
[2025-06-07T15:53:40.238+0000] {spark_submit.py:644} INFO - 25/06/07 15:53:40 INFO SecurityManager: Changing modify acls groups to:
[2025-06-07T15:53:40.238+0000] {spark_submit.py:644} INFO - 25/06/07 15:53:40 INFO SecurityManager: SecurityManager: authentication disabled; ui acls disabled; users with view permissions: ***; groups with view permissions: EMPTY; users with modify permissions: ***; groups with modify permissions: EMPTY
[2025-06-07T15:53:40.347+0000] {spark_submit.py:644} INFO - 25/06/07 15:53:40 INFO Utils: Successfully started service 'sparkDriver' on port 38743.
[2025-06-07T15:53:40.366+0000] {spark_submit.py:644} INFO - 25/06/07 15:53:40 INFO SparkEnv: Registering MapOutputTracker
[2025-06-07T15:53:40.388+0000] {spark_submit.py:644} INFO - 25/06/07 15:53:40 INFO SparkEnv: Registering BlockManagerMaster
[2025-06-07T15:53:40.396+0000] {spark_submit.py:644} INFO - 25/06/07 15:53:40 INFO BlockManagerMasterEndpoint: Using org.apache.spark.storage.DefaultTopologyMapper for getting topology information
[2025-06-07T15:53:40.397+0000] {spark_submit.py:644} INFO - 25/06/07 15:53:40 INFO BlockManagerMasterEndpoint: BlockManagerMasterEndpoint up
[2025-06-07T15:53:40.399+0000] {spark_submit.py:644} INFO - 25/06/07 15:53:40 INFO SparkEnv: Registering BlockManagerMasterHeartbeat
[2025-06-07T15:53:40.411+0000] {spark_submit.py:644} INFO - 25/06/07 15:53:40 INFO DiskBlockManager: Created local directory at /tmp/blockmgr-be61d30d-9452-4be2-87b7-07c96291a0cb
[2025-06-07T15:53:40.418+0000] {spark_submit.py:644} INFO - 25/06/07 15:53:40 INFO MemoryStore: MemoryStore started with capacity 434.4 MiB
[2025-06-07T15:53:40.426+0000] {spark_submit.py:644} INFO - 25/06/07 15:53:40 INFO SparkEnv: Registering OutputCommitCoordinator
[2025-06-07T15:53:40.483+0000] {spark_submit.py:644} INFO - 25/06/07 15:53:40 INFO JettyUtils: Start Jetty 0.0.0.0:4040 for SparkUI
[2025-06-07T15:53:40.514+0000] {spark_submit.py:644} INFO - 25/06/07 15:53:40 INFO Utils: Successfully started service 'SparkUI' on port 4040.
[2025-06-07T15:53:40.533+0000] {spark_submit.py:644} INFO - 25/06/07 15:53:40 INFO SparkContext: Added JAR file:///home/***/.ivy2/jars/org.apache.hadoop_hadoop-aws-3.3.4.jar at spark://b5e5641a3f5a:38743/jars/org.apache.hadoop_hadoop-aws-3.3.4.jar with timestamp 1749311620174
[2025-06-07T15:53:40.533+0000] {spark_submit.py:644} INFO - 25/06/07 15:53:40 INFO SparkContext: Added JAR file:///home/***/.ivy2/jars/com.amazonaws_aws-java-sdk-bundle-1.12.262.jar at spark://b5e5641a3f5a:38743/jars/com.amazonaws_aws-java-sdk-bundle-1.12.262.jar with timestamp 1749311620174
[2025-06-07T15:53:40.534+0000] {spark_submit.py:644} INFO - 25/06/07 15:53:40 INFO SparkContext: Added JAR file:///home/***/.ivy2/jars/io.delta_delta-spark_2.12-3.1.0.jar at spark://b5e5641a3f5a:38743/jars/io.delta_delta-spark_2.12-3.1.0.jar with timestamp 1749311620174
[2025-06-07T15:53:40.534+0000] {spark_submit.py:644} INFO - 25/06/07 15:53:40 INFO SparkContext: Added JAR file:///home/***/.ivy2/jars/org.wildfly.openssl_wildfly-openssl-1.0.7.Final.jar at spark://b5e5641a3f5a:38743/jars/org.wildfly.openssl_wildfly-openssl-1.0.7.Final.jar with timestamp 1749311620174
[2025-06-07T15:53:40.534+0000] {spark_submit.py:644} INFO - 25/06/07 15:53:40 INFO SparkContext: Added JAR file:///home/***/.ivy2/jars/io.delta_delta-storage-3.1.0.jar at spark://b5e5641a3f5a:38743/jars/io.delta_delta-storage-3.1.0.jar with timestamp 1749311620174
[2025-06-07T15:53:40.534+0000] {spark_submit.py:644} INFO - 25/06/07 15:53:40 INFO SparkContext: Added JAR file:///home/***/.ivy2/jars/org.antlr_antlr4-runtime-4.9.3.jar at spark://b5e5641a3f5a:38743/jars/org.antlr_antlr4-runtime-4.9.3.jar with timestamp 1749311620174
[2025-06-07T15:53:40.535+0000] {spark_submit.py:644} INFO - 25/06/07 15:53:40 INFO SparkContext: Added file file:///home/***/.ivy2/jars/org.apache.hadoop_hadoop-aws-3.3.4.jar at spark://b5e5641a3f5a:38743/files/org.apache.hadoop_hadoop-aws-3.3.4.jar with timestamp 1749311620174
[2025-06-07T15:53:40.535+0000] {spark_submit.py:644} INFO - 25/06/07 15:53:40 INFO Utils: Copying /home/***/.ivy2/jars/org.apache.hadoop_hadoop-aws-3.3.4.jar to /tmp/spark-92697055-f0ba-4e2e-9d61-2ec3dee7b414/userFiles-63b13b6b-0847-4991-816b-150069e7988b/org.apache.hadoop_hadoop-aws-3.3.4.jar
[2025-06-07T15:53:40.541+0000] {spark_submit.py:644} INFO - 25/06/07 15:53:40 INFO SparkContext: Added file file:///home/***/.ivy2/jars/com.amazonaws_aws-java-sdk-bundle-1.12.262.jar at spark://b5e5641a3f5a:38743/files/com.amazonaws_aws-java-sdk-bundle-1.12.262.jar with timestamp 1749311620174
[2025-06-07T15:53:40.542+0000] {spark_submit.py:644} INFO - 25/06/07 15:53:40 INFO Utils: Copying /home/***/.ivy2/jars/com.amazonaws_aws-java-sdk-bundle-1.12.262.jar to /tmp/spark-92697055-f0ba-4e2e-9d61-2ec3dee7b414/userFiles-63b13b6b-0847-4991-816b-150069e7988b/com.amazonaws_aws-java-sdk-bundle-1.12.262.jar
[2025-06-07T15:53:40.615+0000] {spark_submit.py:644} INFO - 25/06/07 15:53:40 INFO SparkContext: Added file file:///home/***/.ivy2/jars/io.delta_delta-spark_2.12-3.1.0.jar at spark://b5e5641a3f5a:38743/files/io.delta_delta-spark_2.12-3.1.0.jar with timestamp 1749311620174
[2025-06-07T15:53:40.615+0000] {spark_submit.py:644} INFO - 25/06/07 15:53:40 INFO Utils: Copying /home/***/.ivy2/jars/io.delta_delta-spark_2.12-3.1.0.jar to /tmp/spark-92697055-f0ba-4e2e-9d61-2ec3dee7b414/userFiles-63b13b6b-0847-4991-816b-150069e7988b/io.delta_delta-spark_2.12-3.1.0.jar
[2025-06-07T15:53:40.619+0000] {spark_submit.py:644} INFO - 25/06/07 15:53:40 INFO SparkContext: Added file file:///home/***/.ivy2/jars/org.wildfly.openssl_wildfly-openssl-1.0.7.Final.jar at spark://b5e5641a3f5a:38743/files/org.wildfly.openssl_wildfly-openssl-1.0.7.Final.jar with timestamp 1749311620174
[2025-06-07T15:53:40.619+0000] {spark_submit.py:644} INFO - 25/06/07 15:53:40 INFO Utils: Copying /home/***/.ivy2/jars/org.wildfly.openssl_wildfly-openssl-1.0.7.Final.jar to /tmp/spark-92697055-f0ba-4e2e-9d61-2ec3dee7b414/userFiles-63b13b6b-0847-4991-816b-150069e7988b/org.wildfly.openssl_wildfly-openssl-1.0.7.Final.jar
[2025-06-07T15:53:40.621+0000] {spark_submit.py:644} INFO - 25/06/07 15:53:40 INFO SparkContext: Added file file:///home/***/.ivy2/jars/io.delta_delta-storage-3.1.0.jar at spark://b5e5641a3f5a:38743/files/io.delta_delta-storage-3.1.0.jar with timestamp 1749311620174
[2025-06-07T15:53:40.621+0000] {spark_submit.py:644} INFO - 25/06/07 15:53:40 INFO Utils: Copying /home/***/.ivy2/jars/io.delta_delta-storage-3.1.0.jar to /tmp/spark-92697055-f0ba-4e2e-9d61-2ec3dee7b414/userFiles-63b13b6b-0847-4991-816b-150069e7988b/io.delta_delta-storage-3.1.0.jar
[2025-06-07T15:53:40.623+0000] {spark_submit.py:644} INFO - 25/06/07 15:53:40 INFO SparkContext: Added file file:///home/***/.ivy2/jars/org.antlr_antlr4-runtime-4.9.3.jar at spark://b5e5641a3f5a:38743/files/org.antlr_antlr4-runtime-4.9.3.jar with timestamp 1749311620174
[2025-06-07T15:53:40.623+0000] {spark_submit.py:644} INFO - 25/06/07 15:53:40 INFO Utils: Copying /home/***/.ivy2/jars/org.antlr_antlr4-runtime-4.9.3.jar to /tmp/spark-92697055-f0ba-4e2e-9d61-2ec3dee7b414/userFiles-63b13b6b-0847-4991-816b-150069e7988b/org.antlr_antlr4-runtime-4.9.3.jar
[2025-06-07T15:53:40.664+0000] {spark_submit.py:644} INFO - 25/06/07 15:53:40 INFO StandaloneAppClient$ClientEndpoint: Connecting to master spark://spark-master:7077...
[2025-06-07T15:53:40.684+0000] {spark_submit.py:644} INFO - 25/06/07 15:53:40 INFO TransportClientFactory: Successfully created connection to spark-master/172.19.0.6:7077 after 10 ms (0 ms spent in bootstraps)
[2025-06-07T15:53:40.725+0000] {spark_submit.py:644} INFO - 25/06/07 15:53:40 INFO StandaloneSchedulerBackend: Connected to Spark cluster with app ID app-20250607155340-0002
[2025-06-07T15:53:40.729+0000] {spark_submit.py:644} INFO - 25/06/07 15:53:40 INFO StandaloneAppClient$ClientEndpoint: Executor added: app-20250607155340-0002/0 on worker-20250607155059-172.19.0.7-41643 (172.19.0.7:41643) with 4 core(s)
[2025-06-07T15:53:40.730+0000] {spark_submit.py:644} INFO - 25/06/07 15:53:40 INFO StandaloneSchedulerBackend: Granted executor ID app-20250607155340-0002/0 on hostPort 172.19.0.7:41643 with 4 core(s), 2.0 GiB RAM
[2025-06-07T15:53:40.730+0000] {spark_submit.py:644} INFO - 25/06/07 15:53:40 INFO Utils: Successfully started service 'org.apache.spark.network.netty.NettyBlockTransferService' on port 39641.
[2025-06-07T15:53:40.730+0000] {spark_submit.py:644} INFO - 25/06/07 15:53:40 INFO NettyBlockTransferService: Server created on b5e5641a3f5a:39641
[2025-06-07T15:53:40.731+0000] {spark_submit.py:644} INFO - 25/06/07 15:53:40 INFO BlockManager: Using org.apache.spark.storage.RandomBlockReplicationPolicy for block replication policy
[2025-06-07T15:53:40.734+0000] {spark_submit.py:644} INFO - 25/06/07 15:53:40 INFO BlockManagerMaster: Registering BlockManager BlockManagerId(driver, b5e5641a3f5a, 39641, None)
[2025-06-07T15:53:40.736+0000] {spark_submit.py:644} INFO - 25/06/07 15:53:40 INFO BlockManagerMasterEndpoint: Registering block manager b5e5641a3f5a:39641 with 434.4 MiB RAM, BlockManagerId(driver, b5e5641a3f5a, 39641, None)
[2025-06-07T15:53:40.738+0000] {spark_submit.py:644} INFO - 25/06/07 15:53:40 INFO BlockManagerMaster: Registered BlockManager BlockManagerId(driver, b5e5641a3f5a, 39641, None)
[2025-06-07T15:53:40.738+0000] {spark_submit.py:644} INFO - 25/06/07 15:53:40 INFO BlockManager: Initialized BlockManager: BlockManagerId(driver, b5e5641a3f5a, 39641, None)
[2025-06-07T15:53:40.746+0000] {spark_submit.py:644} INFO - 25/06/07 15:53:40 INFO StandaloneAppClient$ClientEndpoint: Executor updated: app-20250607155340-0002/0 is now RUNNING
[2025-06-07T15:53:40.839+0000] {spark_submit.py:644} INFO - 25/06/07 15:53:40 INFO StandaloneSchedulerBackend: SchedulerBackend is ready for scheduling beginning after reached minRegisteredResourcesRatio: 0.0
[2025-06-07T15:53:40.963+0000] {spark_submit.py:644} INFO - Silver to Gold: Spark session created.
[2025-06-07T15:53:40.967+0000] {spark_submit.py:644} INFO - 25/06/07 15:53:40 INFO SharedState: Setting hive.metastore.warehouse.dir ('null') to the value of spark.sql.warehouse.dir.
[2025-06-07T15:53:40.968+0000] {spark_submit.py:644} INFO - 25/06/07 15:53:40 INFO SharedState: Warehouse path is 'file:/tmp/spark-warehouse'.
[2025-06-07T15:53:41.514+0000] {spark_submit.py:644} INFO - 25/06/07 15:53:41 INFO HiveConf: Found configuration file null
[2025-06-07T15:53:41.519+0000] {spark_submit.py:644} INFO - 25/06/07 15:53:41 INFO HiveUtils: Initializing HiveMetastoreConnection version 2.3.9 using Spark classes.
[2025-06-07T15:53:41.631+0000] {spark_submit.py:644} INFO - 25/06/07 15:53:41 INFO HiveClientImpl: Warehouse location for Hive client (version 2.3.9) is file:/tmp/spark-warehouse
[2025-06-07T15:53:41.648+0000] {spark_submit.py:644} INFO - 25/06/07 15:53:41 INFO metastore: Trying to connect to metastore with URI thrift://hive-metastore:9083
[2025-06-07T15:53:41.658+0000] {spark_submit.py:644} INFO - 25/06/07 15:53:41 INFO metastore: Opened a connection to metastore, current connections: 1
[2025-06-07T15:53:41.669+0000] {spark_submit.py:644} INFO - 25/06/07 15:53:41 INFO metastore: Connected to metastore.
[2025-06-07T15:53:42.179+0000] {spark_submit.py:644} INFO - 25/06/07 15:53:42 WARN MetricsConfig: Cannot locate configuration: tried hadoop-metrics2-s3a-file-system.properties,hadoop-metrics2.properties
[2025-06-07T15:53:42.184+0000] {spark_submit.py:644} INFO - 25/06/07 15:53:42 INFO MetricsSystemImpl: Scheduled Metric snapshot period at 10 second(s).
[2025-06-07T15:53:42.185+0000] {spark_submit.py:644} INFO - 25/06/07 15:53:42 INFO MetricsSystemImpl: s3a-file-system metrics system started
[2025-06-07T15:53:42.275+0000] {spark_submit.py:644} INFO - 25/06/07 15:53:42 INFO StandaloneSchedulerBackend$StandaloneDriverEndpoint: Registered executor NettyRpcEndpointRef(spark-client://Executor) (172.19.0.7:38856) with ID 0,  ResourceProfileId 0
[2025-06-07T15:53:42.314+0000] {spark_submit.py:644} INFO - 25/06/07 15:53:42 INFO BlockManagerMasterEndpoint: Registering block manager 172.19.0.7:37165 with 1048.8 MiB RAM, BlockManagerId(0, 172.19.0.7, 37165, None)
[2025-06-07T15:53:42.662+0000] {spark_submit.py:644} INFO - 25/06/07 15:53:42 INFO DelegatingLogStore: LogStore `LogStoreAdapter(io.delta.storage.S3SingleDriverLogStore)` is used for scheme `s3a`
[2025-06-07T15:53:42.791+0000] {spark_submit.py:644} INFO - 25/06/07 15:53:42 INFO DeltaLog: Loading version 0.
[2025-06-07T15:53:43.880+0000] {spark_submit.py:644} INFO - 25/06/07 15:53:43 INFO DeltaLogFileIndex: Created DeltaLogFileIndex(JSON, numFilesInSegment: 1, totalFileSize: 3974)
[2025-06-07T15:53:44.308+0000] {spark_submit.py:644} INFO - 25/06/07 15:53:44 INFO DataSourceStrategy: Pruning directories with:
[2025-06-07T15:53:44.318+0000] {spark_submit.py:644} INFO - 25/06/07 15:53:44 INFO FileSourceStrategy: Pushed Filters:
[2025-06-07T15:53:44.319+0000] {spark_submit.py:644} INFO - 25/06/07 15:53:44 INFO FileSourceStrategy: Post-Scan Filters: (isnotnull(protocol#11.minReaderVersion) OR isnotnull(metaData#10.id))
[2025-06-07T15:53:44.563+0000] {spark_submit.py:644} INFO - 25/06/07 15:53:44 INFO CodeGenerator: Code generated in 149.361208 ms
[2025-06-07T15:53:44.598+0000] {spark_submit.py:644} INFO - 25/06/07 15:53:44 INFO MemoryStore: Block broadcast_0 stored as values in memory (estimated size 205.3 KiB, free 434.2 MiB)
[2025-06-07T15:53:44.623+0000] {spark_submit.py:644} INFO - 25/06/07 15:53:44 INFO MemoryStore: Block broadcast_0_piece0 stored as bytes in memory (estimated size 36.1 KiB, free 434.2 MiB)
[2025-06-07T15:53:44.625+0000] {spark_submit.py:644} INFO - 25/06/07 15:53:44 INFO BlockManagerInfo: Added broadcast_0_piece0 in memory on b5e5641a3f5a:39641 (size: 36.1 KiB, free: 434.4 MiB)
[2025-06-07T15:53:44.628+0000] {spark_submit.py:644} INFO - 25/06/07 15:53:44 INFO SparkContext: Created broadcast 0 from toString at String.java:4220
[2025-06-07T15:53:44.643+0000] {spark_submit.py:644} INFO - 25/06/07 15:53:44 INFO FileSourceScanExec: Planning scan with bin packing, max size: 4194304 bytes, open cost is considered as scanning 4194304 bytes.
[2025-06-07T15:53:44.732+0000] {spark_submit.py:644} INFO - 25/06/07 15:53:44 INFO SparkContext: Starting job: toString at String.java:4220
[2025-06-07T15:53:44.739+0000] {spark_submit.py:644} INFO - 25/06/07 15:53:44 INFO DAGScheduler: Got job 0 (toString at String.java:4220) with 1 output partitions
[2025-06-07T15:53:44.740+0000] {spark_submit.py:644} INFO - 25/06/07 15:53:44 INFO DAGScheduler: Final stage: ResultStage 0 (toString at String.java:4220)
[2025-06-07T15:53:44.740+0000] {spark_submit.py:644} INFO - 25/06/07 15:53:44 INFO DAGScheduler: Parents of final stage: List()
[2025-06-07T15:53:44.741+0000] {spark_submit.py:644} INFO - 25/06/07 15:53:44 INFO DAGScheduler: Missing parents: List()
[2025-06-07T15:53:44.742+0000] {spark_submit.py:644} INFO - 25/06/07 15:53:44 INFO DAGScheduler: Submitting ResultStage 0 (MapPartitionsRDD[3] at toString at String.java:4220), which has no missing parents
[2025-06-07T15:53:44.752+0000] {spark_submit.py:644} INFO - 25/06/07 15:53:44 INFO MemoryStore: Block broadcast_1 stored as values in memory (estimated size 40.0 KiB, free 434.1 MiB)
[2025-06-07T15:53:44.752+0000] {spark_submit.py:644} INFO - 25/06/07 15:53:44 INFO MemoryStore: Block broadcast_1_piece0 stored as bytes in memory (estimated size 13.7 KiB, free 434.1 MiB)
[2025-06-07T15:53:44.753+0000] {spark_submit.py:644} INFO - 25/06/07 15:53:44 INFO BlockManagerInfo: Added broadcast_1_piece0 in memory on b5e5641a3f5a:39641 (size: 13.7 KiB, free: 434.4 MiB)
[2025-06-07T15:53:44.753+0000] {spark_submit.py:644} INFO - 25/06/07 15:53:44 INFO SparkContext: Created broadcast 1 from broadcast at DAGScheduler.scala:1585
[2025-06-07T15:53:44.764+0000] {spark_submit.py:644} INFO - 25/06/07 15:53:44 INFO DAGScheduler: Submitting 1 missing tasks from ResultStage 0 (MapPartitionsRDD[3] at toString at String.java:4220) (first 15 tasks are for partitions Vector(0))
[2025-06-07T15:53:44.765+0000] {spark_submit.py:644} INFO - 25/06/07 15:53:44 INFO TaskSchedulerImpl: Adding task set 0.0 with 1 tasks resource profile 0
[2025-06-07T15:53:44.780+0000] {spark_submit.py:644} INFO - 25/06/07 15:53:44 INFO TaskSetManager: Starting task 0.0 in stage 0.0 (TID 0) (172.19.0.7, executor 0, partition 0, PROCESS_LOCAL, 10850 bytes)
[2025-06-07T15:53:44.905+0000] {spark_submit.py:644} INFO - 25/06/07 15:53:44 INFO BlockManagerInfo: Added broadcast_1_piece0 in memory on 172.19.0.7:37165 (size: 13.7 KiB, free: 1048.8 MiB)
[2025-06-07T15:53:45.412+0000] {spark_submit.py:644} INFO - 25/06/07 15:53:45 INFO BlockManagerInfo: Added broadcast_0_piece0 in memory on 172.19.0.7:37165 (size: 36.1 KiB, free: 1048.8 MiB)
[2025-06-07T15:53:45.989+0000] {spark_submit.py:644} INFO - 25/06/07 15:53:45 INFO TaskSetManager: Finished task 0.0 in stage 0.0 (TID 0) in 1215 ms on 172.19.0.7 (executor 0) (1/1)
[2025-06-07T15:53:45.990+0000] {spark_submit.py:644} INFO - 25/06/07 15:53:45 INFO TaskSchedulerImpl: Removed TaskSet 0.0, whose tasks have all completed, from pool
[2025-06-07T15:53:45.993+0000] {spark_submit.py:644} INFO - 25/06/07 15:53:45 INFO DAGScheduler: ResultStage 0 (toString at String.java:4220) finished in 1.243 s
[2025-06-07T15:53:45.994+0000] {spark_submit.py:644} INFO - 25/06/07 15:53:45 INFO DAGScheduler: Job 0 is finished. Cancelling potential speculative or zombie tasks for this job
[2025-06-07T15:53:45.994+0000] {spark_submit.py:644} INFO - 25/06/07 15:53:45 INFO TaskSchedulerImpl: Killing all running tasks in stage 0: Stage finished
[2025-06-07T15:53:45.995+0000] {spark_submit.py:644} INFO - 25/06/07 15:53:45 INFO DAGScheduler: Job 0 finished: toString at String.java:4220, took 1.261267 s
[2025-06-07T15:53:46.028+0000] {spark_submit.py:644} INFO - 25/06/07 15:53:46 INFO BlockManagerInfo: Removed broadcast_1_piece0 on b5e5641a3f5a:39641 in memory (size: 13.7 KiB, free: 434.4 MiB)
[2025-06-07T15:53:46.030+0000] {spark_submit.py:644} INFO - 25/06/07 15:53:46 INFO BlockManagerInfo: Removed broadcast_1_piece0 on 172.19.0.7:37165 in memory (size: 13.7 KiB, free: 1048.8 MiB)
[2025-06-07T15:53:46.049+0000] {spark_submit.py:644} INFO - 25/06/07 15:53:46 INFO CodeGenerator: Code generated in 37.10025 ms
[2025-06-07T15:53:46.053+0000] {spark_submit.py:644} INFO - 25/06/07 15:53:46 INFO Snapshot: [tableId=5e8e0847-57b5-47f9-b5c1-d1f7f24b7e05] Created snapshot Snapshot(path=s3a://mybucket/sc_stats_db/silver/transformed_data/_delta_log, version=0, metadata=Metadata(f55065e3-5b96-4330-a530-1eddc6979537,null,null,Format(parquet,Map()),{"type":"struct","fields":[{"name":"Season_year","type":"string","nullable":true,"metadata":{}},{"name":"Season_div","type":"string","nullable":true,"metadata":{}},{"name":"Date","type":"date","nullable":true,"metadata":{}},{"name":"OPP","type":"string","nullable":true,"metadata":{}},{"name":"Result","type":"string","nullable":true,"metadata":{}},{"name":"T_Score","type":"long","nullable":true,"metadata":{}},{"name":"O_Score","type":"long","nullable":true,"metadata":{}},{"name":"MIN","type":"double","nullable":true,"metadata":{}},{"name":"FG","type":"string","nullable":true,"metadata":{}},{"name":"FGM","type":"long","nullable":true,"metadata":{}},{"name":"FGA","type":"long","nullable":true,"metadata":{}},{"name":"FG_Percentage","type":"double","nullable":true,"metadata":{}},{"name":"3PT","type":"string","nullable":true,"metadata":{}},{"name":"3PTM","type":"long","nullable":true,"metadata":{}},{"name":"3PTA","type":"long","nullable":true,"metadata":{}},{"name":"3P_Percentage","type":"double","nullable":true,"metadata":{}},{"name":"FT","type":"string","nullable":true,"metadata":{}},{"name":"FTM","type":"long","nullable":true,"metadata":{}},{"name":"FTA","type":"long","nullable":true,"metadata":{}},{"name":"FT_Percentage","type":"double","nullable":true,"metadata":{}},{"name":"REB","type":"long","nullable":true,"metadata":{}},{"name":"AST","type":"long","nullable":true,"metadata":{}},{"name":"BLK","type":"long","nullable":true,"metadata":{}},{"name":"STL","type":"long","nullable":true,"metadata":{}},{"name":"PF","type":"long","nullable":true,"metadata":{}},{"name":"TO","type":"long","nullable":true,"metadata":{}},{"name":"PTS","type":"long","nullable":true,"metadata":{}},{"name":"Point_Difference","type":"long","nullable":true,"metadata":{}}]},List(),Map(),Some(1749311609921)), logSegment=LogSegment(s3a://mybucket/sc_stats_db/silver/transformed_data/_delta_log,0,WrappedArray(S3AFileStatus{path=s3a://mybucket/sc_stats_db/silver/transformed_data/_delta_log/00000000000000000000.json; isDirectory=false; length=3974; replication=1; blocksize=33554432; modification_time=1749311615758; access_time=0; owner=***; group=***; permission=rw-rw-rw-; isSymlink=false; hasAcl=false; isEncrypted=true; isErasureCoded=false} isEmptyDirectory=FALSE eTag=afef6a342cb628fb554bdf80f29b3867 versionId=null),org.apache.spark.sql.delta.EmptyCheckpointProvider$@57a46c50,1749311615758), checksumOpt=None)
[2025-06-07T15:53:46.126+0000] {spark_submit.py:644} INFO - Successfully read silver table
[2025-06-07T15:53:46.167+0000] {spark_submit.py:644} INFO - Writing data to Gold layer
[2025-06-07T15:53:46.225+0000] {spark_submit.py:644} INFO - 25/06/07 15:53:46 WARN SparkStringUtils: Truncated the string representation of a plan since it was too large. This behavior can be adjusted by setting 'spark.sql.debug.maxToStringFields'.
[2025-06-07T15:53:46.276+0000] {spark_submit.py:644} INFO - 25/06/07 15:53:46 INFO DelegatingLogStore: LogStore `LogStoreAdapter(io.delta.storage.S3SingleDriverLogStore)` is used for scheme `s3a`
[2025-06-07T15:53:46.285+0000] {spark_submit.py:644} INFO - 25/06/07 15:53:46 INFO DeltaLog: Creating initial snapshot without metadata, because the directory is empty
[2025-06-07T15:53:46.287+0000] {spark_submit.py:644} INFO - 25/06/07 15:53:46 INFO InitialSnapshot: [tableId=e5383cd0-2880-4796-ab05-6fb71fed3bcd] Created snapshot InitialSnapshot(path=s3a://mybucket/sc_stats_db/gold/summary_data/_delta_log, version=-1, metadata=Metadata(76c30ad8-b4ee-4fd5-920e-d1c3c047e306,null,null,Format(parquet,Map()),null,List(),Map(),Some(1749311626286)), logSegment=LogSegment(s3a://mybucket/sc_stats_db/gold/summary_data/_delta_log,-1,List(),org.apache.spark.sql.delta.EmptyCheckpointProvider$@57a46c50,-1), checksumOpt=None)
[2025-06-07T15:53:46.319+0000] {spark_submit.py:644} INFO - 25/06/07 15:53:46 INFO DeltaLog: No delta log found for the Delta table at s3a://mybucket/sc_stats_db/gold/summary_data/_delta_log
[2025-06-07T15:53:46.320+0000] {spark_submit.py:644} INFO - 25/06/07 15:53:46 INFO InitialSnapshot: [tableId=76c30ad8-b4ee-4fd5-920e-d1c3c047e306] Created snapshot InitialSnapshot(path=s3a://mybucket/sc_stats_db/gold/summary_data/_delta_log, version=-1, metadata=Metadata(a3476ef1-c64d-47ea-915d-5b221114e056,null,null,Format(parquet,Map()),null,List(),Map(),Some(1749311626319)), logSegment=LogSegment(s3a://mybucket/sc_stats_db/gold/summary_data/_delta_log,-1,List(),org.apache.spark.sql.delta.EmptyCheckpointProvider$@57a46c50,-1), checksumOpt=None)
[2025-06-07T15:53:46.346+0000] {spark_submit.py:644} INFO - 25/06/07 15:53:46 INFO OptimisticTransaction: [tableId=a3476ef1,txnId=72bc4bd3] Updated metadata from - to Metadata(5498a60c-0405-44de-bab5-d99d0ed0ad1e,null,null,Format(parquet,Map()),{"type":"struct","fields":[{"name":"Season_year","type":"string","nullable":true,"metadata":{}},{"name":"Season_div","type":"string","nullable":true,"metadata":{}},{"name":"Date","type":"date","nullable":true,"metadata":{}},{"name":"OPP","type":"string","nullable":true,"metadata":{}},{"name":"Result","type":"string","nullable":true,"metadata":{}},{"name":"T_Score","type":"long","nullable":true,"metadata":{}},{"name":"O_Score","type":"long","nullable":true,"metadata":{}},{"name":"MIN","type":"double","nullable":true,"metadata":{}},{"name":"FG","type":"string","nullable":true,"metadata":{}},{"name":"FGM","type":"long","nullable":true,"metadata":{}},{"name":"FGA","type":"long","nullable":true,"metadata":{}},{"name":"FG_Percentage","type":"double","nullable":true,"metadata":{}},{"name":"3PT","type":"string","nullable":true,"metadata":{}},{"name":"3PTM","type":"long","nullable":true,"metadata":{}},{"name":"3PTA","type":"long","nullable":true,"metadata":{}},{"name":"3P_Percentage","type":"double","nullable":true,"metadata":{}},{"name":"FT","type":"string","nullable":true,"metadata":{}},{"name":"FTM","type":"long","nullable":true,"metadata":{}},{"name":"FTA","type":"long","nullable":true,"metadata":{}},{"name":"FT_Percentage","type":"double","nullable":true,"metadata":{}},{"name":"REB","type":"long","nullable":true,"metadata":{}},{"name":"AST","type":"long","nullable":true,"metadata":{}},{"name":"BLK","type":"long","nullable":true,"metadata":{}},{"name":"STL","type":"long","nullable":true,"metadata":{}},{"name":"PF","type":"long","nullable":true,"metadata":{}},{"name":"TO","type":"long","nullable":true,"metadata":{}},{"name":"PTS","type":"long","nullable":true,"metadata":{}},{"name":"Point_Difference","type":"long","nullable":true,"metadata":{}},{"name":"processing_date","type":"date","nullable":true,"metadata":{}}]},ArrayBuffer(),Map(),Some(1749311626334))
[2025-06-07T15:53:46.430+0000] {spark_submit.py:644} INFO - 25/06/07 15:53:46 INFO BlockManagerInfo: Removed broadcast_0_piece0 on b5e5641a3f5a:39641 in memory (size: 36.1 KiB, free: 434.4 MiB)
[2025-06-07T15:53:46.431+0000] {spark_submit.py:644} INFO - 25/06/07 15:53:46 INFO BlockManagerInfo: Removed broadcast_0_piece0 on 172.19.0.7:37165 in memory (size: 36.1 KiB, free: 1048.8 MiB)
[2025-06-07T15:53:46.570+0000] {spark_submit.py:644} INFO - 25/06/07 15:53:46 INFO PrepareDeltaScan: DELTA: Filtering files for query
[2025-06-07T15:53:46.572+0000] {spark_submit.py:644} INFO - 25/06/07 15:53:46 INFO Snapshot: [tableId=f55065e3-5b96-4330-a530-1eddc6979537] DELTA: Compute snapshot for version: 0
[2025-06-07T15:53:46.579+0000] {spark_submit.py:644} INFO - 25/06/07 15:53:46 INFO MemoryStore: Block broadcast_2 stored as values in memory (estimated size 205.0 KiB, free 434.2 MiB)
[2025-06-07T15:53:46.584+0000] {spark_submit.py:644} INFO - 25/06/07 15:53:46 INFO MemoryStore: Block broadcast_2_piece0 stored as bytes in memory (estimated size 36.0 KiB, free 434.2 MiB)
[2025-06-07T15:53:46.584+0000] {spark_submit.py:644} INFO - 25/06/07 15:53:46 INFO BlockManagerInfo: Added broadcast_2_piece0 in memory on b5e5641a3f5a:39641 (size: 36.0 KiB, free: 434.4 MiB)
[2025-06-07T15:53:46.585+0000] {spark_submit.py:644} INFO - 25/06/07 15:53:46 INFO SparkContext: Created broadcast 2 from $anonfun$recordDeltaOperationInternal$1 at DatabricksLogging.scala:128
[2025-06-07T15:53:46.842+0000] {spark_submit.py:644} INFO - 25/06/07 15:53:46 INFO DataSourceStrategy: Pruning directories with:
[2025-06-07T15:53:46.842+0000] {spark_submit.py:644} INFO - 25/06/07 15:53:46 INFO FileSourceStrategy: Pushed Filters:
[2025-06-07T15:53:46.843+0000] {spark_submit.py:644} INFO - 25/06/07 15:53:46 INFO FileSourceStrategy: Post-Scan Filters:
[2025-06-07T15:53:46.980+0000] {spark_submit.py:644} INFO - 25/06/07 15:53:46 INFO CodeGenerator: Code generated in 63.225666 ms
[2025-06-07T15:53:46.982+0000] {spark_submit.py:644} INFO - 25/06/07 15:53:46 INFO MemoryStore: Block broadcast_3 stored as values in memory (estimated size 205.3 KiB, free 434.0 MiB)
[2025-06-07T15:53:46.987+0000] {spark_submit.py:644} INFO - 25/06/07 15:53:46 INFO MemoryStore: Block broadcast_3_piece0 stored as bytes in memory (estimated size 36.1 KiB, free 433.9 MiB)
[2025-06-07T15:53:46.988+0000] {spark_submit.py:644} INFO - 25/06/07 15:53:46 INFO BlockManagerInfo: Added broadcast_3_piece0 in memory on b5e5641a3f5a:39641 (size: 36.1 KiB, free: 434.3 MiB)
[2025-06-07T15:53:46.989+0000] {spark_submit.py:644} INFO - 25/06/07 15:53:46 INFO SparkContext: Created broadcast 3 from $anonfun$recordDeltaOperationInternal$1 at DatabricksLogging.scala:128
[2025-06-07T15:53:46.989+0000] {spark_submit.py:644} INFO - 25/06/07 15:53:46 INFO FileSourceScanExec: Planning scan with bin packing, max size: 4194304 bytes, open cost is considered as scanning 4194304 bytes.
[2025-06-07T15:53:47.029+0000] {spark_submit.py:644} INFO - 25/06/07 15:53:47 INFO DAGScheduler: Registering RDD 7 ($anonfun$recordDeltaOperationInternal$1 at DatabricksLogging.scala:128) as input to shuffle 0
[2025-06-07T15:53:47.032+0000] {spark_submit.py:644} INFO - 25/06/07 15:53:47 INFO DAGScheduler: Got map stage job 1 ($anonfun$recordDeltaOperationInternal$1 at DatabricksLogging.scala:128) with 1 output partitions
[2025-06-07T15:53:47.032+0000] {spark_submit.py:644} INFO - 25/06/07 15:53:47 INFO DAGScheduler: Final stage: ShuffleMapStage 1 ($anonfun$recordDeltaOperationInternal$1 at DatabricksLogging.scala:128)
[2025-06-07T15:53:47.032+0000] {spark_submit.py:644} INFO - 25/06/07 15:53:47 INFO DAGScheduler: Parents of final stage: List()
[2025-06-07T15:53:47.032+0000] {spark_submit.py:644} INFO - 25/06/07 15:53:47 INFO DAGScheduler: Missing parents: List()
[2025-06-07T15:53:47.033+0000] {spark_submit.py:644} INFO - 25/06/07 15:53:47 INFO DAGScheduler: Submitting ShuffleMapStage 1 (MapPartitionsRDD[7] at $anonfun$recordDeltaOperationInternal$1 at DatabricksLogging.scala:128), which has no missing parents
[2025-06-07T15:53:47.042+0000] {spark_submit.py:644} INFO - 25/06/07 15:53:47 INFO MemoryStore: Block broadcast_4 stored as values in memory (estimated size 105.6 KiB, free 433.8 MiB)
[2025-06-07T15:53:47.043+0000] {spark_submit.py:644} INFO - 25/06/07 15:53:47 INFO MemoryStore: Block broadcast_4_piece0 stored as bytes in memory (estimated size 32.6 KiB, free 433.8 MiB)
[2025-06-07T15:53:47.044+0000] {spark_submit.py:644} INFO - 25/06/07 15:53:47 INFO BlockManagerInfo: Added broadcast_4_piece0 in memory on b5e5641a3f5a:39641 (size: 32.6 KiB, free: 434.3 MiB)
[2025-06-07T15:53:47.044+0000] {spark_submit.py:644} INFO - 25/06/07 15:53:47 INFO SparkContext: Created broadcast 4 from broadcast at DAGScheduler.scala:1585
[2025-06-07T15:53:47.045+0000] {spark_submit.py:644} INFO - 25/06/07 15:53:47 INFO DAGScheduler: Submitting 1 missing tasks from ShuffleMapStage 1 (MapPartitionsRDD[7] at $anonfun$recordDeltaOperationInternal$1 at DatabricksLogging.scala:128) (first 15 tasks are for partitions Vector(0))
[2025-06-07T15:53:47.045+0000] {spark_submit.py:644} INFO - 25/06/07 15:53:47 INFO TaskSchedulerImpl: Adding task set 1.0 with 1 tasks resource profile 0
[2025-06-07T15:53:47.047+0000] {spark_submit.py:644} INFO - 25/06/07 15:53:47 INFO TaskSetManager: Starting task 0.0 in stage 1.0 (TID 1) (172.19.0.7, executor 0, partition 0, PROCESS_LOCAL, 10839 bytes)
[2025-06-07T15:53:47.065+0000] {spark_submit.py:644} INFO - 25/06/07 15:53:47 INFO BlockManagerInfo: Added broadcast_4_piece0 in memory on 172.19.0.7:37165 (size: 32.6 KiB, free: 1048.8 MiB)
[2025-06-07T15:53:47.323+0000] {spark_submit.py:644} INFO - 25/06/07 15:53:47 INFO BlockManagerInfo: Added broadcast_3_piece0 in memory on 172.19.0.7:37165 (size: 36.1 KiB, free: 1048.7 MiB)
[2025-06-07T15:53:47.826+0000] {spark_submit.py:644} INFO - 25/06/07 15:53:47 INFO TaskSetManager: Finished task 0.0 in stage 1.0 (TID 1) in 780 ms on 172.19.0.7 (executor 0) (1/1)
[2025-06-07T15:53:47.827+0000] {spark_submit.py:644} INFO - 25/06/07 15:53:47 INFO TaskSchedulerImpl: Removed TaskSet 1.0, whose tasks have all completed, from pool
[2025-06-07T15:53:47.828+0000] {spark_submit.py:644} INFO - 25/06/07 15:53:47 INFO DAGScheduler: ShuffleMapStage 1 ($anonfun$recordDeltaOperationInternal$1 at DatabricksLogging.scala:128) finished in 0.793 s
[2025-06-07T15:53:47.828+0000] {spark_submit.py:644} INFO - 25/06/07 15:53:47 INFO DAGScheduler: looking for newly runnable stages
[2025-06-07T15:53:47.828+0000] {spark_submit.py:644} INFO - 25/06/07 15:53:47 INFO DAGScheduler: running: Set()
[2025-06-07T15:53:47.828+0000] {spark_submit.py:644} INFO - 25/06/07 15:53:47 INFO DAGScheduler: waiting: Set()
[2025-06-07T15:53:47.828+0000] {spark_submit.py:644} INFO - 25/06/07 15:53:47 INFO DAGScheduler: failed: Set()
[2025-06-07T15:53:47.952+0000] {spark_submit.py:644} INFO - 25/06/07 15:53:47 INFO BlockManagerInfo: Removed broadcast_4_piece0 on b5e5641a3f5a:39641 in memory (size: 32.6 KiB, free: 434.3 MiB)
[2025-06-07T15:53:47.954+0000] {spark_submit.py:644} INFO - 25/06/07 15:53:47 INFO BlockManagerInfo: Removed broadcast_4_piece0 on 172.19.0.7:37165 in memory (size: 32.6 KiB, free: 1048.8 MiB)
[2025-06-07T15:53:48.038+0000] {spark_submit.py:644} INFO - 25/06/07 15:53:48 INFO CodeGenerator: Generated method too long to be JIT compiled: org.apache.spark.sql.catalyst.expressions.GeneratedClass$GeneratedIteratorForCodegenStage3.serializefromobject_doConsume_0$ is 24899 bytes
[2025-06-07T15:53:48.039+0000] {spark_submit.py:644} INFO - 25/06/07 15:53:48 INFO CodeGenerator: Code generated in 132.182958 ms
[2025-06-07T15:53:48.083+0000] {spark_submit.py:644} INFO - 25/06/07 15:53:48 INFO CodeGenerator: Code generated in 32.276833 ms
[2025-06-07T15:53:48.240+0000] {spark_submit.py:644} INFO - 25/06/07 15:53:48 INFO CodeGenerator: Code generated in 33.826625 ms
[2025-06-07T15:53:48.246+0000] {spark_submit.py:644} INFO - 25/06/07 15:53:48 INFO DAGScheduler: Registering RDD 17 ($anonfun$recordDeltaOperationInternal$1 at DatabricksLogging.scala:128) as input to shuffle 1
[2025-06-07T15:53:48.246+0000] {spark_submit.py:644} INFO - 25/06/07 15:53:48 INFO DAGScheduler: Got map stage job 2 ($anonfun$recordDeltaOperationInternal$1 at DatabricksLogging.scala:128) with 50 output partitions
[2025-06-07T15:53:48.247+0000] {spark_submit.py:644} INFO - 25/06/07 15:53:48 INFO DAGScheduler: Final stage: ShuffleMapStage 3 ($anonfun$recordDeltaOperationInternal$1 at DatabricksLogging.scala:128)
[2025-06-07T15:53:48.247+0000] {spark_submit.py:644} INFO - 25/06/07 15:53:48 INFO DAGScheduler: Parents of final stage: List(ShuffleMapStage 2)
[2025-06-07T15:53:48.247+0000] {spark_submit.py:644} INFO - 25/06/07 15:53:48 INFO DAGScheduler: Missing parents: List()
[2025-06-07T15:53:48.248+0000] {spark_submit.py:644} INFO - 25/06/07 15:53:48 INFO DAGScheduler: Submitting ShuffleMapStage 3 (MapPartitionsRDD[17] at $anonfun$recordDeltaOperationInternal$1 at DatabricksLogging.scala:128), which has no missing parents
[2025-06-07T15:53:48.268+0000] {spark_submit.py:644} INFO - 25/06/07 15:53:48 INFO MemoryStore: Block broadcast_5 stored as values in memory (estimated size 602.6 KiB, free 433.3 MiB)
[2025-06-07T15:53:48.269+0000] {spark_submit.py:644} INFO - 25/06/07 15:53:48 INFO MemoryStore: Block broadcast_5_piece0 stored as bytes in memory (estimated size 138.2 KiB, free 433.2 MiB)
[2025-06-07T15:53:48.270+0000] {spark_submit.py:644} INFO - 25/06/07 15:53:48 INFO BlockManagerInfo: Added broadcast_5_piece0 in memory on b5e5641a3f5a:39641 (size: 138.2 KiB, free: 434.2 MiB)
[2025-06-07T15:53:48.270+0000] {spark_submit.py:644} INFO - 25/06/07 15:53:48 INFO SparkContext: Created broadcast 5 from broadcast at DAGScheduler.scala:1585
[2025-06-07T15:53:48.270+0000] {spark_submit.py:644} INFO - 25/06/07 15:53:48 INFO DAGScheduler: Submitting 50 missing tasks from ShuffleMapStage 3 (MapPartitionsRDD[17] at $anonfun$recordDeltaOperationInternal$1 at DatabricksLogging.scala:128) (first 15 tasks are for partitions Vector(0, 1, 2, 3, 4, 5, 6, 7, 8, 9, 10, 11, 12, 13, 14))
[2025-06-07T15:53:48.271+0000] {spark_submit.py:644} INFO - 25/06/07 15:53:48 INFO TaskSchedulerImpl: Adding task set 3.0 with 50 tasks resource profile 0
[2025-06-07T15:53:48.273+0000] {spark_submit.py:644} INFO - 25/06/07 15:53:48 INFO TaskSetManager: Starting task 12.0 in stage 3.0 (TID 2) (172.19.0.7, executor 0, partition 12, NODE_LOCAL, 10175 bytes)
[2025-06-07T15:53:48.273+0000] {spark_submit.py:644} INFO - 25/06/07 15:53:48 INFO TaskSetManager: Starting task 42.0 in stage 3.0 (TID 3) (172.19.0.7, executor 0, partition 42, NODE_LOCAL, 10175 bytes)
[2025-06-07T15:53:48.274+0000] {spark_submit.py:644} INFO - 25/06/07 15:53:48 INFO TaskSetManager: Starting task 0.0 in stage 3.0 (TID 4) (172.19.0.7, executor 0, partition 0, PROCESS_LOCAL, 10175 bytes)
[2025-06-07T15:53:48.274+0000] {spark_submit.py:644} INFO - 25/06/07 15:53:48 INFO TaskSetManager: Starting task 1.0 in stage 3.0 (TID 5) (172.19.0.7, executor 0, partition 1, PROCESS_LOCAL, 10175 bytes)
[2025-06-07T15:53:48.289+0000] {spark_submit.py:644} INFO - 25/06/07 15:53:48 INFO BlockManagerInfo: Added broadcast_5_piece0 in memory on 172.19.0.7:37165 (size: 138.2 KiB, free: 1048.6 MiB)
[2025-06-07T15:53:48.465+0000] {spark_submit.py:644} INFO - 25/06/07 15:53:48 INFO MapOutputTrackerMasterEndpoint: Asked to send map output locations for shuffle 0 to 172.19.0.7:38856
[2025-06-07T15:53:48.922+0000] {spark_submit.py:644} INFO - 25/06/07 15:53:48 INFO BlockManagerInfo: Added rdd_14_1 in memory on 172.19.0.7:37165 (size: 46.0 B, free: 1048.6 MiB)
[2025-06-07T15:53:48.923+0000] {spark_submit.py:644} INFO - 25/06/07 15:53:48 INFO BlockManagerInfo: Added rdd_14_0 in memory on 172.19.0.7:37165 (size: 46.0 B, free: 1048.6 MiB)
[2025-06-07T15:53:48.923+0000] {spark_submit.py:644} INFO - 25/06/07 15:53:48 INFO BlockManagerInfo: Added rdd_14_12 in memory on 172.19.0.7:37165 (size: 799.0 B, free: 1048.6 MiB)
[2025-06-07T15:53:48.925+0000] {spark_submit.py:644} INFO - 25/06/07 15:53:48 INFO BlockManagerInfo: Added rdd_14_42 in memory on 172.19.0.7:37165 (size: 724.0 B, free: 1048.6 MiB)
[2025-06-07T15:53:49.284+0000] {spark_submit.py:644} INFO - 25/06/07 15:53:49 INFO TaskSetManager: Starting task 2.0 in stage 3.0 (TID 6) (172.19.0.7, executor 0, partition 2, PROCESS_LOCAL, 10175 bytes)
[2025-06-07T15:53:49.285+0000] {spark_submit.py:644} INFO - 25/06/07 15:53:49 INFO TaskSetManager: Finished task 42.0 in stage 3.0 (TID 3) in 1011 ms on 172.19.0.7 (executor 0) (1/50)
[2025-06-07T15:53:49.286+0000] {spark_submit.py:644} INFO - 25/06/07 15:53:49 INFO TaskSetManager: Starting task 3.0 in stage 3.0 (TID 7) (172.19.0.7, executor 0, partition 3, PROCESS_LOCAL, 10175 bytes)
[2025-06-07T15:53:49.286+0000] {spark_submit.py:644} INFO - 25/06/07 15:53:49 INFO TaskSetManager: Starting task 4.0 in stage 3.0 (TID 8) (172.19.0.7, executor 0, partition 4, PROCESS_LOCAL, 10175 bytes)
[2025-06-07T15:53:49.287+0000] {spark_submit.py:644} INFO - 25/06/07 15:53:49 INFO TaskSetManager: Starting task 5.0 in stage 3.0 (TID 9) (172.19.0.7, executor 0, partition 5, PROCESS_LOCAL, 10175 bytes)
[2025-06-07T15:53:49.289+0000] {spark_submit.py:644} INFO - 25/06/07 15:53:49 INFO TaskSetManager: Finished task 0.0 in stage 3.0 (TID 4) in 1012 ms on 172.19.0.7 (executor 0) (2/50)
[2025-06-07T15:53:49.290+0000] {spark_submit.py:644} INFO - 25/06/07 15:53:49 INFO TaskSetManager: Finished task 1.0 in stage 3.0 (TID 5) in 1015 ms on 172.19.0.7 (executor 0) (3/50)
[2025-06-07T15:53:49.290+0000] {spark_submit.py:644} INFO - 25/06/07 15:53:49 INFO TaskSetManager: Finished task 12.0 in stage 3.0 (TID 2) in 1017 ms on 172.19.0.7 (executor 0) (4/50)
[2025-06-07T15:53:49.395+0000] {spark_submit.py:644} INFO - 25/06/07 15:53:49 INFO BlockManagerInfo: Added rdd_14_2 in memory on 172.19.0.7:37165 (size: 46.0 B, free: 1048.6 MiB)
[2025-06-07T15:53:49.405+0000] {spark_submit.py:644} INFO - 25/06/07 15:53:49 INFO BlockManagerInfo: Added rdd_14_4 in memory on 172.19.0.7:37165 (size: 46.0 B, free: 1048.6 MiB)
[2025-06-07T15:53:49.407+0000] {spark_submit.py:644} INFO - 25/06/07 15:53:49 INFO BlockManagerInfo: Added rdd_14_5 in memory on 172.19.0.7:37165 (size: 46.0 B, free: 1048.6 MiB)
[2025-06-07T15:53:49.411+0000] {spark_submit.py:644} INFO - 25/06/07 15:53:49 INFO BlockManagerInfo: Added rdd_14_3 in memory on 172.19.0.7:37165 (size: 46.0 B, free: 1048.6 MiB)
[2025-06-07T15:53:49.439+0000] {spark_submit.py:644} INFO - 25/06/07 15:53:49 INFO TaskSetManager: Starting task 6.0 in stage 3.0 (TID 10) (172.19.0.7, executor 0, partition 6, PROCESS_LOCAL, 10175 bytes)
[2025-06-07T15:53:49.440+0000] {spark_submit.py:644} INFO - 25/06/07 15:53:49 INFO TaskSetManager: Finished task 2.0 in stage 3.0 (TID 6) in 157 ms on 172.19.0.7 (executor 0) (5/50)
[2025-06-07T15:53:49.445+0000] {spark_submit.py:644} INFO - 25/06/07 15:53:49 INFO TaskSetManager: Starting task 7.0 in stage 3.0 (TID 11) (172.19.0.7, executor 0, partition 7, PROCESS_LOCAL, 10175 bytes)
[2025-06-07T15:53:49.445+0000] {spark_submit.py:644} INFO - 25/06/07 15:53:49 INFO TaskSetManager: Finished task 4.0 in stage 3.0 (TID 8) in 159 ms on 172.19.0.7 (executor 0) (6/50)
[2025-06-07T15:53:49.446+0000] {spark_submit.py:644} INFO - 25/06/07 15:53:49 INFO TaskSetManager: Finished task 3.0 in stage 3.0 (TID 7) in 161 ms on 172.19.0.7 (executor 0) (7/50)
[2025-06-07T15:53:49.447+0000] {spark_submit.py:644} INFO - 25/06/07 15:53:49 INFO TaskSetManager: Starting task 8.0 in stage 3.0 (TID 12) (172.19.0.7, executor 0, partition 8, PROCESS_LOCAL, 10175 bytes)
[2025-06-07T15:53:49.449+0000] {spark_submit.py:644} INFO - 25/06/07 15:53:49 INFO TaskSetManager: Starting task 9.0 in stage 3.0 (TID 13) (172.19.0.7, executor 0, partition 9, PROCESS_LOCAL, 10175 bytes)
[2025-06-07T15:53:49.450+0000] {spark_submit.py:644} INFO - 25/06/07 15:53:49 INFO TaskSetManager: Finished task 5.0 in stage 3.0 (TID 9) in 164 ms on 172.19.0.7 (executor 0) (8/50)
[2025-06-07T15:53:49.492+0000] {spark_submit.py:644} INFO - 25/06/07 15:53:49 INFO BlockManagerInfo: Added rdd_14_6 in memory on 172.19.0.7:37165 (size: 46.0 B, free: 1048.6 MiB)
[2025-06-07T15:53:49.508+0000] {spark_submit.py:644} INFO - 25/06/07 15:53:49 INFO BlockManagerInfo: Added rdd_14_8 in memory on 172.19.0.7:37165 (size: 46.0 B, free: 1048.6 MiB)
[2025-06-07T15:53:49.515+0000] {spark_submit.py:644} INFO - 25/06/07 15:53:49 INFO BlockManagerInfo: Added rdd_14_7 in memory on 172.19.0.7:37165 (size: 46.0 B, free: 1048.6 MiB)
[2025-06-07T15:53:49.519+0000] {spark_submit.py:644} INFO - 25/06/07 15:53:49 INFO BlockManagerInfo: Added rdd_14_9 in memory on 172.19.0.7:37165 (size: 46.0 B, free: 1048.6 MiB)
[2025-06-07T15:53:49.522+0000] {spark_submit.py:644} INFO - 25/06/07 15:53:49 INFO TaskSetManager: Starting task 10.0 in stage 3.0 (TID 14) (172.19.0.7, executor 0, partition 10, PROCESS_LOCAL, 10175 bytes)
[2025-06-07T15:53:49.522+0000] {spark_submit.py:644} INFO - 25/06/07 15:53:49 INFO TaskSetManager: Finished task 6.0 in stage 3.0 (TID 10) in 83 ms on 172.19.0.7 (executor 0) (9/50)
[2025-06-07T15:53:49.533+0000] {spark_submit.py:644} INFO - 25/06/07 15:53:49 INFO TaskSetManager: Starting task 11.0 in stage 3.0 (TID 15) (172.19.0.7, executor 0, partition 11, PROCESS_LOCAL, 10175 bytes)
[2025-06-07T15:53:49.534+0000] {spark_submit.py:644} INFO - 25/06/07 15:53:49 INFO TaskSetManager: Finished task 8.0 in stage 3.0 (TID 12) in 87 ms on 172.19.0.7 (executor 0) (10/50)
[2025-06-07T15:53:49.538+0000] {spark_submit.py:644} INFO - 25/06/07 15:53:49 INFO TaskSetManager: Starting task 13.0 in stage 3.0 (TID 16) (172.19.0.7, executor 0, partition 13, PROCESS_LOCAL, 10175 bytes)
[2025-06-07T15:53:49.539+0000] {spark_submit.py:644} INFO - 25/06/07 15:53:49 INFO TaskSetManager: Finished task 7.0 in stage 3.0 (TID 11) in 95 ms on 172.19.0.7 (executor 0) (11/50)
[2025-06-07T15:53:49.542+0000] {spark_submit.py:644} INFO - 25/06/07 15:53:49 INFO TaskSetManager: Starting task 14.0 in stage 3.0 (TID 17) (172.19.0.7, executor 0, partition 14, PROCESS_LOCAL, 10175 bytes)
[2025-06-07T15:53:49.543+0000] {spark_submit.py:644} INFO - 25/06/07 15:53:49 INFO TaskSetManager: Finished task 9.0 in stage 3.0 (TID 13) in 95 ms on 172.19.0.7 (executor 0) (12/50)
[2025-06-07T15:53:49.569+0000] {spark_submit.py:644} INFO - 25/06/07 15:53:49 INFO BlockManagerInfo: Added rdd_14_10 in memory on 172.19.0.7:37165 (size: 46.0 B, free: 1048.6 MiB)
[2025-06-07T15:53:49.582+0000] {spark_submit.py:644} INFO - 25/06/07 15:53:49 INFO BlockManagerInfo: Added rdd_14_11 in memory on 172.19.0.7:37165 (size: 46.0 B, free: 1048.6 MiB)
[2025-06-07T15:53:49.585+0000] {spark_submit.py:644} INFO - 25/06/07 15:53:49 INFO BlockManagerInfo: Added rdd_14_13 in memory on 172.19.0.7:37165 (size: 46.0 B, free: 1048.6 MiB)
[2025-06-07T15:53:49.590+0000] {spark_submit.py:644} INFO - 25/06/07 15:53:49 INFO BlockManagerInfo: Added rdd_14_14 in memory on 172.19.0.7:37165 (size: 46.0 B, free: 1048.6 MiB)
[2025-06-07T15:53:49.599+0000] {spark_submit.py:644} INFO - 25/06/07 15:53:49 INFO TaskSetManager: Starting task 15.0 in stage 3.0 (TID 18) (172.19.0.7, executor 0, partition 15, PROCESS_LOCAL, 10175 bytes)
[2025-06-07T15:53:49.600+0000] {spark_submit.py:644} INFO - 25/06/07 15:53:49 INFO TaskSetManager: Finished task 10.0 in stage 3.0 (TID 14) in 78 ms on 172.19.0.7 (executor 0) (13/50)
[2025-06-07T15:53:49.606+0000] {spark_submit.py:644} INFO - 25/06/07 15:53:49 INFO TaskSetManager: Starting task 16.0 in stage 3.0 (TID 19) (172.19.0.7, executor 0, partition 16, PROCESS_LOCAL, 10175 bytes)
[2025-06-07T15:53:49.607+0000] {spark_submit.py:644} INFO - 25/06/07 15:53:49 INFO TaskSetManager: Finished task 11.0 in stage 3.0 (TID 15) in 74 ms on 172.19.0.7 (executor 0) (14/50)
[2025-06-07T15:53:49.608+0000] {spark_submit.py:644} INFO - 25/06/07 15:53:49 INFO TaskSetManager: Starting task 17.0 in stage 3.0 (TID 20) (172.19.0.7, executor 0, partition 17, PROCESS_LOCAL, 10175 bytes)
[2025-06-07T15:53:49.610+0000] {spark_submit.py:644} INFO - 25/06/07 15:53:49 INFO TaskSetManager: Finished task 13.0 in stage 3.0 (TID 16) in 71 ms on 172.19.0.7 (executor 0) (15/50)
[2025-06-07T15:53:49.613+0000] {spark_submit.py:644} INFO - 25/06/07 15:53:49 INFO TaskSetManager: Starting task 18.0 in stage 3.0 (TID 21) (172.19.0.7, executor 0, partition 18, PROCESS_LOCAL, 10175 bytes)
[2025-06-07T15:53:49.615+0000] {spark_submit.py:644} INFO - 25/06/07 15:53:49 INFO TaskSetManager: Finished task 14.0 in stage 3.0 (TID 17) in 71 ms on 172.19.0.7 (executor 0) (16/50)
[2025-06-07T15:53:49.655+0000] {spark_submit.py:644} INFO - 25/06/07 15:53:49 INFO BlockManagerInfo: Added rdd_14_15 in memory on 172.19.0.7:37165 (size: 46.0 B, free: 1048.6 MiB)
[2025-06-07T15:53:49.677+0000] {spark_submit.py:644} INFO - 25/06/07 15:53:49 INFO BlockManagerInfo: Added rdd_14_17 in memory on 172.19.0.7:37165 (size: 46.0 B, free: 1048.6 MiB)
[2025-06-07T15:53:49.679+0000] {spark_submit.py:644} INFO - 25/06/07 15:53:49 INFO BlockManagerInfo: Added rdd_14_18 in memory on 172.19.0.7:37165 (size: 46.0 B, free: 1048.6 MiB)
[2025-06-07T15:53:49.681+0000] {spark_submit.py:644} INFO - 25/06/07 15:53:49 INFO BlockManagerInfo: Added rdd_14_16 in memory on 172.19.0.7:37165 (size: 46.0 B, free: 1048.6 MiB)
[2025-06-07T15:53:49.682+0000] {spark_submit.py:644} INFO - 25/06/07 15:53:49 INFO TaskSetManager: Starting task 19.0 in stage 3.0 (TID 22) (172.19.0.7, executor 0, partition 19, PROCESS_LOCAL, 10175 bytes)
[2025-06-07T15:53:49.683+0000] {spark_submit.py:644} INFO - 25/06/07 15:53:49 INFO TaskSetManager: Finished task 15.0 in stage 3.0 (TID 18) in 84 ms on 172.19.0.7 (executor 0) (17/50)
[2025-06-07T15:53:49.701+0000] {spark_submit.py:644} INFO - 25/06/07 15:53:49 INFO TaskSetManager: Starting task 20.0 in stage 3.0 (TID 23) (172.19.0.7, executor 0, partition 20, PROCESS_LOCAL, 10175 bytes)
[2025-06-07T15:53:49.703+0000] {spark_submit.py:644} INFO - 25/06/07 15:53:49 INFO TaskSetManager: Finished task 18.0 in stage 3.0 (TID 21) in 90 ms on 172.19.0.7 (executor 0) (18/50)
[2025-06-07T15:53:49.706+0000] {spark_submit.py:644} INFO - 25/06/07 15:53:49 INFO TaskSetManager: Starting task 21.0 in stage 3.0 (TID 24) (172.19.0.7, executor 0, partition 21, PROCESS_LOCAL, 10175 bytes)
[2025-06-07T15:53:49.707+0000] {spark_submit.py:644} INFO - 25/06/07 15:53:49 INFO TaskSetManager: Finished task 16.0 in stage 3.0 (TID 19) in 98 ms on 172.19.0.7 (executor 0) (19/50)
[2025-06-07T15:53:49.709+0000] {spark_submit.py:644} INFO - 25/06/07 15:53:49 INFO TaskSetManager: Starting task 22.0 in stage 3.0 (TID 25) (172.19.0.7, executor 0, partition 22, PROCESS_LOCAL, 10175 bytes)
[2025-06-07T15:53:49.710+0000] {spark_submit.py:644} INFO - 25/06/07 15:53:49 INFO TaskSetManager: Finished task 17.0 in stage 3.0 (TID 20) in 100 ms on 172.19.0.7 (executor 0) (20/50)
[2025-06-07T15:53:49.726+0000] {spark_submit.py:644} INFO - 25/06/07 15:53:49 INFO BlockManagerInfo: Added rdd_14_19 in memory on 172.19.0.7:37165 (size: 46.0 B, free: 1048.6 MiB)
[2025-06-07T15:53:49.752+0000] {spark_submit.py:644} INFO - 25/06/07 15:53:49 INFO TaskSetManager: Starting task 23.0 in stage 3.0 (TID 26) (172.19.0.7, executor 0, partition 23, PROCESS_LOCAL, 10175 bytes)
[2025-06-07T15:53:49.753+0000] {spark_submit.py:644} INFO - 25/06/07 15:53:49 INFO TaskSetManager: Finished task 19.0 in stage 3.0 (TID 22) in 71 ms on 172.19.0.7 (executor 0) (21/50)
[2025-06-07T15:53:49.768+0000] {spark_submit.py:644} INFO - 25/06/07 15:53:49 INFO BlockManagerInfo: Added rdd_14_21 in memory on 172.19.0.7:37165 (size: 46.0 B, free: 1048.6 MiB)
[2025-06-07T15:53:49.768+0000] {spark_submit.py:644} INFO - 25/06/07 15:53:49 INFO BlockManagerInfo: Added rdd_14_20 in memory on 172.19.0.7:37165 (size: 46.0 B, free: 1048.6 MiB)
[2025-06-07T15:53:49.768+0000] {spark_submit.py:644} INFO - 25/06/07 15:53:49 INFO BlockManagerInfo: Added rdd_14_22 in memory on 172.19.0.7:37165 (size: 46.0 B, free: 1048.6 MiB)
[2025-06-07T15:53:49.789+0000] {spark_submit.py:644} INFO - 25/06/07 15:53:49 INFO TaskSetManager: Starting task 24.0 in stage 3.0 (TID 27) (172.19.0.7, executor 0, partition 24, PROCESS_LOCAL, 10175 bytes)
[2025-06-07T15:53:49.790+0000] {spark_submit.py:644} INFO - 25/06/07 15:53:49 INFO TaskSetManager: Starting task 25.0 in stage 3.0 (TID 28) (172.19.0.7, executor 0, partition 25, PROCESS_LOCAL, 10175 bytes)
[2025-06-07T15:53:49.791+0000] {spark_submit.py:644} INFO - 25/06/07 15:53:49 INFO TaskSetManager: Finished task 20.0 in stage 3.0 (TID 23) in 90 ms on 172.19.0.7 (executor 0) (22/50)
[2025-06-07T15:53:49.794+0000] {spark_submit.py:644} INFO - 25/06/07 15:53:49 INFO TaskSetManager: Finished task 22.0 in stage 3.0 (TID 25) in 84 ms on 172.19.0.7 (executor 0) (23/50)
[2025-06-07T15:53:49.795+0000] {spark_submit.py:644} INFO - 25/06/07 15:53:49 INFO TaskSetManager: Starting task 26.0 in stage 3.0 (TID 29) (172.19.0.7, executor 0, partition 26, PROCESS_LOCAL, 10175 bytes)
[2025-06-07T15:53:49.796+0000] {spark_submit.py:644} INFO - 25/06/07 15:53:49 INFO TaskSetManager: Finished task 21.0 in stage 3.0 (TID 24) in 89 ms on 172.19.0.7 (executor 0) (24/50)
[2025-06-07T15:53:49.796+0000] {spark_submit.py:644} INFO - 25/06/07 15:53:49 INFO BlockManagerInfo: Added rdd_14_23 in memory on 172.19.0.7:37165 (size: 46.0 B, free: 1048.6 MiB)
[2025-06-07T15:53:49.810+0000] {spark_submit.py:644} INFO - 25/06/07 15:53:49 INFO TaskSetManager: Starting task 27.0 in stage 3.0 (TID 30) (172.19.0.7, executor 0, partition 27, PROCESS_LOCAL, 10175 bytes)
[2025-06-07T15:53:49.811+0000] {spark_submit.py:644} INFO - 25/06/07 15:53:49 INFO TaskSetManager: Finished task 23.0 in stage 3.0 (TID 26) in 59 ms on 172.19.0.7 (executor 0) (25/50)
[2025-06-07T15:53:49.833+0000] {spark_submit.py:644} INFO - 25/06/07 15:53:49 INFO BlockManagerInfo: Added rdd_14_25 in memory on 172.19.0.7:37165 (size: 46.0 B, free: 1048.6 MiB)
[2025-06-07T15:53:49.845+0000] {spark_submit.py:644} INFO - 25/06/07 15:53:49 INFO BlockManagerInfo: Added rdd_14_24 in memory on 172.19.0.7:37165 (size: 46.0 B, free: 1048.6 MiB)
[2025-06-07T15:53:49.848+0000] {spark_submit.py:644} INFO - 25/06/07 15:53:49 INFO BlockManagerInfo: Added rdd_14_26 in memory on 172.19.0.7:37165 (size: 46.0 B, free: 1048.6 MiB)
[2025-06-07T15:53:49.849+0000] {spark_submit.py:644} INFO - 25/06/07 15:53:49 INFO BlockManagerInfo: Added rdd_14_27 in memory on 172.19.0.7:37165 (size: 46.0 B, free: 1048.6 MiB)
[2025-06-07T15:53:49.851+0000] {spark_submit.py:644} INFO - 25/06/07 15:53:49 INFO TaskSetManager: Starting task 28.0 in stage 3.0 (TID 31) (172.19.0.7, executor 0, partition 28, PROCESS_LOCAL, 10175 bytes)
[2025-06-07T15:53:49.852+0000] {spark_submit.py:644} INFO - 25/06/07 15:53:49 INFO TaskSetManager: Finished task 25.0 in stage 3.0 (TID 28) in 62 ms on 172.19.0.7 (executor 0) (26/50)
[2025-06-07T15:53:49.863+0000] {spark_submit.py:644} INFO - 25/06/07 15:53:49 INFO TaskSetManager: Starting task 29.0 in stage 3.0 (TID 32) (172.19.0.7, executor 0, partition 29, PROCESS_LOCAL, 10175 bytes)
[2025-06-07T15:53:49.864+0000] {spark_submit.py:644} INFO - 25/06/07 15:53:49 INFO TaskSetManager: Starting task 30.0 in stage 3.0 (TID 33) (172.19.0.7, executor 0, partition 30, PROCESS_LOCAL, 10175 bytes)
[2025-06-07T15:53:49.865+0000] {spark_submit.py:644} INFO - 25/06/07 15:53:49 INFO TaskSetManager: Finished task 24.0 in stage 3.0 (TID 27) in 75 ms on 172.19.0.7 (executor 0) (27/50)
[2025-06-07T15:53:49.867+0000] {spark_submit.py:644} INFO - 25/06/07 15:53:49 INFO TaskSetManager: Finished task 26.0 in stage 3.0 (TID 29) in 73 ms on 172.19.0.7 (executor 0) (28/50)
[2025-06-07T15:53:49.868+0000] {spark_submit.py:644} INFO - 25/06/07 15:53:49 INFO TaskSetManager: Starting task 31.0 in stage 3.0 (TID 34) (172.19.0.7, executor 0, partition 31, PROCESS_LOCAL, 10175 bytes)
[2025-06-07T15:53:49.868+0000] {spark_submit.py:644} INFO - 25/06/07 15:53:49 INFO TaskSetManager: Finished task 27.0 in stage 3.0 (TID 30) in 58 ms on 172.19.0.7 (executor 0) (29/50)
[2025-06-07T15:53:49.879+0000] {spark_submit.py:644} INFO - 25/06/07 15:53:49 INFO BlockManagerInfo: Added rdd_14_28 in memory on 172.19.0.7:37165 (size: 46.0 B, free: 1048.6 MiB)
[2025-06-07T15:53:49.896+0000] {spark_submit.py:644} INFO - 25/06/07 15:53:49 INFO TaskSetManager: Starting task 32.0 in stage 3.0 (TID 35) (172.19.0.7, executor 0, partition 32, PROCESS_LOCAL, 10175 bytes)
[2025-06-07T15:53:49.897+0000] {spark_submit.py:644} INFO - 25/06/07 15:53:49 INFO TaskSetManager: Finished task 28.0 in stage 3.0 (TID 31) in 45 ms on 172.19.0.7 (executor 0) (30/50)
[2025-06-07T15:53:49.907+0000] {spark_submit.py:644} INFO - 25/06/07 15:53:49 INFO BlockManagerInfo: Added rdd_14_30 in memory on 172.19.0.7:37165 (size: 46.0 B, free: 1048.6 MiB)
[2025-06-07T15:53:49.908+0000] {spark_submit.py:644} INFO - 25/06/07 15:53:49 INFO BlockManagerInfo: Added rdd_14_31 in memory on 172.19.0.7:37165 (size: 46.0 B, free: 1048.6 MiB)
[2025-06-07T15:53:49.909+0000] {spark_submit.py:644} INFO - 25/06/07 15:53:49 INFO BlockManagerInfo: Added rdd_14_29 in memory on 172.19.0.7:37165 (size: 46.0 B, free: 1048.6 MiB)
[2025-06-07T15:53:49.925+0000] {spark_submit.py:644} INFO - 25/06/07 15:53:49 INFO TaskSetManager: Starting task 33.0 in stage 3.0 (TID 36) (172.19.0.7, executor 0, partition 33, PROCESS_LOCAL, 10175 bytes)
[2025-06-07T15:53:49.925+0000] {spark_submit.py:644} INFO - 25/06/07 15:53:49 INFO TaskSetManager: Finished task 31.0 in stage 3.0 (TID 34) in 59 ms on 172.19.0.7 (executor 0) (31/50)
[2025-06-07T15:53:49.926+0000] {spark_submit.py:644} INFO - 25/06/07 15:53:49 INFO TaskSetManager: Starting task 34.0 in stage 3.0 (TID 37) (172.19.0.7, executor 0, partition 34, PROCESS_LOCAL, 10175 bytes)
[2025-06-07T15:53:49.927+0000] {spark_submit.py:644} INFO - 25/06/07 15:53:49 INFO TaskSetManager: Starting task 35.0 in stage 3.0 (TID 38) (172.19.0.7, executor 0, partition 35, PROCESS_LOCAL, 10175 bytes)
[2025-06-07T15:53:49.929+0000] {spark_submit.py:644} INFO - 25/06/07 15:53:49 INFO TaskSetManager: Finished task 29.0 in stage 3.0 (TID 32) in 65 ms on 172.19.0.7 (executor 0) (32/50)
[2025-06-07T15:53:49.929+0000] {spark_submit.py:644} INFO - 25/06/07 15:53:49 INFO TaskSetManager: Finished task 30.0 in stage 3.0 (TID 33) in 64 ms on 172.19.0.7 (executor 0) (33/50)
[2025-06-07T15:53:49.933+0000] {spark_submit.py:644} INFO - 25/06/07 15:53:49 INFO BlockManagerInfo: Added rdd_14_32 in memory on 172.19.0.7:37165 (size: 46.0 B, free: 1048.6 MiB)
[2025-06-07T15:53:49.947+0000] {spark_submit.py:644} INFO - 25/06/07 15:53:49 INFO TaskSetManager: Starting task 36.0 in stage 3.0 (TID 39) (172.19.0.7, executor 0, partition 36, PROCESS_LOCAL, 10175 bytes)
[2025-06-07T15:53:49.947+0000] {spark_submit.py:644} INFO - 25/06/07 15:53:49 INFO TaskSetManager: Finished task 32.0 in stage 3.0 (TID 35) in 52 ms on 172.19.0.7 (executor 0) (34/50)
[2025-06-07T15:53:49.953+0000] {spark_submit.py:644} INFO - 25/06/07 15:53:49 INFO BlockManagerInfo: Added rdd_14_33 in memory on 172.19.0.7:37165 (size: 46.0 B, free: 1048.6 MiB)
[2025-06-07T15:53:49.964+0000] {spark_submit.py:644} INFO - 25/06/07 15:53:49 INFO BlockManagerInfo: Added rdd_14_34 in memory on 172.19.0.7:37165 (size: 46.0 B, free: 1048.6 MiB)
[2025-06-07T15:53:49.965+0000] {spark_submit.py:644} INFO - 25/06/07 15:53:49 INFO BlockManagerInfo: Added rdd_14_35 in memory on 172.19.0.7:37165 (size: 46.0 B, free: 1048.6 MiB)
[2025-06-07T15:53:49.970+0000] {spark_submit.py:644} INFO - 25/06/07 15:53:49 INFO TaskSetManager: Starting task 37.0 in stage 3.0 (TID 40) (172.19.0.7, executor 0, partition 37, PROCESS_LOCAL, 10175 bytes)
[2025-06-07T15:53:49.972+0000] {spark_submit.py:644} INFO - 25/06/07 15:53:49 INFO TaskSetManager: Finished task 33.0 in stage 3.0 (TID 36) in 47 ms on 172.19.0.7 (executor 0) (35/50)
[2025-06-07T15:53:49.978+0000] {spark_submit.py:644} INFO - 25/06/07 15:53:49 INFO BlockManagerInfo: Added rdd_14_36 in memory on 172.19.0.7:37165 (size: 46.0 B, free: 1048.6 MiB)
[2025-06-07T15:53:49.986+0000] {spark_submit.py:644} INFO - 25/06/07 15:53:49 INFO TaskSetManager: Starting task 38.0 in stage 3.0 (TID 41) (172.19.0.7, executor 0, partition 38, PROCESS_LOCAL, 10175 bytes)
[2025-06-07T15:53:49.988+0000] {spark_submit.py:644} INFO - 25/06/07 15:53:49 INFO TaskSetManager: Finished task 35.0 in stage 3.0 (TID 38) in 60 ms on 172.19.0.7 (executor 0) (36/50)
[2025-06-07T15:53:49.989+0000] {spark_submit.py:644} INFO - 25/06/07 15:53:49 INFO TaskSetManager: Finished task 34.0 in stage 3.0 (TID 37) in 61 ms on 172.19.0.7 (executor 0) (37/50)
[2025-06-07T15:53:49.989+0000] {spark_submit.py:644} INFO - 25/06/07 15:53:49 INFO TaskSetManager: Starting task 39.0 in stage 3.0 (TID 42) (172.19.0.7, executor 0, partition 39, PROCESS_LOCAL, 10175 bytes)
[2025-06-07T15:53:49.992+0000] {spark_submit.py:644} INFO - 25/06/07 15:53:49 INFO TaskSetManager: Starting task 40.0 in stage 3.0 (TID 43) (172.19.0.7, executor 0, partition 40, PROCESS_LOCAL, 10175 bytes)
[2025-06-07T15:53:49.993+0000] {spark_submit.py:644} INFO - 25/06/07 15:53:49 INFO TaskSetManager: Finished task 36.0 in stage 3.0 (TID 39) in 46 ms on 172.19.0.7 (executor 0) (38/50)
[2025-06-07T15:53:50.000+0000] {spark_submit.py:644} INFO - 25/06/07 15:53:50 INFO BlockManagerInfo: Added rdd_14_37 in memory on 172.19.0.7:37165 (size: 46.0 B, free: 1048.6 MiB)
[2025-06-07T15:53:50.015+0000] {spark_submit.py:644} INFO - 25/06/07 15:53:50 INFO TaskSetManager: Starting task 41.0 in stage 3.0 (TID 44) (172.19.0.7, executor 0, partition 41, PROCESS_LOCAL, 10175 bytes)
[2025-06-07T15:53:50.016+0000] {spark_submit.py:644} INFO - 25/06/07 15:53:50 INFO TaskSetManager: Finished task 37.0 in stage 3.0 (TID 40) in 45 ms on 172.19.0.7 (executor 0) (39/50)
[2025-06-07T15:53:50.027+0000] {spark_submit.py:644} INFO - 25/06/07 15:53:50 INFO BlockManagerInfo: Added rdd_14_38 in memory on 172.19.0.7:37165 (size: 46.0 B, free: 1048.6 MiB)
[2025-06-07T15:53:50.031+0000] {spark_submit.py:644} INFO - 25/06/07 15:53:50 INFO BlockManagerInfo: Added rdd_14_40 in memory on 172.19.0.7:37165 (size: 46.0 B, free: 1048.6 MiB)
[2025-06-07T15:53:50.032+0000] {spark_submit.py:644} INFO - 25/06/07 15:53:50 INFO BlockManagerInfo: Added rdd_14_39 in memory on 172.19.0.7:37165 (size: 46.0 B, free: 1048.6 MiB)
[2025-06-07T15:53:50.041+0000] {spark_submit.py:644} INFO - 25/06/07 15:53:50 INFO TaskSetManager: Starting task 43.0 in stage 3.0 (TID 45) (172.19.0.7, executor 0, partition 43, PROCESS_LOCAL, 10175 bytes)
[2025-06-07T15:53:50.042+0000] {spark_submit.py:644} INFO - 25/06/07 15:53:50 INFO TaskSetManager: Finished task 38.0 in stage 3.0 (TID 41) in 56 ms on 172.19.0.7 (executor 0) (40/50)
[2025-06-07T15:53:50.043+0000] {spark_submit.py:644} INFO - 25/06/07 15:53:50 INFO BlockManagerInfo: Added rdd_14_41 in memory on 172.19.0.7:37165 (size: 46.0 B, free: 1048.6 MiB)
[2025-06-07T15:53:50.045+0000] {spark_submit.py:644} INFO - 25/06/07 15:53:50 INFO TaskSetManager: Starting task 44.0 in stage 3.0 (TID 46) (172.19.0.7, executor 0, partition 44, PROCESS_LOCAL, 10175 bytes)
[2025-06-07T15:53:50.046+0000] {spark_submit.py:644} INFO - 25/06/07 15:53:50 INFO TaskSetManager: Finished task 40.0 in stage 3.0 (TID 43) in 55 ms on 172.19.0.7 (executor 0) (41/50)
[2025-06-07T15:53:50.048+0000] {spark_submit.py:644} INFO - 25/06/07 15:53:50 INFO TaskSetManager: Starting task 45.0 in stage 3.0 (TID 47) (172.19.0.7, executor 0, partition 45, PROCESS_LOCAL, 10175 bytes)
[2025-06-07T15:53:50.048+0000] {spark_submit.py:644} INFO - 25/06/07 15:53:50 INFO TaskSetManager: Finished task 39.0 in stage 3.0 (TID 42) in 61 ms on 172.19.0.7 (executor 0) (42/50)
[2025-06-07T15:53:50.055+0000] {spark_submit.py:644} INFO - 25/06/07 15:53:50 INFO TaskSetManager: Starting task 46.0 in stage 3.0 (TID 48) (172.19.0.7, executor 0, partition 46, PROCESS_LOCAL, 10175 bytes)
[2025-06-07T15:53:50.056+0000] {spark_submit.py:644} INFO - 25/06/07 15:53:50 INFO TaskSetManager: Finished task 41.0 in stage 3.0 (TID 44) in 40 ms on 172.19.0.7 (executor 0) (43/50)
[2025-06-07T15:53:50.071+0000] {spark_submit.py:644} INFO - 25/06/07 15:53:50 INFO BlockManagerInfo: Added rdd_14_43 in memory on 172.19.0.7:37165 (size: 46.0 B, free: 1048.6 MiB)
[2025-06-07T15:53:50.077+0000] {spark_submit.py:644} INFO - 25/06/07 15:53:50 INFO BlockManagerInfo: Added rdd_14_44 in memory on 172.19.0.7:37165 (size: 46.0 B, free: 1048.6 MiB)
[2025-06-07T15:53:50.078+0000] {spark_submit.py:644} INFO - 25/06/07 15:53:50 INFO BlockManagerInfo: Added rdd_14_45 in memory on 172.19.0.7:37165 (size: 46.0 B, free: 1048.6 MiB)
[2025-06-07T15:53:50.082+0000] {spark_submit.py:644} INFO - 25/06/07 15:53:50 INFO BlockManagerInfo: Added rdd_14_46 in memory on 172.19.0.7:37165 (size: 46.0 B, free: 1048.6 MiB)
[2025-06-07T15:53:50.087+0000] {spark_submit.py:644} INFO - 25/06/07 15:53:50 INFO TaskSetManager: Starting task 47.0 in stage 3.0 (TID 49) (172.19.0.7, executor 0, partition 47, PROCESS_LOCAL, 10175 bytes)
[2025-06-07T15:53:50.088+0000] {spark_submit.py:644} INFO - 25/06/07 15:53:50 INFO TaskSetManager: Finished task 43.0 in stage 3.0 (TID 45) in 46 ms on 172.19.0.7 (executor 0) (44/50)
[2025-06-07T15:53:50.093+0000] {spark_submit.py:644} INFO - 25/06/07 15:53:50 INFO TaskSetManager: Starting task 48.0 in stage 3.0 (TID 50) (172.19.0.7, executor 0, partition 48, PROCESS_LOCAL, 10175 bytes)
[2025-06-07T15:53:50.093+0000] {spark_submit.py:644} INFO - 25/06/07 15:53:50 INFO TaskSetManager: Finished task 45.0 in stage 3.0 (TID 47) in 46 ms on 172.19.0.7 (executor 0) (45/50)
[2025-06-07T15:53:50.095+0000] {spark_submit.py:644} INFO - 25/06/07 15:53:50 INFO TaskSetManager: Starting task 49.0 in stage 3.0 (TID 51) (172.19.0.7, executor 0, partition 49, PROCESS_LOCAL, 10175 bytes)
[2025-06-07T15:53:50.095+0000] {spark_submit.py:644} INFO - 25/06/07 15:53:50 INFO TaskSetManager: Finished task 44.0 in stage 3.0 (TID 46) in 49 ms on 172.19.0.7 (executor 0) (46/50)
[2025-06-07T15:53:50.096+0000] {spark_submit.py:644} INFO - 25/06/07 15:53:50 INFO TaskSetManager: Finished task 46.0 in stage 3.0 (TID 48) in 41 ms on 172.19.0.7 (executor 0) (47/50)
[2025-06-07T15:53:50.109+0000] {spark_submit.py:644} INFO - 25/06/07 15:53:50 INFO BlockManagerInfo: Added rdd_14_47 in memory on 172.19.0.7:37165 (size: 46.0 B, free: 1048.6 MiB)
[2025-06-07T15:53:50.120+0000] {spark_submit.py:644} INFO - 25/06/07 15:53:50 INFO BlockManagerInfo: Added rdd_14_48 in memory on 172.19.0.7:37165 (size: 46.0 B, free: 1048.6 MiB)
[2025-06-07T15:53:50.120+0000] {spark_submit.py:644} INFO - 25/06/07 15:53:50 INFO TaskSetManager: Finished task 47.0 in stage 3.0 (TID 49) in 33 ms on 172.19.0.7 (executor 0) (48/50)
[2025-06-07T15:53:50.120+0000] {spark_submit.py:644} INFO - 25/06/07 15:53:50 INFO BlockManagerInfo: Added rdd_14_49 in memory on 172.19.0.7:37165 (size: 46.0 B, free: 1048.6 MiB)
[2025-06-07T15:53:50.132+0000] {spark_submit.py:644} INFO - 25/06/07 15:53:50 INFO TaskSetManager: Finished task 48.0 in stage 3.0 (TID 50) in 40 ms on 172.19.0.7 (executor 0) (49/50)
[2025-06-07T15:53:50.132+0000] {spark_submit.py:644} INFO - 25/06/07 15:53:50 INFO TaskSetManager: Finished task 49.0 in stage 3.0 (TID 51) in 38 ms on 172.19.0.7 (executor 0) (50/50)
[2025-06-07T15:53:50.133+0000] {spark_submit.py:644} INFO - 25/06/07 15:53:50 INFO TaskSchedulerImpl: Removed TaskSet 3.0, whose tasks have all completed, from pool
[2025-06-07T15:53:50.133+0000] {spark_submit.py:644} INFO - 25/06/07 15:53:50 INFO DAGScheduler: ShuffleMapStage 3 ($anonfun$recordDeltaOperationInternal$1 at DatabricksLogging.scala:128) finished in 1.879 s
[2025-06-07T15:53:50.133+0000] {spark_submit.py:644} INFO - 25/06/07 15:53:50 INFO DAGScheduler: looking for newly runnable stages
[2025-06-07T15:53:50.133+0000] {spark_submit.py:644} INFO - 25/06/07 15:53:50 INFO DAGScheduler: running: Set()
[2025-06-07T15:53:50.134+0000] {spark_submit.py:644} INFO - 25/06/07 15:53:50 INFO DAGScheduler: waiting: Set()
[2025-06-07T15:53:50.134+0000] {spark_submit.py:644} INFO - 25/06/07 15:53:50 INFO DAGScheduler: failed: Set()
[2025-06-07T15:53:50.146+0000] {spark_submit.py:644} INFO - 25/06/07 15:53:50 INFO SparkContext: Starting job: $anonfun$recordDeltaOperationInternal$1 at DatabricksLogging.scala:128
[2025-06-07T15:53:50.147+0000] {spark_submit.py:644} INFO - 25/06/07 15:53:50 INFO DAGScheduler: Got job 3 ($anonfun$recordDeltaOperationInternal$1 at DatabricksLogging.scala:128) with 1 output partitions
[2025-06-07T15:53:50.148+0000] {spark_submit.py:644} INFO - 25/06/07 15:53:50 INFO DAGScheduler: Final stage: ResultStage 6 ($anonfun$recordDeltaOperationInternal$1 at DatabricksLogging.scala:128)
[2025-06-07T15:53:50.148+0000] {spark_submit.py:644} INFO - 25/06/07 15:53:50 INFO DAGScheduler: Parents of final stage: List(ShuffleMapStage 5)
[2025-06-07T15:53:50.148+0000] {spark_submit.py:644} INFO - 25/06/07 15:53:50 INFO DAGScheduler: Missing parents: List()
[2025-06-07T15:53:50.148+0000] {spark_submit.py:644} INFO - 25/06/07 15:53:50 INFO DAGScheduler: Submitting ResultStage 6 (MapPartitionsRDD[20] at $anonfun$recordDeltaOperationInternal$1 at DatabricksLogging.scala:128), which has no missing parents
[2025-06-07T15:53:50.151+0000] {spark_submit.py:644} INFO - 25/06/07 15:53:50 INFO MemoryStore: Block broadcast_6 stored as values in memory (estimated size 533.9 KiB, free 432.7 MiB)
[2025-06-07T15:53:50.153+0000] {spark_submit.py:644} INFO - 25/06/07 15:53:50 INFO MemoryStore: Block broadcast_6_piece0 stored as bytes in memory (estimated size 124.5 KiB, free 432.6 MiB)
[2025-06-07T15:53:50.153+0000] {spark_submit.py:644} INFO - 25/06/07 15:53:50 INFO BlockManagerInfo: Added broadcast_6_piece0 in memory on b5e5641a3f5a:39641 (size: 124.5 KiB, free: 434.1 MiB)
[2025-06-07T15:53:50.153+0000] {spark_submit.py:644} INFO - 25/06/07 15:53:50 INFO SparkContext: Created broadcast 6 from broadcast at DAGScheduler.scala:1585
[2025-06-07T15:53:50.154+0000] {spark_submit.py:644} INFO - 25/06/07 15:53:50 INFO DAGScheduler: Submitting 1 missing tasks from ResultStage 6 (MapPartitionsRDD[20] at $anonfun$recordDeltaOperationInternal$1 at DatabricksLogging.scala:128) (first 15 tasks are for partitions Vector(0))
[2025-06-07T15:53:50.154+0000] {spark_submit.py:644} INFO - 25/06/07 15:53:50 INFO TaskSchedulerImpl: Adding task set 6.0 with 1 tasks resource profile 0
[2025-06-07T15:53:50.155+0000] {spark_submit.py:644} INFO - 25/06/07 15:53:50 INFO TaskSetManager: Starting task 0.0 in stage 6.0 (TID 52) (172.19.0.7, executor 0, partition 0, NODE_LOCAL, 10186 bytes)
[2025-06-07T15:53:50.162+0000] {spark_submit.py:644} INFO - 25/06/07 15:53:50 INFO BlockManagerInfo: Added broadcast_6_piece0 in memory on 172.19.0.7:37165 (size: 124.5 KiB, free: 1048.5 MiB)
[2025-06-07T15:53:50.168+0000] {spark_submit.py:644} INFO - 25/06/07 15:53:50 INFO MapOutputTrackerMasterEndpoint: Asked to send map output locations for shuffle 1 to 172.19.0.7:38856
[2025-06-07T15:53:50.201+0000] {spark_submit.py:644} INFO - 25/06/07 15:53:50 INFO TaskSetManager: Finished task 0.0 in stage 6.0 (TID 52) in 47 ms on 172.19.0.7 (executor 0) (1/1)
[2025-06-07T15:53:50.202+0000] {spark_submit.py:644} INFO - 25/06/07 15:53:50 INFO TaskSchedulerImpl: Removed TaskSet 6.0, whose tasks have all completed, from pool
[2025-06-07T15:53:50.202+0000] {spark_submit.py:644} INFO - 25/06/07 15:53:50 INFO DAGScheduler: ResultStage 6 ($anonfun$recordDeltaOperationInternal$1 at DatabricksLogging.scala:128) finished in 0.053 s
[2025-06-07T15:53:50.202+0000] {spark_submit.py:644} INFO - 25/06/07 15:53:50 INFO DAGScheduler: Job 3 is finished. Cancelling potential speculative or zombie tasks for this job
[2025-06-07T15:53:50.202+0000] {spark_submit.py:644} INFO - 25/06/07 15:53:50 INFO TaskSchedulerImpl: Killing all running tasks in stage 6: Stage finished
[2025-06-07T15:53:50.203+0000] {spark_submit.py:644} INFO - 25/06/07 15:53:50 INFO DAGScheduler: Job 3 finished: $anonfun$recordDeltaOperationInternal$1 at DatabricksLogging.scala:128, took 0.055501 s
[2025-06-07T15:53:50.225+0000] {spark_submit.py:644} INFO - 25/06/07 15:53:50 INFO CodeGenerator: Code generated in 17.414417 ms
[2025-06-07T15:53:50.227+0000] {spark_submit.py:644} INFO - 25/06/07 15:53:50 INFO Snapshot: [tableId=f55065e3-5b96-4330-a530-1eddc6979537] DELTA: Done
[2025-06-07T15:53:50.308+0000] {spark_submit.py:644} INFO - 25/06/07 15:53:50 INFO BlockManagerInfo: Removed broadcast_5_piece0 on b5e5641a3f5a:39641 in memory (size: 138.2 KiB, free: 434.2 MiB)
[2025-06-07T15:53:50.310+0000] {spark_submit.py:644} INFO - 25/06/07 15:53:50 INFO BlockManagerInfo: Removed broadcast_5_piece0 on 172.19.0.7:37165 in memory (size: 138.2 KiB, free: 1048.6 MiB)
[2025-06-07T15:53:50.314+0000] {spark_submit.py:644} INFO - 25/06/07 15:53:50 INFO BlockManagerInfo: Removed broadcast_6_piece0 on b5e5641a3f5a:39641 in memory (size: 124.5 KiB, free: 434.3 MiB)
[2025-06-07T15:53:50.315+0000] {spark_submit.py:644} INFO - 25/06/07 15:53:50 INFO BlockManagerInfo: Removed broadcast_6_piece0 on 172.19.0.7:37165 in memory (size: 124.5 KiB, free: 1048.8 MiB)
[2025-06-07T15:53:50.378+0000] {spark_submit.py:644} INFO - 25/06/07 15:53:50 INFO CodeGenerator: Code generated in 54.147417 ms
[2025-06-07T15:53:50.388+0000] {spark_submit.py:644} INFO - 25/06/07 15:53:50 INFO SparkContext: Starting job: $anonfun$recordDeltaOperationInternal$1 at DatabricksLogging.scala:128
[2025-06-07T15:53:50.389+0000] {spark_submit.py:644} INFO - 25/06/07 15:53:50 INFO DAGScheduler: Got job 4 ($anonfun$recordDeltaOperationInternal$1 at DatabricksLogging.scala:128) with 50 output partitions
[2025-06-07T15:53:50.390+0000] {spark_submit.py:644} INFO - 25/06/07 15:53:50 INFO DAGScheduler: Final stage: ResultStage 8 ($anonfun$recordDeltaOperationInternal$1 at DatabricksLogging.scala:128)
[2025-06-07T15:53:50.390+0000] {spark_submit.py:644} INFO - 25/06/07 15:53:50 INFO DAGScheduler: Parents of final stage: List(ShuffleMapStage 7)
[2025-06-07T15:53:50.390+0000] {spark_submit.py:644} INFO - 25/06/07 15:53:50 INFO DAGScheduler: Missing parents: List()
[2025-06-07T15:53:50.391+0000] {spark_submit.py:644} INFO - 25/06/07 15:53:50 INFO DAGScheduler: Submitting ResultStage 8 (MapPartitionsRDD[22] at $anonfun$recordDeltaOperationInternal$1 at DatabricksLogging.scala:128), which has no missing parents
[2025-06-07T15:53:50.394+0000] {spark_submit.py:644} INFO - 25/06/07 15:53:50 INFO MemoryStore: Block broadcast_7 stored as values in memory (estimated size 684.1 KiB, free 433.3 MiB)
[2025-06-07T15:53:50.396+0000] {spark_submit.py:644} INFO - 25/06/07 15:53:50 INFO MemoryStore: Block broadcast_7_piece0 stored as bytes in memory (estimated size 154.5 KiB, free 433.1 MiB)
[2025-06-07T15:53:50.396+0000] {spark_submit.py:644} INFO - 25/06/07 15:53:50 INFO BlockManagerInfo: Added broadcast_7_piece0 in memory on b5e5641a3f5a:39641 (size: 154.5 KiB, free: 434.2 MiB)
[2025-06-07T15:53:50.396+0000] {spark_submit.py:644} INFO - 25/06/07 15:53:50 INFO SparkContext: Created broadcast 7 from broadcast at DAGScheduler.scala:1585
[2025-06-07T15:53:50.397+0000] {spark_submit.py:644} INFO - 25/06/07 15:53:50 INFO DAGScheduler: Submitting 50 missing tasks from ResultStage 8 (MapPartitionsRDD[22] at $anonfun$recordDeltaOperationInternal$1 at DatabricksLogging.scala:128) (first 15 tasks are for partitions Vector(0, 1, 2, 3, 4, 5, 6, 7, 8, 9, 10, 11, 12, 13, 14))
[2025-06-07T15:53:50.397+0000] {spark_submit.py:644} INFO - 25/06/07 15:53:50 INFO TaskSchedulerImpl: Adding task set 8.0 with 50 tasks resource profile 0
[2025-06-07T15:53:50.398+0000] {spark_submit.py:644} INFO - 25/06/07 15:53:50 INFO TaskSetManager: Starting task 0.0 in stage 8.0 (TID 53) (172.19.0.7, executor 0, partition 0, PROCESS_LOCAL, 10186 bytes)
[2025-06-07T15:53:50.399+0000] {spark_submit.py:644} INFO - 25/06/07 15:53:50 INFO TaskSetManager: Starting task 1.0 in stage 8.0 (TID 54) (172.19.0.7, executor 0, partition 1, PROCESS_LOCAL, 10186 bytes)
[2025-06-07T15:53:50.399+0000] {spark_submit.py:644} INFO - 25/06/07 15:53:50 INFO TaskSetManager: Starting task 2.0 in stage 8.0 (TID 55) (172.19.0.7, executor 0, partition 2, PROCESS_LOCAL, 10186 bytes)
[2025-06-07T15:53:50.399+0000] {spark_submit.py:644} INFO - 25/06/07 15:53:50 INFO TaskSetManager: Starting task 3.0 in stage 8.0 (TID 56) (172.19.0.7, executor 0, partition 3, PROCESS_LOCAL, 10186 bytes)
[2025-06-07T15:53:50.407+0000] {spark_submit.py:644} INFO - 25/06/07 15:53:50 INFO BlockManagerInfo: Added broadcast_7_piece0 in memory on 172.19.0.7:37165 (size: 154.5 KiB, free: 1048.6 MiB)
[2025-06-07T15:53:50.508+0000] {spark_submit.py:644} INFO - 25/06/07 15:53:50 INFO TaskSetManager: Starting task 4.0 in stage 8.0 (TID 57) (172.19.0.7, executor 0, partition 4, PROCESS_LOCAL, 10186 bytes)
[2025-06-07T15:53:50.509+0000] {spark_submit.py:644} INFO - 25/06/07 15:53:50 INFO TaskSetManager: Finished task 2.0 in stage 8.0 (TID 55) in 110 ms on 172.19.0.7 (executor 0) (1/50)
[2025-06-07T15:53:50.511+0000] {spark_submit.py:644} INFO - 25/06/07 15:53:50 INFO TaskSetManager: Starting task 5.0 in stage 8.0 (TID 58) (172.19.0.7, executor 0, partition 5, PROCESS_LOCAL, 10186 bytes)
[2025-06-07T15:53:50.511+0000] {spark_submit.py:644} INFO - 25/06/07 15:53:50 INFO TaskSetManager: Starting task 6.0 in stage 8.0 (TID 59) (172.19.0.7, executor 0, partition 6, PROCESS_LOCAL, 10186 bytes)
[2025-06-07T15:53:50.512+0000] {spark_submit.py:644} INFO - 25/06/07 15:53:50 INFO TaskSetManager: Starting task 7.0 in stage 8.0 (TID 60) (172.19.0.7, executor 0, partition 7, PROCESS_LOCAL, 10186 bytes)
[2025-06-07T15:53:50.512+0000] {spark_submit.py:644} INFO - 25/06/07 15:53:50 INFO TaskSetManager: Finished task 1.0 in stage 8.0 (TID 54) in 112 ms on 172.19.0.7 (executor 0) (2/50)
[2025-06-07T15:53:50.512+0000] {spark_submit.py:644} INFO - 25/06/07 15:53:50 INFO TaskSetManager: Finished task 0.0 in stage 8.0 (TID 53) in 112 ms on 172.19.0.7 (executor 0) (3/50)
[2025-06-07T15:53:50.513+0000] {spark_submit.py:644} INFO - 25/06/07 15:53:50 INFO TaskSetManager: Finished task 3.0 in stage 8.0 (TID 56) in 111 ms on 172.19.0.7 (executor 0) (4/50)
[2025-06-07T15:53:50.532+0000] {spark_submit.py:644} INFO - 25/06/07 15:53:50 INFO TaskSetManager: Starting task 8.0 in stage 8.0 (TID 61) (172.19.0.7, executor 0, partition 8, PROCESS_LOCAL, 10186 bytes)
[2025-06-07T15:53:50.533+0000] {spark_submit.py:644} INFO - 25/06/07 15:53:50 INFO TaskSetManager: Starting task 9.0 in stage 8.0 (TID 62) (172.19.0.7, executor 0, partition 9, PROCESS_LOCAL, 10186 bytes)
[2025-06-07T15:53:50.536+0000] {spark_submit.py:644} INFO - 25/06/07 15:53:50 INFO TaskSetManager: Finished task 7.0 in stage 8.0 (TID 60) in 23 ms on 172.19.0.7 (executor 0) (5/50)
[2025-06-07T15:53:50.537+0000] {spark_submit.py:644} INFO - 25/06/07 15:53:50 INFO TaskSetManager: Starting task 10.0 in stage 8.0 (TID 63) (172.19.0.7, executor 0, partition 10, PROCESS_LOCAL, 10186 bytes)
[2025-06-07T15:53:50.537+0000] {spark_submit.py:644} INFO - 25/06/07 15:53:50 INFO TaskSetManager: Finished task 4.0 in stage 8.0 (TID 57) in 26 ms on 172.19.0.7 (executor 0) (6/50)
[2025-06-07T15:53:50.537+0000] {spark_submit.py:644} INFO - 25/06/07 15:53:50 INFO TaskSetManager: Finished task 5.0 in stage 8.0 (TID 58) in 25 ms on 172.19.0.7 (executor 0) (7/50)
[2025-06-07T15:53:50.537+0000] {spark_submit.py:644} INFO - 25/06/07 15:53:50 INFO TaskSetManager: Starting task 11.0 in stage 8.0 (TID 64) (172.19.0.7, executor 0, partition 11, PROCESS_LOCAL, 10186 bytes)
[2025-06-07T15:53:50.538+0000] {spark_submit.py:644} INFO - 25/06/07 15:53:50 INFO TaskSetManager: Finished task 6.0 in stage 8.0 (TID 59) in 25 ms on 172.19.0.7 (executor 0) (8/50)
[2025-06-07T15:53:50.546+0000] {spark_submit.py:644} INFO - 25/06/07 15:53:50 INFO TaskSetManager: Starting task 12.0 in stage 8.0 (TID 65) (172.19.0.7, executor 0, partition 12, PROCESS_LOCAL, 10186 bytes)
[2025-06-07T15:53:50.547+0000] {spark_submit.py:644} INFO - 25/06/07 15:53:50 INFO TaskSetManager: Starting task 13.0 in stage 8.0 (TID 66) (172.19.0.7, executor 0, partition 13, PROCESS_LOCAL, 10186 bytes)
[2025-06-07T15:53:50.547+0000] {spark_submit.py:644} INFO - 25/06/07 15:53:50 INFO TaskSetManager: Starting task 14.0 in stage 8.0 (TID 67) (172.19.0.7, executor 0, partition 14, PROCESS_LOCAL, 10186 bytes)
[2025-06-07T15:53:50.548+0000] {spark_submit.py:644} INFO - 25/06/07 15:53:50 INFO TaskSetManager: Starting task 15.0 in stage 8.0 (TID 68) (172.19.0.7, executor 0, partition 15, PROCESS_LOCAL, 10186 bytes)
[2025-06-07T15:53:50.548+0000] {spark_submit.py:644} INFO - 25/06/07 15:53:50 INFO TaskSetManager: Finished task 9.0 in stage 8.0 (TID 62) in 16 ms on 172.19.0.7 (executor 0) (9/50)
[2025-06-07T15:53:50.549+0000] {spark_submit.py:644} INFO - 25/06/07 15:53:50 INFO TaskSetManager: Finished task 11.0 in stage 8.0 (TID 64) in 15 ms on 172.19.0.7 (executor 0) (10/50)
[2025-06-07T15:53:50.549+0000] {spark_submit.py:644} INFO - 25/06/07 15:53:50 INFO TaskSetManager: Finished task 8.0 in stage 8.0 (TID 61) in 17 ms on 172.19.0.7 (executor 0) (11/50)
[2025-06-07T15:53:50.550+0000] {spark_submit.py:644} INFO - 25/06/07 15:53:50 INFO TaskSetManager: Finished task 10.0 in stage 8.0 (TID 63) in 16 ms on 172.19.0.7 (executor 0) (12/50)
[2025-06-07T15:53:50.559+0000] {spark_submit.py:644} INFO - 25/06/07 15:53:50 INFO TaskSetManager: Starting task 16.0 in stage 8.0 (TID 69) (172.19.0.7, executor 0, partition 16, PROCESS_LOCAL, 10186 bytes)
[2025-06-07T15:53:50.560+0000] {spark_submit.py:644} INFO - 25/06/07 15:53:50 INFO TaskSetManager: Starting task 17.0 in stage 8.0 (TID 70) (172.19.0.7, executor 0, partition 17, PROCESS_LOCAL, 10186 bytes)
[2025-06-07T15:53:50.561+0000] {spark_submit.py:644} INFO - 25/06/07 15:53:50 INFO TaskSetManager: Finished task 13.0 in stage 8.0 (TID 66) in 13 ms on 172.19.0.7 (executor 0) (13/50)
[2025-06-07T15:53:50.561+0000] {spark_submit.py:644} INFO - 25/06/07 15:53:50 INFO TaskSetManager: Starting task 18.0 in stage 8.0 (TID 71) (172.19.0.7, executor 0, partition 18, PROCESS_LOCAL, 10186 bytes)
[2025-06-07T15:53:50.562+0000] {spark_submit.py:644} INFO - 25/06/07 15:53:50 INFO TaskSetManager: Finished task 12.0 in stage 8.0 (TID 65) in 14 ms on 172.19.0.7 (executor 0) (14/50)
[2025-06-07T15:53:50.562+0000] {spark_submit.py:644} INFO - 25/06/07 15:53:50 INFO TaskSetManager: Finished task 14.0 in stage 8.0 (TID 67) in 13 ms on 172.19.0.7 (executor 0) (15/50)
[2025-06-07T15:53:50.563+0000] {spark_submit.py:644} INFO - 25/06/07 15:53:50 INFO TaskSetManager: Starting task 19.0 in stage 8.0 (TID 72) (172.19.0.7, executor 0, partition 19, PROCESS_LOCAL, 10186 bytes)
[2025-06-07T15:53:50.563+0000] {spark_submit.py:644} INFO - 25/06/07 15:53:50 INFO TaskSetManager: Finished task 15.0 in stage 8.0 (TID 68) in 14 ms on 172.19.0.7 (executor 0) (16/50)
[2025-06-07T15:53:50.569+0000] {spark_submit.py:644} INFO - 25/06/07 15:53:50 INFO TaskSetManager: Starting task 20.0 in stage 8.0 (TID 73) (172.19.0.7, executor 0, partition 20, PROCESS_LOCAL, 10186 bytes)
[2025-06-07T15:53:50.570+0000] {spark_submit.py:644} INFO - 25/06/07 15:53:50 INFO TaskSetManager: Finished task 16.0 in stage 8.0 (TID 69) in 11 ms on 172.19.0.7 (executor 0) (17/50)
[2025-06-07T15:53:50.573+0000] {spark_submit.py:644} INFO - 25/06/07 15:53:50 INFO TaskSetManager: Starting task 21.0 in stage 8.0 (TID 74) (172.19.0.7, executor 0, partition 21, PROCESS_LOCAL, 10186 bytes)
[2025-06-07T15:53:50.574+0000] {spark_submit.py:644} INFO - 25/06/07 15:53:50 INFO TaskSetManager: Finished task 19.0 in stage 8.0 (TID 72) in 13 ms on 172.19.0.7 (executor 0) (18/50)
[2025-06-07T15:53:50.574+0000] {spark_submit.py:644} INFO - 25/06/07 15:53:50 INFO TaskSetManager: Starting task 22.0 in stage 8.0 (TID 75) (172.19.0.7, executor 0, partition 22, PROCESS_LOCAL, 10186 bytes)
[2025-06-07T15:53:50.575+0000] {spark_submit.py:644} INFO - 25/06/07 15:53:50 INFO TaskSetManager: Starting task 23.0 in stage 8.0 (TID 76) (172.19.0.7, executor 0, partition 23, PROCESS_LOCAL, 10186 bytes)
[2025-06-07T15:53:50.575+0000] {spark_submit.py:644} INFO - 25/06/07 15:53:50 INFO TaskSetManager: Finished task 17.0 in stage 8.0 (TID 70) in 15 ms on 172.19.0.7 (executor 0) (19/50)
[2025-06-07T15:53:50.576+0000] {spark_submit.py:644} INFO - 25/06/07 15:53:50 INFO TaskSetManager: Finished task 18.0 in stage 8.0 (TID 71) in 14 ms on 172.19.0.7 (executor 0) (20/50)
[2025-06-07T15:53:50.578+0000] {spark_submit.py:644} INFO - 25/06/07 15:53:50 INFO TaskSetManager: Starting task 24.0 in stage 8.0 (TID 77) (172.19.0.7, executor 0, partition 24, PROCESS_LOCAL, 10186 bytes)
[2025-06-07T15:53:50.579+0000] {spark_submit.py:644} INFO - 25/06/07 15:53:50 INFO TaskSetManager: Finished task 20.0 in stage 8.0 (TID 73) in 10 ms on 172.19.0.7 (executor 0) (21/50)
[2025-06-07T15:53:50.586+0000] {spark_submit.py:644} INFO - 25/06/07 15:53:50 INFO TaskSetManager: Starting task 25.0 in stage 8.0 (TID 78) (172.19.0.7, executor 0, partition 25, PROCESS_LOCAL, 10186 bytes)
[2025-06-07T15:53:50.586+0000] {spark_submit.py:644} INFO - 25/06/07 15:53:50 INFO TaskSetManager: Finished task 22.0 in stage 8.0 (TID 75) in 12 ms on 172.19.0.7 (executor 0) (22/50)
[2025-06-07T15:53:50.587+0000] {spark_submit.py:644} INFO - 25/06/07 15:53:50 INFO TaskSetManager: Starting task 26.0 in stage 8.0 (TID 79) (172.19.0.7, executor 0, partition 26, PROCESS_LOCAL, 10186 bytes)
[2025-06-07T15:53:50.587+0000] {spark_submit.py:644} INFO - 25/06/07 15:53:50 INFO TaskSetManager: Starting task 27.0 in stage 8.0 (TID 80) (172.19.0.7, executor 0, partition 27, PROCESS_LOCAL, 10186 bytes)
[2025-06-07T15:53:50.587+0000] {spark_submit.py:644} INFO - 25/06/07 15:53:50 INFO TaskSetManager: Finished task 23.0 in stage 8.0 (TID 76) in 12 ms on 172.19.0.7 (executor 0) (23/50)
[2025-06-07T15:53:50.588+0000] {spark_submit.py:644} INFO - 25/06/07 15:53:50 INFO TaskSetManager: Starting task 28.0 in stage 8.0 (TID 81) (172.19.0.7, executor 0, partition 28, PROCESS_LOCAL, 10186 bytes)
[2025-06-07T15:53:50.588+0000] {spark_submit.py:644} INFO - 25/06/07 15:53:50 INFO TaskSetManager: Finished task 21.0 in stage 8.0 (TID 74) in 15 ms on 172.19.0.7 (executor 0) (24/50)
[2025-06-07T15:53:50.589+0000] {spark_submit.py:644} INFO - 25/06/07 15:53:50 INFO TaskSetManager: Finished task 24.0 in stage 8.0 (TID 77) in 11 ms on 172.19.0.7 (executor 0) (25/50)
[2025-06-07T15:53:50.596+0000] {spark_submit.py:644} INFO - 25/06/07 15:53:50 INFO TaskSetManager: Starting task 29.0 in stage 8.0 (TID 82) (172.19.0.7, executor 0, partition 29, PROCESS_LOCAL, 10186 bytes)
[2025-06-07T15:53:50.598+0000] {spark_submit.py:644} INFO - 25/06/07 15:53:50 INFO TaskSetManager: Finished task 25.0 in stage 8.0 (TID 78) in 12 ms on 172.19.0.7 (executor 0) (26/50)
[2025-06-07T15:53:50.598+0000] {spark_submit.py:644} INFO - 25/06/07 15:53:50 INFO TaskSetManager: Starting task 30.0 in stage 8.0 (TID 83) (172.19.0.7, executor 0, partition 30, PROCESS_LOCAL, 10186 bytes)
[2025-06-07T15:53:50.599+0000] {spark_submit.py:644} INFO - 25/06/07 15:53:50 INFO TaskSetManager: Finished task 26.0 in stage 8.0 (TID 79) in 12 ms on 172.19.0.7 (executor 0) (27/50)
[2025-06-07T15:53:50.600+0000] {spark_submit.py:644} INFO - 25/06/07 15:53:50 INFO TaskSetManager: Starting task 31.0 in stage 8.0 (TID 84) (172.19.0.7, executor 0, partition 31, PROCESS_LOCAL, 10186 bytes)
[2025-06-07T15:53:50.600+0000] {spark_submit.py:644} INFO - 25/06/07 15:53:50 INFO TaskSetManager: Finished task 27.0 in stage 8.0 (TID 80) in 13 ms on 172.19.0.7 (executor 0) (28/50)
[2025-06-07T15:53:50.600+0000] {spark_submit.py:644} INFO - 25/06/07 15:53:50 INFO TaskSetManager: Starting task 32.0 in stage 8.0 (TID 85) (172.19.0.7, executor 0, partition 32, PROCESS_LOCAL, 10186 bytes)
[2025-06-07T15:53:50.601+0000] {spark_submit.py:644} INFO - 25/06/07 15:53:50 INFO TaskSetManager: Finished task 28.0 in stage 8.0 (TID 81) in 13 ms on 172.19.0.7 (executor 0) (29/50)
[2025-06-07T15:53:50.605+0000] {spark_submit.py:644} INFO - 25/06/07 15:53:50 INFO TaskSetManager: Starting task 33.0 in stage 8.0 (TID 86) (172.19.0.7, executor 0, partition 33, PROCESS_LOCAL, 10186 bytes)
[2025-06-07T15:53:50.606+0000] {spark_submit.py:644} INFO - 25/06/07 15:53:50 INFO TaskSetManager: Finished task 29.0 in stage 8.0 (TID 82) in 9 ms on 172.19.0.7 (executor 0) (30/50)
[2025-06-07T15:53:50.609+0000] {spark_submit.py:644} INFO - 25/06/07 15:53:50 INFO TaskSetManager: Starting task 34.0 in stage 8.0 (TID 87) (172.19.0.7, executor 0, partition 34, PROCESS_LOCAL, 10186 bytes)
[2025-06-07T15:53:50.610+0000] {spark_submit.py:644} INFO - 25/06/07 15:53:50 INFO TaskSetManager: Finished task 32.0 in stage 8.0 (TID 85) in 9 ms on 172.19.0.7 (executor 0) (31/50)
[2025-06-07T15:53:50.610+0000] {spark_submit.py:644} INFO - 25/06/07 15:53:50 INFO TaskSetManager: Starting task 35.0 in stage 8.0 (TID 88) (172.19.0.7, executor 0, partition 35, PROCESS_LOCAL, 10186 bytes)
[2025-06-07T15:53:50.610+0000] {spark_submit.py:644} INFO - 25/06/07 15:53:50 INFO TaskSetManager: Finished task 31.0 in stage 8.0 (TID 84) in 11 ms on 172.19.0.7 (executor 0) (32/50)
[2025-06-07T15:53:50.611+0000] {spark_submit.py:644} INFO - 25/06/07 15:53:50 INFO TaskSetManager: Starting task 36.0 in stage 8.0 (TID 89) (172.19.0.7, executor 0, partition 36, PROCESS_LOCAL, 10186 bytes)
[2025-06-07T15:53:50.615+0000] {spark_submit.py:644} INFO - 25/06/07 15:53:50 INFO TaskSetManager: Finished task 30.0 in stage 8.0 (TID 83) in 14 ms on 172.19.0.7 (executor 0) (33/50)
[2025-06-07T15:53:50.616+0000] {spark_submit.py:644} INFO - 25/06/07 15:53:50 INFO TaskSetManager: Starting task 37.0 in stage 8.0 (TID 90) (172.19.0.7, executor 0, partition 37, PROCESS_LOCAL, 10186 bytes)
[2025-06-07T15:53:50.616+0000] {spark_submit.py:644} INFO - 25/06/07 15:53:50 INFO TaskSetManager: Finished task 33.0 in stage 8.0 (TID 86) in 10 ms on 172.19.0.7 (executor 0) (34/50)
[2025-06-07T15:53:50.621+0000] {spark_submit.py:644} INFO - 25/06/07 15:53:50 INFO TaskSetManager: Starting task 38.0 in stage 8.0 (TID 91) (172.19.0.7, executor 0, partition 38, PROCESS_LOCAL, 10186 bytes)
[2025-06-07T15:53:50.622+0000] {spark_submit.py:644} INFO - 25/06/07 15:53:50 INFO TaskSetManager: Starting task 39.0 in stage 8.0 (TID 92) (172.19.0.7, executor 0, partition 39, PROCESS_LOCAL, 10186 bytes)
[2025-06-07T15:53:50.622+0000] {spark_submit.py:644} INFO - 25/06/07 15:53:50 INFO TaskSetManager: Finished task 35.0 in stage 8.0 (TID 88) in 12 ms on 172.19.0.7 (executor 0) (35/50)
[2025-06-07T15:53:50.623+0000] {spark_submit.py:644} INFO - 25/06/07 15:53:50 INFO TaskSetManager: Starting task 40.0 in stage 8.0 (TID 93) (172.19.0.7, executor 0, partition 40, PROCESS_LOCAL, 10186 bytes)
[2025-06-07T15:53:50.623+0000] {spark_submit.py:644} INFO - 25/06/07 15:53:50 INFO TaskSetManager: Starting task 41.0 in stage 8.0 (TID 94) (172.19.0.7, executor 0, partition 41, PROCESS_LOCAL, 10186 bytes)
[2025-06-07T15:53:50.624+0000] {spark_submit.py:644} INFO - 25/06/07 15:53:50 INFO TaskSetManager: Finished task 36.0 in stage 8.0 (TID 89) in 13 ms on 172.19.0.7 (executor 0) (36/50)
[2025-06-07T15:53:50.624+0000] {spark_submit.py:644} INFO - 25/06/07 15:53:50 INFO TaskSetManager: Finished task 34.0 in stage 8.0 (TID 87) in 14 ms on 172.19.0.7 (executor 0) (37/50)
[2025-06-07T15:53:50.625+0000] {spark_submit.py:644} INFO - 25/06/07 15:53:50 INFO TaskSetManager: Finished task 37.0 in stage 8.0 (TID 90) in 11 ms on 172.19.0.7 (executor 0) (38/50)
[2025-06-07T15:53:50.635+0000] {spark_submit.py:644} INFO - 25/06/07 15:53:50 INFO TaskSetManager: Starting task 42.0 in stage 8.0 (TID 95) (172.19.0.7, executor 0, partition 42, PROCESS_LOCAL, 10186 bytes)
[2025-06-07T15:53:50.636+0000] {spark_submit.py:644} INFO - 25/06/07 15:53:50 INFO TaskSetManager: Starting task 43.0 in stage 8.0 (TID 96) (172.19.0.7, executor 0, partition 43, PROCESS_LOCAL, 10186 bytes)
[2025-06-07T15:53:50.639+0000] {spark_submit.py:644} INFO - 25/06/07 15:53:50 INFO TaskSetManager: Finished task 39.0 in stage 8.0 (TID 92) in 15 ms on 172.19.0.7 (executor 0) (39/50)
[2025-06-07T15:53:50.640+0000] {spark_submit.py:644} INFO - 25/06/07 15:53:50 INFO TaskSetManager: Finished task 40.0 in stage 8.0 (TID 93) in 14 ms on 172.19.0.7 (executor 0) (40/50)
[2025-06-07T15:53:50.640+0000] {spark_submit.py:644} INFO - 25/06/07 15:53:50 INFO TaskSetManager: Starting task 44.0 in stage 8.0 (TID 97) (172.19.0.7, executor 0, partition 44, PROCESS_LOCAL, 10186 bytes)
[2025-06-07T15:53:50.640+0000] {spark_submit.py:644} INFO - 25/06/07 15:53:50 INFO TaskSetManager: Starting task 45.0 in stage 8.0 (TID 98) (172.19.0.7, executor 0, partition 45, PROCESS_LOCAL, 10186 bytes)
[2025-06-07T15:53:50.640+0000] {spark_submit.py:644} INFO - 25/06/07 15:53:50 INFO TaskSetManager: Finished task 38.0 in stage 8.0 (TID 91) in 17 ms on 172.19.0.7 (executor 0) (41/50)
[2025-06-07T15:53:50.640+0000] {spark_submit.py:644} INFO - 25/06/07 15:53:50 INFO TaskSetManager: Finished task 41.0 in stage 8.0 (TID 94) in 15 ms on 172.19.0.7 (executor 0) (42/50)
[2025-06-07T15:53:50.647+0000] {spark_submit.py:644} INFO - 25/06/07 15:53:50 INFO TaskSetManager: Starting task 46.0 in stage 8.0 (TID 99) (172.19.0.7, executor 0, partition 46, PROCESS_LOCAL, 10186 bytes)
[2025-06-07T15:53:50.647+0000] {spark_submit.py:644} INFO - 25/06/07 15:53:50 INFO TaskSetManager: Starting task 47.0 in stage 8.0 (TID 100) (172.19.0.7, executor 0, partition 47, PROCESS_LOCAL, 10186 bytes)
[2025-06-07T15:53:50.648+0000] {spark_submit.py:644} INFO - 25/06/07 15:53:50 INFO TaskSetManager: Starting task 48.0 in stage 8.0 (TID 101) (172.19.0.7, executor 0, partition 48, PROCESS_LOCAL, 10186 bytes)
[2025-06-07T15:53:50.649+0000] {spark_submit.py:644} INFO - 25/06/07 15:53:50 INFO TaskSetManager: Starting task 49.0 in stage 8.0 (TID 102) (172.19.0.7, executor 0, partition 49, PROCESS_LOCAL, 10186 bytes)
[2025-06-07T15:53:50.649+0000] {spark_submit.py:644} INFO - 25/06/07 15:53:50 INFO TaskSetManager: Finished task 43.0 in stage 8.0 (TID 96) in 13 ms on 172.19.0.7 (executor 0) (43/50)
